[2021-10-09 04:07:41,208] {taskinstance.py:903} INFO - Dependencies all met for <TaskInstance: template_dag.generate_new_logs 2021-10-09T04:07:38.420967+00:00 [queued]>
[2021-10-09 04:07:41,216] {taskinstance.py:903} INFO - Dependencies all met for <TaskInstance: template_dag.generate_new_logs 2021-10-09T04:07:38.420967+00:00 [queued]>
[2021-10-09 04:07:41,217] {taskinstance.py:1094} INFO - 
--------------------------------------------------------------------------------
[2021-10-09 04:07:41,217] {taskinstance.py:1095} INFO - Starting attempt 1 of 2
[2021-10-09 04:07:41,217] {taskinstance.py:1096} INFO - 
--------------------------------------------------------------------------------
[2021-10-09 04:07:41,229] {taskinstance.py:1114} INFO - Executing <Task(BashOperator): generate_new_logs> on 2021-10-09T04:07:38.420967+00:00
[2021-10-09 04:07:41,233] {standard_task_runner.py:52} INFO - Started process 5322 to run task
[2021-10-09 04:07:41,237] {standard_task_runner.py:76} INFO - Running: ['airflow', 'tasks', 'run', 'template_dag', 'generate_new_logs', '2021-10-09T04:07:38.420967+00:00', '--job-id', '317', '--pool', 'default_pool', '--raw', '--subdir', 'DAGS_FOLDER/template_dag.py', '--cfg-path', '/tmp/tmp35ztlfun', '--error-file', '/tmp/tmpqcjml34u']
[2021-10-09 04:07:41,238] {standard_task_runner.py:77} INFO - Job 317: Subtask generate_new_logs
[2021-10-09 04:07:41,273] {logging_mixin.py:109} INFO - Running <TaskInstance: template_dag.generate_new_logs 2021-10-09T04:07:38.420967+00:00 [running]> on host a6cf1bcf3ec3
[2021-10-09 04:07:41,358] {taskinstance.py:1462} ERROR - Task failed with exception
Traceback (most recent call last):
  File "/usr/local/lib/python3.8/dist-packages/airflow/models/taskinstance.py", line 1164, in _run_raw_task
    self._prepare_and_execute_task_with_callbacks(context, task)
  File "/usr/local/lib/python3.8/dist-packages/airflow/models/taskinstance.py", line 1245, in _prepare_and_execute_task_with_callbacks
    self.render_templates(context=context)
  File "/usr/local/lib/python3.8/dist-packages/airflow/models/taskinstance.py", line 1754, in render_templates
    self.task.render_template_fields(context)
  File "/usr/local/lib/python3.8/dist-packages/airflow/models/baseoperator.py", line 997, in render_template_fields
    self._do_render_template_fields(self, self.template_fields, context, jinja_env, set())
  File "/usr/local/lib/python3.8/dist-packages/airflow/models/baseoperator.py", line 1010, in _do_render_template_fields
    rendered_content = self.render_template(content, context, jinja_env, seen_oids)
  File "/usr/local/lib/python3.8/dist-packages/airflow/models/baseoperator.py", line 1047, in render_template
    return jinja_env.from_string(content).render(**context)
  File "/usr/local/lib/python3.8/dist-packages/jinja2/environment.py", line 1090, in render
    self.environment.handle_exception()
  File "/usr/local/lib/python3.8/dist-packages/jinja2/environment.py", line 832, in handle_exception
    reraise(*rewrite_traceback_stack(source=source))
  File "/usr/local/lib/python3.8/dist-packages/jinja2/_compat.py", line 28, in reraise
    raise value.with_traceback(tb)
  File "<template>", line 16, in top-level template code
jinja2.exceptions.UndefinedError: 'dict object' has no attribute 'dir_'
[2021-10-09 04:07:41,359] {taskinstance.py:1505} INFO - Marking task as UP_FOR_RETRY. dag_id=template_dag, task_id=generate_new_logs, execution_date=20211009T040738, start_date=20211009T040741, end_date=20211009T040741
[2021-10-09 04:07:41,408] {local_task_job.py:151} INFO - Task exited with return code 1
[2021-10-09 04:07:41,433] {local_task_job.py:261} INFO - 0 downstream tasks scheduled from follow-on schedule check
