[2021-09-03 08:22:15,383] {processor.py:162} INFO - Started process (PID=5241) to work on /usr/local/airflow/dags/connect_to_gdrive.py
[2021-09-03 08:22:15,384] {processor.py:613} INFO - Processing file /usr/local/airflow/dags/connect_to_gdrive.py for tasks to queue
[2021-09-03 08:22:15,384] {logging_mixin.py:109} INFO - [2021-09-03 08:22:15,384] {dagbag.py:496} INFO - Filling up the DagBag from /usr/local/airflow/dags/connect_to_gdrive.py
[2021-09-03 08:22:15,589] {logging_mixin.py:109} INFO - [2021-09-03 08:22:15,588] {dagbag.py:329} ERROR - Failed to import: /usr/local/airflow/dags/connect_to_gdrive.py
Traceback (most recent call last):
  File "/usr/local/lib/python3.8/dist-packages/airflow/models/dagbag.py", line 326, in _load_modules_from_file
    loader.exec_module(new_module)
  File "<frozen importlib._bootstrap_external>", line 848, in exec_module
  File "<frozen importlib._bootstrap>", line 219, in _call_with_frames_removed
  File "/usr/local/airflow/dags/connect_to_gdrive.py", line 42, in <module>
    dummy_op >> hello_task >> hello_task2 >> hello_task3
NameError: name 'hello_task2' is not defined
[2021-09-03 08:22:15,589] {processor.py:625} WARNING - No viable dags retrieved from /usr/local/airflow/dags/connect_to_gdrive.py
[2021-09-03 08:22:15,599] {processor.py:170} INFO - Processing /usr/local/airflow/dags/connect_to_gdrive.py took 0.219 seconds
[2021-09-03 08:22:46,559] {processor.py:162} INFO - Started process (PID=5592) to work on /usr/local/airflow/dags/connect_to_gdrive.py
[2021-09-03 08:22:46,561] {processor.py:613} INFO - Processing file /usr/local/airflow/dags/connect_to_gdrive.py for tasks to queue
[2021-09-03 08:22:46,561] {logging_mixin.py:109} INFO - [2021-09-03 08:22:46,561] {dagbag.py:496} INFO - Filling up the DagBag from /usr/local/airflow/dags/connect_to_gdrive.py
[2021-09-03 08:22:46,774] {logging_mixin.py:109} INFO - [2021-09-03 08:22:46,773] {dagbag.py:329} ERROR - Failed to import: /usr/local/airflow/dags/connect_to_gdrive.py
Traceback (most recent call last):
  File "/usr/local/lib/python3.8/dist-packages/airflow/models/dagbag.py", line 326, in _load_modules_from_file
    loader.exec_module(new_module)
  File "<frozen importlib._bootstrap_external>", line 848, in exec_module
  File "<frozen importlib._bootstrap>", line 219, in _call_with_frames_removed
  File "/usr/local/airflow/dags/connect_to_gdrive.py", line 49, in <module>
    dummy_op >> hello_task >> hello_task2 >> hello_task3
NameError: name 'hello_task2' is not defined
[2021-09-03 08:22:46,774] {processor.py:625} WARNING - No viable dags retrieved from /usr/local/airflow/dags/connect_to_gdrive.py
[2021-09-03 08:22:46,784] {processor.py:170} INFO - Processing /usr/local/airflow/dags/connect_to_gdrive.py took 0.229 seconds
[2021-09-03 08:23:16,821] {processor.py:162} INFO - Started process (PID=5918) to work on /usr/local/airflow/dags/connect_to_gdrive.py
[2021-09-03 08:23:16,822] {processor.py:613} INFO - Processing file /usr/local/airflow/dags/connect_to_gdrive.py for tasks to queue
[2021-09-03 08:23:16,823] {logging_mixin.py:109} INFO - [2021-09-03 08:23:16,823] {dagbag.py:496} INFO - Filling up the DagBag from /usr/local/airflow/dags/connect_to_gdrive.py
[2021-09-03 08:23:17,028] {logging_mixin.py:109} INFO - [2021-09-03 08:23:17,027] {dagbag.py:329} ERROR - Failed to import: /usr/local/airflow/dags/connect_to_gdrive.py
Traceback (most recent call last):
  File "/usr/local/lib/python3.8/dist-packages/airflow/models/dagbag.py", line 326, in _load_modules_from_file
    loader.exec_module(new_module)
  File "<frozen importlib._bootstrap_external>", line 848, in exec_module
  File "<frozen importlib._bootstrap>", line 219, in _call_with_frames_removed
  File "/usr/local/airflow/dags/connect_to_gdrive.py", line 49, in <module>
    dummy_op >> hello_task >> hello_task2 >> hello_task3
NameError: name 'hello_task2' is not defined
[2021-09-03 08:23:17,028] {processor.py:625} WARNING - No viable dags retrieved from /usr/local/airflow/dags/connect_to_gdrive.py
[2021-09-03 08:23:17,041] {processor.py:170} INFO - Processing /usr/local/airflow/dags/connect_to_gdrive.py took 0.224 seconds
[2021-09-03 08:23:48,014] {processor.py:162} INFO - Started process (PID=6269) to work on /usr/local/airflow/dags/connect_to_gdrive.py
[2021-09-03 08:23:48,015] {processor.py:613} INFO - Processing file /usr/local/airflow/dags/connect_to_gdrive.py for tasks to queue
[2021-09-03 08:23:48,015] {logging_mixin.py:109} INFO - [2021-09-03 08:23:48,015] {dagbag.py:496} INFO - Filling up the DagBag from /usr/local/airflow/dags/connect_to_gdrive.py
[2021-09-03 08:23:48,231] {logging_mixin.py:109} INFO - [2021-09-03 08:23:48,230] {dagbag.py:329} ERROR - Failed to import: /usr/local/airflow/dags/connect_to_gdrive.py
Traceback (most recent call last):
  File "/usr/local/lib/python3.8/dist-packages/airflow/models/dagbag.py", line 326, in _load_modules_from_file
    loader.exec_module(new_module)
  File "<frozen importlib._bootstrap_external>", line 848, in exec_module
  File "<frozen importlib._bootstrap>", line 219, in _call_with_frames_removed
  File "/usr/local/airflow/dags/connect_to_gdrive.py", line 49, in <module>
    dummy_op >> hello_task >> hello_task2 >> hello_task3
NameError: name 'hello_task2' is not defined
[2021-09-03 08:23:48,231] {processor.py:625} WARNING - No viable dags retrieved from /usr/local/airflow/dags/connect_to_gdrive.py
[2021-09-03 08:23:48,240] {processor.py:170} INFO - Processing /usr/local/airflow/dags/connect_to_gdrive.py took 0.230 seconds
[2021-09-03 08:24:18,293] {processor.py:162} INFO - Started process (PID=6589) to work on /usr/local/airflow/dags/connect_to_gdrive.py
[2021-09-03 08:24:18,295] {processor.py:613} INFO - Processing file /usr/local/airflow/dags/connect_to_gdrive.py for tasks to queue
[2021-09-03 08:24:18,295] {logging_mixin.py:109} INFO - [2021-09-03 08:24:18,295] {dagbag.py:496} INFO - Filling up the DagBag from /usr/local/airflow/dags/connect_to_gdrive.py
[2021-09-03 08:24:18,571] {logging_mixin.py:109} INFO - [2021-09-03 08:24:18,570] {dagbag.py:329} ERROR - Failed to import: /usr/local/airflow/dags/connect_to_gdrive.py
Traceback (most recent call last):
  File "/usr/local/lib/python3.8/dist-packages/airflow/models/dagbag.py", line 326, in _load_modules_from_file
    loader.exec_module(new_module)
  File "<frozen importlib._bootstrap_external>", line 848, in exec_module
  File "<frozen importlib._bootstrap>", line 219, in _call_with_frames_removed
  File "/usr/local/airflow/dags/connect_to_gdrive.py", line 50, in <module>
    dummy_op >> hello_task >> hello_task2 >> hello_task3
NameError: name 'hello_task2' is not defined
[2021-09-03 08:24:18,571] {processor.py:625} WARNING - No viable dags retrieved from /usr/local/airflow/dags/connect_to_gdrive.py
[2021-09-03 08:24:18,581] {processor.py:170} INFO - Processing /usr/local/airflow/dags/connect_to_gdrive.py took 0.293 seconds
[2021-09-03 08:24:48,641] {processor.py:162} INFO - Started process (PID=6932) to work on /usr/local/airflow/dags/connect_to_gdrive.py
[2021-09-03 08:24:48,643] {processor.py:613} INFO - Processing file /usr/local/airflow/dags/connect_to_gdrive.py for tasks to queue
[2021-09-03 08:24:48,643] {logging_mixin.py:109} INFO - [2021-09-03 08:24:48,643] {dagbag.py:496} INFO - Filling up the DagBag from /usr/local/airflow/dags/connect_to_gdrive.py
[2021-09-03 08:24:48,862] {logging_mixin.py:109} INFO - [2021-09-03 08:24:48,862] {dagbag.py:329} ERROR - Failed to import: /usr/local/airflow/dags/connect_to_gdrive.py
Traceback (most recent call last):
  File "/usr/local/lib/python3.8/dist-packages/airflow/models/dagbag.py", line 326, in _load_modules_from_file
    loader.exec_module(new_module)
  File "<frozen importlib._bootstrap_external>", line 848, in exec_module
  File "<frozen importlib._bootstrap>", line 219, in _call_with_frames_removed
  File "/usr/local/airflow/dags/connect_to_gdrive.py", line 52, in <module>
    dummy_op >> hello_task >> hello_task2 >> hello_task3
NameError: name 'hello_task' is not defined
[2021-09-03 08:24:48,862] {processor.py:625} WARNING - No viable dags retrieved from /usr/local/airflow/dags/connect_to_gdrive.py
[2021-09-03 08:24:48,872] {processor.py:170} INFO - Processing /usr/local/airflow/dags/connect_to_gdrive.py took 0.235 seconds
[2021-09-03 08:25:18,916] {processor.py:162} INFO - Started process (PID=7258) to work on /usr/local/airflow/dags/connect_to_gdrive.py
[2021-09-03 08:25:18,917] {processor.py:613} INFO - Processing file /usr/local/airflow/dags/connect_to_gdrive.py for tasks to queue
[2021-09-03 08:25:18,918] {logging_mixin.py:109} INFO - [2021-09-03 08:25:18,917] {dagbag.py:496} INFO - Filling up the DagBag from /usr/local/airflow/dags/connect_to_gdrive.py
[2021-09-03 08:25:19,141] {processor.py:623} INFO - DAG(s) dict_keys(['hello_gdive']) retrieved from /usr/local/airflow/dags/connect_to_gdrive.py
[2021-09-03 08:25:19,880] {logging_mixin.py:109} INFO - [2021-09-03 08:25:19,880] {dag.py:1833} INFO - Sync 1 DAGs
[2021-09-03 08:25:19,885] {logging_mixin.py:109} INFO - [2021-09-03 08:25:19,885] {dag.py:1852} INFO - Creating ORM DAG for hello_gdive
[2021-09-03 08:25:19,888] {logging_mixin.py:109} INFO - [2021-09-03 08:25:19,888] {dag.py:2306} INFO - Setting next_dagrun for hello_gdive to 2021-08-14 17:00:00+00:00
[2021-09-03 08:25:19,895] {processor.py:170} INFO - Processing /usr/local/airflow/dags/connect_to_gdrive.py took 0.983 seconds
[2021-09-03 08:25:50,190] {processor.py:162} INFO - Started process (PID=7636) to work on /usr/local/airflow/dags/connect_to_gdrive.py
[2021-09-03 08:25:50,192] {processor.py:613} INFO - Processing file /usr/local/airflow/dags/connect_to_gdrive.py for tasks to queue
[2021-09-03 08:25:50,193] {logging_mixin.py:109} INFO - [2021-09-03 08:25:50,193] {dagbag.py:496} INFO - Filling up the DagBag from /usr/local/airflow/dags/connect_to_gdrive.py
[2021-09-03 08:25:50,434] {processor.py:623} INFO - DAG(s) dict_keys(['hello_gdive']) retrieved from /usr/local/airflow/dags/connect_to_gdrive.py
[2021-09-03 08:25:50,445] {logging_mixin.py:109} INFO - [2021-09-03 08:25:50,445] {dag.py:1833} INFO - Sync 1 DAGs
[2021-09-03 08:25:50,453] {logging_mixin.py:109} INFO - [2021-09-03 08:25:50,452] {dag.py:2306} INFO - Setting next_dagrun for hello_gdive to None
[2021-09-03 08:25:50,457] {processor.py:170} INFO - Processing /usr/local/airflow/dags/connect_to_gdrive.py took 0.272 seconds
[2021-09-03 08:26:20,483] {processor.py:162} INFO - Started process (PID=7956) to work on /usr/local/airflow/dags/connect_to_gdrive.py
[2021-09-03 08:26:20,486] {processor.py:613} INFO - Processing file /usr/local/airflow/dags/connect_to_gdrive.py for tasks to queue
[2021-09-03 08:26:20,487] {logging_mixin.py:109} INFO - [2021-09-03 08:26:20,486] {dagbag.py:496} INFO - Filling up the DagBag from /usr/local/airflow/dags/connect_to_gdrive.py
[2021-09-03 08:26:20,769] {processor.py:623} INFO - DAG(s) dict_keys(['hello_gdive']) retrieved from /usr/local/airflow/dags/connect_to_gdrive.py
[2021-09-03 08:26:20,781] {logging_mixin.py:109} INFO - [2021-09-03 08:26:20,781] {dag.py:1833} INFO - Sync 1 DAGs
[2021-09-03 08:26:20,791] {logging_mixin.py:109} INFO - [2021-09-03 08:26:20,790] {dag.py:2306} INFO - Setting next_dagrun for hello_gdive to None
[2021-09-03 08:26:20,797] {processor.py:170} INFO - Processing /usr/local/airflow/dags/connect_to_gdrive.py took 0.319 seconds
[2021-09-03 08:26:51,715] {processor.py:162} INFO - Started process (PID=8307) to work on /usr/local/airflow/dags/connect_to_gdrive.py
[2021-09-03 08:26:51,715] {processor.py:613} INFO - Processing file /usr/local/airflow/dags/connect_to_gdrive.py for tasks to queue
[2021-09-03 08:26:51,716] {logging_mixin.py:109} INFO - [2021-09-03 08:26:51,716] {dagbag.py:496} INFO - Filling up the DagBag from /usr/local/airflow/dags/connect_to_gdrive.py
[2021-09-03 08:26:51,917] {processor.py:623} INFO - DAG(s) dict_keys(['hello_gdive']) retrieved from /usr/local/airflow/dags/connect_to_gdrive.py
[2021-09-03 08:26:51,929] {logging_mixin.py:109} INFO - [2021-09-03 08:26:51,929] {dag.py:1833} INFO - Sync 1 DAGs
[2021-09-03 08:26:51,936] {logging_mixin.py:109} INFO - [2021-09-03 08:26:51,936] {dag.py:2306} INFO - Setting next_dagrun for hello_gdive to None
[2021-09-03 08:26:51,943] {processor.py:170} INFO - Processing /usr/local/airflow/dags/connect_to_gdrive.py took 0.231 seconds
[2021-09-03 08:27:22,004] {processor.py:162} INFO - Started process (PID=8637) to work on /usr/local/airflow/dags/connect_to_gdrive.py
[2021-09-03 08:27:22,006] {processor.py:613} INFO - Processing file /usr/local/airflow/dags/connect_to_gdrive.py for tasks to queue
[2021-09-03 08:27:22,006] {logging_mixin.py:109} INFO - [2021-09-03 08:27:22,006] {dagbag.py:496} INFO - Filling up the DagBag from /usr/local/airflow/dags/connect_to_gdrive.py
[2021-09-03 08:27:22,247] {processor.py:623} INFO - DAG(s) dict_keys(['hello_gdive']) retrieved from /usr/local/airflow/dags/connect_to_gdrive.py
[2021-09-03 08:27:22,259] {logging_mixin.py:109} INFO - [2021-09-03 08:27:22,259] {dag.py:1833} INFO - Sync 1 DAGs
[2021-09-03 08:27:22,267] {logging_mixin.py:109} INFO - [2021-09-03 08:27:22,267] {dag.py:2306} INFO - Setting next_dagrun for hello_gdive to None
[2021-09-03 08:27:22,272] {processor.py:170} INFO - Processing /usr/local/airflow/dags/connect_to_gdrive.py took 0.272 seconds
[2021-09-03 08:27:52,358] {processor.py:162} INFO - Started process (PID=8980) to work on /usr/local/airflow/dags/connect_to_gdrive.py
[2021-09-03 08:27:52,359] {processor.py:613} INFO - Processing file /usr/local/airflow/dags/connect_to_gdrive.py for tasks to queue
[2021-09-03 08:27:52,360] {logging_mixin.py:109} INFO - [2021-09-03 08:27:52,360] {dagbag.py:496} INFO - Filling up the DagBag from /usr/local/airflow/dags/connect_to_gdrive.py
[2021-09-03 08:27:52,565] {processor.py:623} INFO - DAG(s) dict_keys(['hello_gdive']) retrieved from /usr/local/airflow/dags/connect_to_gdrive.py
[2021-09-03 08:27:52,577] {logging_mixin.py:109} INFO - [2021-09-03 08:27:52,576] {dag.py:1833} INFO - Sync 1 DAGs
[2021-09-03 08:27:52,584] {logging_mixin.py:109} INFO - [2021-09-03 08:27:52,584] {dag.py:2306} INFO - Setting next_dagrun for hello_gdive to None
[2021-09-03 08:27:52,594] {processor.py:170} INFO - Processing /usr/local/airflow/dags/connect_to_gdrive.py took 0.239 seconds
[2021-09-03 08:28:22,654] {processor.py:162} INFO - Started process (PID=9307) to work on /usr/local/airflow/dags/connect_to_gdrive.py
[2021-09-03 08:28:22,655] {processor.py:613} INFO - Processing file /usr/local/airflow/dags/connect_to_gdrive.py for tasks to queue
[2021-09-03 08:28:22,656] {logging_mixin.py:109} INFO - [2021-09-03 08:28:22,655] {dagbag.py:496} INFO - Filling up the DagBag from /usr/local/airflow/dags/connect_to_gdrive.py
[2021-09-03 08:28:22,862] {processor.py:623} INFO - DAG(s) dict_keys(['hello_gdive']) retrieved from /usr/local/airflow/dags/connect_to_gdrive.py
[2021-09-03 08:28:22,874] {logging_mixin.py:109} INFO - [2021-09-03 08:28:22,874] {dag.py:1833} INFO - Sync 1 DAGs
[2021-09-03 08:28:22,885] {logging_mixin.py:109} INFO - [2021-09-03 08:28:22,885] {dag.py:2306} INFO - Setting next_dagrun for hello_gdive to None
[2021-09-03 08:28:22,893] {processor.py:170} INFO - Processing /usr/local/airflow/dags/connect_to_gdrive.py took 0.243 seconds
[2021-09-03 08:28:53,007] {processor.py:162} INFO - Started process (PID=9653) to work on /usr/local/airflow/dags/connect_to_gdrive.py
[2021-09-03 08:28:53,007] {processor.py:613} INFO - Processing file /usr/local/airflow/dags/connect_to_gdrive.py for tasks to queue
[2021-09-03 08:28:53,008] {logging_mixin.py:109} INFO - [2021-09-03 08:28:53,008] {dagbag.py:496} INFO - Filling up the DagBag from /usr/local/airflow/dags/connect_to_gdrive.py
[2021-09-03 08:28:53,238] {processor.py:623} INFO - DAG(s) dict_keys(['hello_gdive']) retrieved from /usr/local/airflow/dags/connect_to_gdrive.py
[2021-09-03 08:28:53,253] {logging_mixin.py:109} INFO - [2021-09-03 08:28:53,252] {dag.py:1833} INFO - Sync 1 DAGs
[2021-09-03 08:28:53,262] {logging_mixin.py:109} INFO - [2021-09-03 08:28:53,262] {dag.py:2306} INFO - Setting next_dagrun for hello_gdive to None
[2021-09-03 08:28:53,274] {processor.py:170} INFO - Processing /usr/local/airflow/dags/connect_to_gdrive.py took 0.270 seconds
[2021-09-03 08:29:24,198] {processor.py:162} INFO - Started process (PID=9987) to work on /usr/local/airflow/dags/connect_to_gdrive.py
[2021-09-03 08:29:24,199] {processor.py:613} INFO - Processing file /usr/local/airflow/dags/connect_to_gdrive.py for tasks to queue
[2021-09-03 08:29:24,200] {logging_mixin.py:109} INFO - [2021-09-03 08:29:24,200] {dagbag.py:496} INFO - Filling up the DagBag from /usr/local/airflow/dags/connect_to_gdrive.py
[2021-09-03 08:29:24,412] {processor.py:623} INFO - DAG(s) dict_keys(['hello_gdive']) retrieved from /usr/local/airflow/dags/connect_to_gdrive.py
[2021-09-03 08:29:24,423] {logging_mixin.py:109} INFO - [2021-09-03 08:29:24,423] {dag.py:1833} INFO - Sync 1 DAGs
[2021-09-03 08:29:24,431] {logging_mixin.py:109} INFO - [2021-09-03 08:29:24,431] {dag.py:2306} INFO - Setting next_dagrun for hello_gdive to None
[2021-09-03 08:29:24,440] {processor.py:170} INFO - Processing /usr/local/airflow/dags/connect_to_gdrive.py took 0.246 seconds
[2021-09-03 08:29:54,463] {processor.py:162} INFO - Started process (PID=10324) to work on /usr/local/airflow/dags/connect_to_gdrive.py
[2021-09-03 08:29:54,464] {processor.py:613} INFO - Processing file /usr/local/airflow/dags/connect_to_gdrive.py for tasks to queue
[2021-09-03 08:29:54,464] {logging_mixin.py:109} INFO - [2021-09-03 08:29:54,464] {dagbag.py:496} INFO - Filling up the DagBag from /usr/local/airflow/dags/connect_to_gdrive.py
[2021-09-03 08:29:54,732] {processor.py:623} INFO - DAG(s) dict_keys(['hello_gdive']) retrieved from /usr/local/airflow/dags/connect_to_gdrive.py
[2021-09-03 08:29:54,753] {logging_mixin.py:109} INFO - [2021-09-03 08:29:54,753] {dag.py:1833} INFO - Sync 1 DAGs
[2021-09-03 08:29:54,766] {logging_mixin.py:109} INFO - [2021-09-03 08:29:54,766] {dag.py:2306} INFO - Setting next_dagrun for hello_gdive to None
[2021-09-03 08:29:54,773] {processor.py:170} INFO - Processing /usr/local/airflow/dags/connect_to_gdrive.py took 0.314 seconds
[2021-09-03 08:30:25,697] {processor.py:162} INFO - Started process (PID=10657) to work on /usr/local/airflow/dags/connect_to_gdrive.py
[2021-09-03 08:30:25,698] {processor.py:613} INFO - Processing file /usr/local/airflow/dags/connect_to_gdrive.py for tasks to queue
[2021-09-03 08:30:25,699] {logging_mixin.py:109} INFO - [2021-09-03 08:30:25,699] {dagbag.py:496} INFO - Filling up the DagBag from /usr/local/airflow/dags/connect_to_gdrive.py
[2021-09-03 08:30:25,909] {processor.py:623} INFO - DAG(s) dict_keys(['hello_gdive']) retrieved from /usr/local/airflow/dags/connect_to_gdrive.py
[2021-09-03 08:30:25,920] {logging_mixin.py:109} INFO - [2021-09-03 08:30:25,920] {dag.py:1833} INFO - Sync 1 DAGs
[2021-09-03 08:30:25,928] {logging_mixin.py:109} INFO - [2021-09-03 08:30:25,928] {dag.py:2306} INFO - Setting next_dagrun for hello_gdive to None
[2021-09-03 08:30:25,937] {processor.py:170} INFO - Processing /usr/local/airflow/dags/connect_to_gdrive.py took 0.243 seconds
[2021-09-03 08:30:55,976] {processor.py:162} INFO - Started process (PID=11000) to work on /usr/local/airflow/dags/connect_to_gdrive.py
[2021-09-03 08:30:55,978] {processor.py:613} INFO - Processing file /usr/local/airflow/dags/connect_to_gdrive.py for tasks to queue
[2021-09-03 08:30:55,979] {logging_mixin.py:109} INFO - [2021-09-03 08:30:55,979] {dagbag.py:496} INFO - Filling up the DagBag from /usr/local/airflow/dags/connect_to_gdrive.py
[2021-09-03 08:30:56,189] {processor.py:623} INFO - DAG(s) dict_keys(['hello_gdive']) retrieved from /usr/local/airflow/dags/connect_to_gdrive.py
[2021-09-03 08:30:56,201] {logging_mixin.py:109} INFO - [2021-09-03 08:30:56,201] {dag.py:1833} INFO - Sync 1 DAGs
[2021-09-03 08:30:56,209] {logging_mixin.py:109} INFO - [2021-09-03 08:30:56,209] {dag.py:2306} INFO - Setting next_dagrun for hello_gdive to None
[2021-09-03 08:30:56,219] {processor.py:170} INFO - Processing /usr/local/airflow/dags/connect_to_gdrive.py took 0.246 seconds
[2021-09-03 08:31:27,158] {processor.py:162} INFO - Started process (PID=11333) to work on /usr/local/airflow/dags/connect_to_gdrive.py
[2021-09-03 08:31:27,159] {processor.py:613} INFO - Processing file /usr/local/airflow/dags/connect_to_gdrive.py for tasks to queue
[2021-09-03 08:31:27,160] {logging_mixin.py:109} INFO - [2021-09-03 08:31:27,160] {dagbag.py:496} INFO - Filling up the DagBag from /usr/local/airflow/dags/connect_to_gdrive.py
[2021-09-03 08:31:27,377] {processor.py:623} INFO - DAG(s) dict_keys(['hello_gdive']) retrieved from /usr/local/airflow/dags/connect_to_gdrive.py
[2021-09-03 08:31:27,388] {logging_mixin.py:109} INFO - [2021-09-03 08:31:27,388] {dag.py:1833} INFO - Sync 1 DAGs
[2021-09-03 08:31:27,397] {logging_mixin.py:109} INFO - [2021-09-03 08:31:27,397] {dag.py:2306} INFO - Setting next_dagrun for hello_gdive to None
[2021-09-03 08:31:27,402] {processor.py:170} INFO - Processing /usr/local/airflow/dags/connect_to_gdrive.py took 0.248 seconds
[2021-09-03 08:31:57,422] {processor.py:162} INFO - Started process (PID=11678) to work on /usr/local/airflow/dags/connect_to_gdrive.py
[2021-09-03 08:31:57,423] {processor.py:613} INFO - Processing file /usr/local/airflow/dags/connect_to_gdrive.py for tasks to queue
[2021-09-03 08:31:57,423] {logging_mixin.py:109} INFO - [2021-09-03 08:31:57,423] {dagbag.py:496} INFO - Filling up the DagBag from /usr/local/airflow/dags/connect_to_gdrive.py
[2021-09-03 08:31:57,657] {processor.py:623} INFO - DAG(s) dict_keys(['hello_gdive']) retrieved from /usr/local/airflow/dags/connect_to_gdrive.py
[2021-09-03 08:31:57,669] {logging_mixin.py:109} INFO - [2021-09-03 08:31:57,669] {dag.py:1833} INFO - Sync 1 DAGs
[2021-09-03 08:31:57,677] {logging_mixin.py:109} INFO - [2021-09-03 08:31:57,677] {dag.py:2306} INFO - Setting next_dagrun for hello_gdive to None
[2021-09-03 08:31:57,682] {processor.py:170} INFO - Processing /usr/local/airflow/dags/connect_to_gdrive.py took 0.262 seconds
[2021-09-03 08:32:28,640] {processor.py:162} INFO - Started process (PID=12011) to work on /usr/local/airflow/dags/connect_to_gdrive.py
[2021-09-03 08:32:28,641] {processor.py:613} INFO - Processing file /usr/local/airflow/dags/connect_to_gdrive.py for tasks to queue
[2021-09-03 08:32:28,641] {logging_mixin.py:109} INFO - [2021-09-03 08:32:28,641] {dagbag.py:496} INFO - Filling up the DagBag from /usr/local/airflow/dags/connect_to_gdrive.py
[2021-09-03 08:32:28,859] {processor.py:623} INFO - DAG(s) dict_keys(['hello_gdive']) retrieved from /usr/local/airflow/dags/connect_to_gdrive.py
[2021-09-03 08:32:28,871] {logging_mixin.py:109} INFO - [2021-09-03 08:32:28,871] {dag.py:1833} INFO - Sync 1 DAGs
[2021-09-03 08:32:28,878] {logging_mixin.py:109} INFO - [2021-09-03 08:32:28,878] {dag.py:2306} INFO - Setting next_dagrun for hello_gdive to None
[2021-09-03 08:32:28,884] {processor.py:170} INFO - Processing /usr/local/airflow/dags/connect_to_gdrive.py took 0.246 seconds
[2021-09-03 08:32:58,930] {processor.py:162} INFO - Started process (PID=12353) to work on /usr/local/airflow/dags/connect_to_gdrive.py
[2021-09-03 08:32:58,932] {processor.py:613} INFO - Processing file /usr/local/airflow/dags/connect_to_gdrive.py for tasks to queue
[2021-09-03 08:32:58,933] {logging_mixin.py:109} INFO - [2021-09-03 08:32:58,932] {dagbag.py:496} INFO - Filling up the DagBag from /usr/local/airflow/dags/connect_to_gdrive.py
[2021-09-03 08:32:59,182] {processor.py:623} INFO - DAG(s) dict_keys(['hello_gdive']) retrieved from /usr/local/airflow/dags/connect_to_gdrive.py
[2021-09-03 08:32:59,194] {logging_mixin.py:109} INFO - [2021-09-03 08:32:59,193] {dag.py:1833} INFO - Sync 1 DAGs
[2021-09-03 08:32:59,201] {logging_mixin.py:109} INFO - [2021-09-03 08:32:59,201] {dag.py:2306} INFO - Setting next_dagrun for hello_gdive to None
[2021-09-03 08:32:59,205] {processor.py:170} INFO - Processing /usr/local/airflow/dags/connect_to_gdrive.py took 0.279 seconds
[2021-09-03 08:33:30,114] {processor.py:162} INFO - Started process (PID=12686) to work on /usr/local/airflow/dags/connect_to_gdrive.py
[2021-09-03 08:33:30,116] {processor.py:613} INFO - Processing file /usr/local/airflow/dags/connect_to_gdrive.py for tasks to queue
[2021-09-03 08:33:30,119] {logging_mixin.py:109} INFO - [2021-09-03 08:33:30,119] {dagbag.py:496} INFO - Filling up the DagBag from /usr/local/airflow/dags/connect_to_gdrive.py
[2021-09-03 08:33:30,326] {processor.py:623} INFO - DAG(s) dict_keys(['hello_gdive']) retrieved from /usr/local/airflow/dags/connect_to_gdrive.py
[2021-09-03 08:33:30,337] {logging_mixin.py:109} INFO - [2021-09-03 08:33:30,337] {dag.py:1833} INFO - Sync 1 DAGs
[2021-09-03 08:33:30,344] {logging_mixin.py:109} INFO - [2021-09-03 08:33:30,344] {dag.py:2306} INFO - Setting next_dagrun for hello_gdive to None
[2021-09-03 08:33:30,349] {processor.py:170} INFO - Processing /usr/local/airflow/dags/connect_to_gdrive.py took 0.239 seconds
[2021-09-03 08:34:00,421] {processor.py:162} INFO - Started process (PID=13029) to work on /usr/local/airflow/dags/connect_to_gdrive.py
[2021-09-03 08:34:00,422] {processor.py:613} INFO - Processing file /usr/local/airflow/dags/connect_to_gdrive.py for tasks to queue
[2021-09-03 08:34:00,423] {logging_mixin.py:109} INFO - [2021-09-03 08:34:00,423] {dagbag.py:496} INFO - Filling up the DagBag from /usr/local/airflow/dags/connect_to_gdrive.py
[2021-09-03 08:34:00,634] {processor.py:623} INFO - DAG(s) dict_keys(['hello_gdive']) retrieved from /usr/local/airflow/dags/connect_to_gdrive.py
[2021-09-03 08:34:00,645] {logging_mixin.py:109} INFO - [2021-09-03 08:34:00,645] {dag.py:1833} INFO - Sync 1 DAGs
[2021-09-03 08:34:00,653] {logging_mixin.py:109} INFO - [2021-09-03 08:34:00,653] {dag.py:2306} INFO - Setting next_dagrun for hello_gdive to None
[2021-09-03 08:34:00,661] {processor.py:170} INFO - Processing /usr/local/airflow/dags/connect_to_gdrive.py took 0.245 seconds
[2021-09-03 08:34:31,601] {processor.py:162} INFO - Started process (PID=13362) to work on /usr/local/airflow/dags/connect_to_gdrive.py
[2021-09-03 08:34:31,602] {processor.py:613} INFO - Processing file /usr/local/airflow/dags/connect_to_gdrive.py for tasks to queue
[2021-09-03 08:34:31,603] {logging_mixin.py:109} INFO - [2021-09-03 08:34:31,602] {dagbag.py:496} INFO - Filling up the DagBag from /usr/local/airflow/dags/connect_to_gdrive.py
[2021-09-03 08:34:31,811] {processor.py:623} INFO - DAG(s) dict_keys(['hello_gdive']) retrieved from /usr/local/airflow/dags/connect_to_gdrive.py
[2021-09-03 08:34:31,823] {logging_mixin.py:109} INFO - [2021-09-03 08:34:31,823] {dag.py:1833} INFO - Sync 1 DAGs
[2021-09-03 08:34:31,830] {logging_mixin.py:109} INFO - [2021-09-03 08:34:31,830] {dag.py:2306} INFO - Setting next_dagrun for hello_gdive to None
[2021-09-03 08:34:31,839] {processor.py:170} INFO - Processing /usr/local/airflow/dags/connect_to_gdrive.py took 0.242 seconds
[2021-09-03 08:35:01,906] {processor.py:162} INFO - Started process (PID=13705) to work on /usr/local/airflow/dags/connect_to_gdrive.py
[2021-09-03 08:35:01,908] {processor.py:613} INFO - Processing file /usr/local/airflow/dags/connect_to_gdrive.py for tasks to queue
[2021-09-03 08:35:01,909] {logging_mixin.py:109} INFO - [2021-09-03 08:35:01,909] {dagbag.py:496} INFO - Filling up the DagBag from /usr/local/airflow/dags/connect_to_gdrive.py
[2021-09-03 08:35:02,114] {processor.py:623} INFO - DAG(s) dict_keys(['hello_gdive']) retrieved from /usr/local/airflow/dags/connect_to_gdrive.py
[2021-09-03 08:35:02,125] {logging_mixin.py:109} INFO - [2021-09-03 08:35:02,125] {dag.py:1833} INFO - Sync 1 DAGs
[2021-09-03 08:35:02,133] {logging_mixin.py:109} INFO - [2021-09-03 08:35:02,133] {dag.py:2306} INFO - Setting next_dagrun for hello_gdive to None
[2021-09-03 08:35:02,142] {processor.py:170} INFO - Processing /usr/local/airflow/dags/connect_to_gdrive.py took 0.239 seconds
[2021-09-03 08:35:33,091] {processor.py:162} INFO - Started process (PID=14039) to work on /usr/local/airflow/dags/connect_to_gdrive.py
[2021-09-03 08:35:33,092] {processor.py:613} INFO - Processing file /usr/local/airflow/dags/connect_to_gdrive.py for tasks to queue
[2021-09-03 08:35:33,092] {logging_mixin.py:109} INFO - [2021-09-03 08:35:33,092] {dagbag.py:496} INFO - Filling up the DagBag from /usr/local/airflow/dags/connect_to_gdrive.py
[2021-09-03 08:35:33,296] {processor.py:623} INFO - DAG(s) dict_keys(['hello_gdive']) retrieved from /usr/local/airflow/dags/connect_to_gdrive.py
[2021-09-03 08:35:33,308] {logging_mixin.py:109} INFO - [2021-09-03 08:35:33,308] {dag.py:1833} INFO - Sync 1 DAGs
[2021-09-03 08:35:33,315] {logging_mixin.py:109} INFO - [2021-09-03 08:35:33,315] {dag.py:2306} INFO - Setting next_dagrun for hello_gdive to None
[2021-09-03 08:35:33,320] {processor.py:170} INFO - Processing /usr/local/airflow/dags/connect_to_gdrive.py took 0.233 seconds
[2021-09-03 08:36:03,348] {processor.py:162} INFO - Started process (PID=14378) to work on /usr/local/airflow/dags/connect_to_gdrive.py
[2021-09-03 08:36:03,349] {processor.py:613} INFO - Processing file /usr/local/airflow/dags/connect_to_gdrive.py for tasks to queue
[2021-09-03 08:36:03,349] {logging_mixin.py:109} INFO - [2021-09-03 08:36:03,349] {dagbag.py:496} INFO - Filling up the DagBag from /usr/local/airflow/dags/connect_to_gdrive.py
[2021-09-03 08:36:03,554] {processor.py:623} INFO - DAG(s) dict_keys(['hello_gdive']) retrieved from /usr/local/airflow/dags/connect_to_gdrive.py
[2021-09-03 08:36:03,565] {logging_mixin.py:109} INFO - [2021-09-03 08:36:03,565] {dag.py:1833} INFO - Sync 1 DAGs
[2021-09-03 08:36:03,572] {logging_mixin.py:109} INFO - [2021-09-03 08:36:03,572] {dag.py:2306} INFO - Setting next_dagrun for hello_gdive to None
[2021-09-03 08:36:03,578] {processor.py:170} INFO - Processing /usr/local/airflow/dags/connect_to_gdrive.py took 0.234 seconds
[2021-09-03 08:36:33,663] {processor.py:162} INFO - Started process (PID=14746) to work on /usr/local/airflow/dags/connect_to_gdrive.py
[2021-09-03 08:36:33,664] {processor.py:613} INFO - Processing file /usr/local/airflow/dags/connect_to_gdrive.py for tasks to queue
[2021-09-03 08:36:33,664] {logging_mixin.py:109} INFO - [2021-09-03 08:36:33,664] {dagbag.py:496} INFO - Filling up the DagBag from /usr/local/airflow/dags/connect_to_gdrive.py
[2021-09-03 08:36:33,874] {processor.py:623} INFO - DAG(s) dict_keys(['hello_gdive']) retrieved from /usr/local/airflow/dags/connect_to_gdrive.py
[2021-09-03 08:36:33,886] {logging_mixin.py:109} INFO - [2021-09-03 08:36:33,886] {dag.py:1833} INFO - Sync 1 DAGs
[2021-09-03 08:36:33,896] {logging_mixin.py:109} INFO - [2021-09-03 08:36:33,896] {dag.py:2306} INFO - Setting next_dagrun for hello_gdive to None
[2021-09-03 08:36:33,900] {processor.py:170} INFO - Processing /usr/local/airflow/dags/connect_to_gdrive.py took 0.240 seconds
[2021-09-03 08:37:04,866] {processor.py:162} INFO - Started process (PID=15227) to work on /usr/local/airflow/dags/connect_to_gdrive.py
[2021-09-03 08:37:04,867] {processor.py:613} INFO - Processing file /usr/local/airflow/dags/connect_to_gdrive.py for tasks to queue
[2021-09-03 08:37:04,868] {logging_mixin.py:109} INFO - [2021-09-03 08:37:04,868] {dagbag.py:496} INFO - Filling up the DagBag from /usr/local/airflow/dags/connect_to_gdrive.py
[2021-09-03 08:37:05,077] {processor.py:623} INFO - DAG(s) dict_keys(['hello_gdive']) retrieved from /usr/local/airflow/dags/connect_to_gdrive.py
[2021-09-03 08:37:05,088] {logging_mixin.py:109} INFO - [2021-09-03 08:37:05,088] {dag.py:1833} INFO - Sync 1 DAGs
[2021-09-03 08:37:05,095] {logging_mixin.py:109} INFO - [2021-09-03 08:37:05,095] {dag.py:2306} INFO - Setting next_dagrun for hello_gdive to None
[2021-09-03 08:37:05,100] {processor.py:170} INFO - Processing /usr/local/airflow/dags/connect_to_gdrive.py took 0.237 seconds
[2021-09-03 08:37:35,141] {processor.py:162} INFO - Started process (PID=15547) to work on /usr/local/airflow/dags/connect_to_gdrive.py
[2021-09-03 08:37:35,142] {processor.py:613} INFO - Processing file /usr/local/airflow/dags/connect_to_gdrive.py for tasks to queue
[2021-09-03 08:37:35,143] {logging_mixin.py:109} INFO - [2021-09-03 08:37:35,143] {dagbag.py:496} INFO - Filling up the DagBag from /usr/local/airflow/dags/connect_to_gdrive.py
[2021-09-03 08:37:35,352] {processor.py:623} INFO - DAG(s) dict_keys(['hello_gdive']) retrieved from /usr/local/airflow/dags/connect_to_gdrive.py
[2021-09-03 08:37:35,364] {logging_mixin.py:109} INFO - [2021-09-03 08:37:35,364] {dag.py:1833} INFO - Sync 1 DAGs
[2021-09-03 08:37:35,371] {logging_mixin.py:109} INFO - [2021-09-03 08:37:35,371] {dag.py:2306} INFO - Setting next_dagrun for hello_gdive to None
[2021-09-03 08:37:35,376] {processor.py:170} INFO - Processing /usr/local/airflow/dags/connect_to_gdrive.py took 0.239 seconds
[2021-09-03 08:38:06,331] {processor.py:162} INFO - Started process (PID=15899) to work on /usr/local/airflow/dags/connect_to_gdrive.py
[2021-09-03 08:38:06,332] {processor.py:613} INFO - Processing file /usr/local/airflow/dags/connect_to_gdrive.py for tasks to queue
[2021-09-03 08:38:06,332] {logging_mixin.py:109} INFO - [2021-09-03 08:38:06,332] {dagbag.py:496} INFO - Filling up the DagBag from /usr/local/airflow/dags/connect_to_gdrive.py
[2021-09-03 08:38:06,553] {processor.py:623} INFO - DAG(s) dict_keys(['hello_gdive']) retrieved from /usr/local/airflow/dags/connect_to_gdrive.py
[2021-09-03 08:38:06,564] {logging_mixin.py:109} INFO - [2021-09-03 08:38:06,564] {dag.py:1833} INFO - Sync 1 DAGs
[2021-09-03 08:38:06,571] {logging_mixin.py:109} INFO - [2021-09-03 08:38:06,571] {dag.py:2306} INFO - Setting next_dagrun for hello_gdive to None
[2021-09-03 08:38:06,576] {processor.py:170} INFO - Processing /usr/local/airflow/dags/connect_to_gdrive.py took 0.249 seconds
[2021-09-03 08:38:36,611] {processor.py:162} INFO - Started process (PID=16225) to work on /usr/local/airflow/dags/connect_to_gdrive.py
[2021-09-03 08:38:36,613] {processor.py:613} INFO - Processing file /usr/local/airflow/dags/connect_to_gdrive.py for tasks to queue
[2021-09-03 08:38:36,613] {logging_mixin.py:109} INFO - [2021-09-03 08:38:36,613] {dagbag.py:496} INFO - Filling up the DagBag from /usr/local/airflow/dags/connect_to_gdrive.py
[2021-09-03 08:38:36,822] {processor.py:623} INFO - DAG(s) dict_keys(['hello_gdive']) retrieved from /usr/local/airflow/dags/connect_to_gdrive.py
[2021-09-03 08:38:36,834] {logging_mixin.py:109} INFO - [2021-09-03 08:38:36,834] {dag.py:1833} INFO - Sync 1 DAGs
[2021-09-03 08:38:36,841] {logging_mixin.py:109} INFO - [2021-09-03 08:38:36,841] {dag.py:2306} INFO - Setting next_dagrun for hello_gdive to None
[2021-09-03 08:38:36,847] {processor.py:170} INFO - Processing /usr/local/airflow/dags/connect_to_gdrive.py took 0.239 seconds
[2021-09-03 08:39:07,803] {processor.py:162} INFO - Started process (PID=16576) to work on /usr/local/airflow/dags/connect_to_gdrive.py
[2021-09-03 08:39:07,805] {processor.py:613} INFO - Processing file /usr/local/airflow/dags/connect_to_gdrive.py for tasks to queue
[2021-09-03 08:39:07,805] {logging_mixin.py:109} INFO - [2021-09-03 08:39:07,805] {dagbag.py:496} INFO - Filling up the DagBag from /usr/local/airflow/dags/connect_to_gdrive.py
[2021-09-03 08:39:08,009] {processor.py:623} INFO - DAG(s) dict_keys(['hello_gdive']) retrieved from /usr/local/airflow/dags/connect_to_gdrive.py
[2021-09-03 08:39:08,021] {logging_mixin.py:109} INFO - [2021-09-03 08:39:08,021] {dag.py:1833} INFO - Sync 1 DAGs
[2021-09-03 08:39:08,028] {logging_mixin.py:109} INFO - [2021-09-03 08:39:08,028] {dag.py:2306} INFO - Setting next_dagrun for hello_gdive to None
[2021-09-03 08:39:08,032] {processor.py:170} INFO - Processing /usr/local/airflow/dags/connect_to_gdrive.py took 0.233 seconds
[2021-09-03 08:39:38,086] {processor.py:162} INFO - Started process (PID=16902) to work on /usr/local/airflow/dags/connect_to_gdrive.py
[2021-09-03 08:39:38,087] {processor.py:613} INFO - Processing file /usr/local/airflow/dags/connect_to_gdrive.py for tasks to queue
[2021-09-03 08:39:38,087] {logging_mixin.py:109} INFO - [2021-09-03 08:39:38,087] {dagbag.py:496} INFO - Filling up the DagBag from /usr/local/airflow/dags/connect_to_gdrive.py
[2021-09-03 08:39:38,285] {processor.py:623} INFO - DAG(s) dict_keys(['hello_gdive']) retrieved from /usr/local/airflow/dags/connect_to_gdrive.py
[2021-09-03 08:39:38,296] {logging_mixin.py:109} INFO - [2021-09-03 08:39:38,296] {dag.py:1833} INFO - Sync 1 DAGs
[2021-09-03 08:39:38,305] {logging_mixin.py:109} INFO - [2021-09-03 08:39:38,305] {dag.py:2306} INFO - Setting next_dagrun for hello_gdive to None
[2021-09-03 08:39:38,323] {processor.py:170} INFO - Processing /usr/local/airflow/dags/connect_to_gdrive.py took 0.239 seconds
[2021-09-03 08:40:09,275] {processor.py:162} INFO - Started process (PID=17253) to work on /usr/local/airflow/dags/connect_to_gdrive.py
[2021-09-03 08:40:09,276] {processor.py:613} INFO - Processing file /usr/local/airflow/dags/connect_to_gdrive.py for tasks to queue
[2021-09-03 08:40:09,277] {logging_mixin.py:109} INFO - [2021-09-03 08:40:09,277] {dagbag.py:496} INFO - Filling up the DagBag from /usr/local/airflow/dags/connect_to_gdrive.py
[2021-09-03 08:40:09,481] {processor.py:623} INFO - DAG(s) dict_keys(['hello_gdive']) retrieved from /usr/local/airflow/dags/connect_to_gdrive.py
[2021-09-03 08:40:09,493] {logging_mixin.py:109} INFO - [2021-09-03 08:40:09,492] {dag.py:1833} INFO - Sync 1 DAGs
[2021-09-03 08:40:09,500] {logging_mixin.py:109} INFO - [2021-09-03 08:40:09,500] {dag.py:2306} INFO - Setting next_dagrun for hello_gdive to None
[2021-09-03 08:40:09,506] {processor.py:170} INFO - Processing /usr/local/airflow/dags/connect_to_gdrive.py took 0.235 seconds
[2021-09-03 08:40:39,565] {processor.py:162} INFO - Started process (PID=17580) to work on /usr/local/airflow/dags/connect_to_gdrive.py
[2021-09-03 08:40:39,566] {processor.py:613} INFO - Processing file /usr/local/airflow/dags/connect_to_gdrive.py for tasks to queue
[2021-09-03 08:40:39,566] {logging_mixin.py:109} INFO - [2021-09-03 08:40:39,566] {dagbag.py:496} INFO - Filling up the DagBag from /usr/local/airflow/dags/connect_to_gdrive.py
[2021-09-03 08:40:39,778] {processor.py:623} INFO - DAG(s) dict_keys(['hello_gdive']) retrieved from /usr/local/airflow/dags/connect_to_gdrive.py
[2021-09-03 08:40:39,792] {logging_mixin.py:109} INFO - [2021-09-03 08:40:39,791] {dag.py:1833} INFO - Sync 1 DAGs
[2021-09-03 08:40:39,802] {logging_mixin.py:109} INFO - [2021-09-03 08:40:39,802] {dag.py:2306} INFO - Setting next_dagrun for hello_gdive to None
[2021-09-03 08:40:39,811] {processor.py:170} INFO - Processing /usr/local/airflow/dags/connect_to_gdrive.py took 0.251 seconds
[2021-09-03 08:41:10,749] {processor.py:162} INFO - Started process (PID=17924) to work on /usr/local/airflow/dags/connect_to_gdrive.py
[2021-09-03 08:41:10,750] {processor.py:613} INFO - Processing file /usr/local/airflow/dags/connect_to_gdrive.py for tasks to queue
[2021-09-03 08:41:10,751] {logging_mixin.py:109} INFO - [2021-09-03 08:41:10,751] {dagbag.py:496} INFO - Filling up the DagBag from /usr/local/airflow/dags/connect_to_gdrive.py
[2021-09-03 08:41:10,958] {processor.py:623} INFO - DAG(s) dict_keys(['hello_gdive']) retrieved from /usr/local/airflow/dags/connect_to_gdrive.py
[2021-09-03 08:41:10,971] {logging_mixin.py:109} INFO - [2021-09-03 08:41:10,971] {dag.py:1833} INFO - Sync 1 DAGs
[2021-09-03 08:41:10,979] {logging_mixin.py:109} INFO - [2021-09-03 08:41:10,979] {dag.py:2306} INFO - Setting next_dagrun for hello_gdive to None
[2021-09-03 08:41:10,992] {processor.py:170} INFO - Processing /usr/local/airflow/dags/connect_to_gdrive.py took 0.247 seconds
[2021-09-03 08:41:41,043] {processor.py:162} INFO - Started process (PID=18257) to work on /usr/local/airflow/dags/connect_to_gdrive.py
[2021-09-03 08:41:41,045] {processor.py:613} INFO - Processing file /usr/local/airflow/dags/connect_to_gdrive.py for tasks to queue
[2021-09-03 08:41:41,045] {logging_mixin.py:109} INFO - [2021-09-03 08:41:41,045] {dagbag.py:496} INFO - Filling up the DagBag from /usr/local/airflow/dags/connect_to_gdrive.py
[2021-09-03 08:41:41,249] {processor.py:623} INFO - DAG(s) dict_keys(['hello_gdive']) retrieved from /usr/local/airflow/dags/connect_to_gdrive.py
[2021-09-03 08:41:41,260] {logging_mixin.py:109} INFO - [2021-09-03 08:41:41,260] {dag.py:1833} INFO - Sync 1 DAGs
[2021-09-03 08:41:41,267] {logging_mixin.py:109} INFO - [2021-09-03 08:41:41,267] {dag.py:2306} INFO - Setting next_dagrun for hello_gdive to None
[2021-09-03 08:41:41,272] {processor.py:170} INFO - Processing /usr/local/airflow/dags/connect_to_gdrive.py took 0.232 seconds
[2021-09-03 08:42:12,228] {processor.py:162} INFO - Started process (PID=18600) to work on /usr/local/airflow/dags/connect_to_gdrive.py
[2021-09-03 08:42:12,229] {processor.py:613} INFO - Processing file /usr/local/airflow/dags/connect_to_gdrive.py for tasks to queue
[2021-09-03 08:42:12,229] {logging_mixin.py:109} INFO - [2021-09-03 08:42:12,229] {dagbag.py:496} INFO - Filling up the DagBag from /usr/local/airflow/dags/connect_to_gdrive.py
[2021-09-03 08:42:12,432] {processor.py:623} INFO - DAG(s) dict_keys(['hello_gdive']) retrieved from /usr/local/airflow/dags/connect_to_gdrive.py
[2021-09-03 08:42:12,443] {logging_mixin.py:109} INFO - [2021-09-03 08:42:12,443] {dag.py:1833} INFO - Sync 1 DAGs
[2021-09-03 08:42:12,451] {logging_mixin.py:109} INFO - [2021-09-03 08:42:12,450] {dag.py:2306} INFO - Setting next_dagrun for hello_gdive to None
[2021-09-03 08:42:12,456] {processor.py:170} INFO - Processing /usr/local/airflow/dags/connect_to_gdrive.py took 0.232 seconds
[2021-09-03 08:42:42,488] {processor.py:162} INFO - Started process (PID=18933) to work on /usr/local/airflow/dags/connect_to_gdrive.py
[2021-09-03 08:42:42,490] {processor.py:613} INFO - Processing file /usr/local/airflow/dags/connect_to_gdrive.py for tasks to queue
[2021-09-03 08:42:42,490] {logging_mixin.py:109} INFO - [2021-09-03 08:42:42,490] {dagbag.py:496} INFO - Filling up the DagBag from /usr/local/airflow/dags/connect_to_gdrive.py
[2021-09-03 08:42:42,702] {processor.py:623} INFO - DAG(s) dict_keys(['hello_gdive']) retrieved from /usr/local/airflow/dags/connect_to_gdrive.py
[2021-09-03 08:42:42,713] {logging_mixin.py:109} INFO - [2021-09-03 08:42:42,713] {dag.py:1833} INFO - Sync 1 DAGs
[2021-09-03 08:42:42,721] {logging_mixin.py:109} INFO - [2021-09-03 08:42:42,720] {dag.py:2306} INFO - Setting next_dagrun for hello_gdive to None
[2021-09-03 08:42:42,726] {processor.py:170} INFO - Processing /usr/local/airflow/dags/connect_to_gdrive.py took 0.242 seconds
[2021-09-03 08:43:12,755] {processor.py:162} INFO - Started process (PID=19263) to work on /usr/local/airflow/dags/connect_to_gdrive.py
[2021-09-03 08:43:12,756] {processor.py:613} INFO - Processing file /usr/local/airflow/dags/connect_to_gdrive.py for tasks to queue
[2021-09-03 08:43:12,757] {logging_mixin.py:109} INFO - [2021-09-03 08:43:12,756] {dagbag.py:496} INFO - Filling up the DagBag from /usr/local/airflow/dags/connect_to_gdrive.py
[2021-09-03 08:43:13,029] {processor.py:623} INFO - DAG(s) dict_keys(['hello_gdive']) retrieved from /usr/local/airflow/dags/connect_to_gdrive.py
[2021-09-03 08:43:13,050] {logging_mixin.py:109} INFO - [2021-09-03 08:43:13,050] {dag.py:1833} INFO - Sync 1 DAGs
[2021-09-03 08:43:13,065] {logging_mixin.py:109} INFO - [2021-09-03 08:43:13,065] {dag.py:2306} INFO - Setting next_dagrun for hello_gdive to None
[2021-09-03 08:43:13,076] {processor.py:170} INFO - Processing /usr/local/airflow/dags/connect_to_gdrive.py took 0.324 seconds
[2021-09-03 08:43:43,954] {processor.py:162} INFO - Started process (PID=19605) to work on /usr/local/airflow/dags/connect_to_gdrive.py
[2021-09-03 08:43:43,956] {processor.py:613} INFO - Processing file /usr/local/airflow/dags/connect_to_gdrive.py for tasks to queue
[2021-09-03 08:43:43,956] {logging_mixin.py:109} INFO - [2021-09-03 08:43:43,956] {dagbag.py:496} INFO - Filling up the DagBag from /usr/local/airflow/dags/connect_to_gdrive.py
[2021-09-03 08:43:44,217] {processor.py:623} INFO - DAG(s) dict_keys(['hello_gdive']) retrieved from /usr/local/airflow/dags/connect_to_gdrive.py
[2021-09-03 08:43:44,230] {logging_mixin.py:109} INFO - [2021-09-03 08:43:44,229] {dag.py:1833} INFO - Sync 1 DAGs
[2021-09-03 08:43:44,238] {logging_mixin.py:109} INFO - [2021-09-03 08:43:44,238] {dag.py:2306} INFO - Setting next_dagrun for hello_gdive to 2021-08-14 17:00:00+00:00
[2021-09-03 08:43:44,245] {processor.py:170} INFO - Processing /usr/local/airflow/dags/connect_to_gdrive.py took 0.294 seconds
[2021-09-03 08:44:15,179] {processor.py:162} INFO - Started process (PID=19955) to work on /usr/local/airflow/dags/connect_to_gdrive.py
[2021-09-03 08:44:15,181] {processor.py:613} INFO - Processing file /usr/local/airflow/dags/connect_to_gdrive.py for tasks to queue
[2021-09-03 08:44:15,181] {logging_mixin.py:109} INFO - [2021-09-03 08:44:15,181] {dagbag.py:496} INFO - Filling up the DagBag from /usr/local/airflow/dags/connect_to_gdrive.py
[2021-09-03 08:44:15,394] {processor.py:623} INFO - DAG(s) dict_keys(['hello_gdive']) retrieved from /usr/local/airflow/dags/connect_to_gdrive.py
[2021-09-03 08:44:15,406] {logging_mixin.py:109} INFO - [2021-09-03 08:44:15,406] {dag.py:1833} INFO - Sync 1 DAGs
[2021-09-03 08:44:15,413] {logging_mixin.py:109} INFO - [2021-09-03 08:44:15,413] {dag.py:2306} INFO - Setting next_dagrun for hello_gdive to None
[2021-09-03 08:44:15,418] {processor.py:170} INFO - Processing /usr/local/airflow/dags/connect_to_gdrive.py took 0.242 seconds
[2021-09-03 08:44:45,441] {processor.py:162} INFO - Started process (PID=20300) to work on /usr/local/airflow/dags/connect_to_gdrive.py
[2021-09-03 08:44:45,443] {processor.py:613} INFO - Processing file /usr/local/airflow/dags/connect_to_gdrive.py for tasks to queue
[2021-09-03 08:44:45,444] {logging_mixin.py:109} INFO - [2021-09-03 08:44:45,443] {dagbag.py:496} INFO - Filling up the DagBag from /usr/local/airflow/dags/connect_to_gdrive.py
[2021-09-03 08:44:45,649] {processor.py:623} INFO - DAG(s) dict_keys(['hello_gdive']) retrieved from /usr/local/airflow/dags/connect_to_gdrive.py
[2021-09-03 08:44:45,661] {logging_mixin.py:109} INFO - [2021-09-03 08:44:45,661] {dag.py:1833} INFO - Sync 1 DAGs
[2021-09-03 08:44:45,668] {logging_mixin.py:109} INFO - [2021-09-03 08:44:45,668] {dag.py:2306} INFO - Setting next_dagrun for hello_gdive to None
[2021-09-03 08:44:45,673] {processor.py:170} INFO - Processing /usr/local/airflow/dags/connect_to_gdrive.py took 0.235 seconds
[2021-09-03 08:45:16,628] {processor.py:162} INFO - Started process (PID=20634) to work on /usr/local/airflow/dags/connect_to_gdrive.py
[2021-09-03 08:45:16,629] {processor.py:613} INFO - Processing file /usr/local/airflow/dags/connect_to_gdrive.py for tasks to queue
[2021-09-03 08:45:16,630] {logging_mixin.py:109} INFO - [2021-09-03 08:45:16,630] {dagbag.py:496} INFO - Filling up the DagBag from /usr/local/airflow/dags/connect_to_gdrive.py
[2021-09-03 08:45:16,832] {processor.py:623} INFO - DAG(s) dict_keys(['hello_gdive']) retrieved from /usr/local/airflow/dags/connect_to_gdrive.py
[2021-09-03 08:45:16,843] {logging_mixin.py:109} INFO - [2021-09-03 08:45:16,843] {dag.py:1833} INFO - Sync 1 DAGs
[2021-09-03 08:45:16,851] {logging_mixin.py:109} INFO - [2021-09-03 08:45:16,851] {dag.py:2306} INFO - Setting next_dagrun for hello_gdive to None
[2021-09-03 08:45:16,861] {processor.py:170} INFO - Processing /usr/local/airflow/dags/connect_to_gdrive.py took 0.236 seconds
[2021-09-03 08:45:46,884] {processor.py:162} INFO - Started process (PID=20977) to work on /usr/local/airflow/dags/connect_to_gdrive.py
[2021-09-03 08:45:46,885] {processor.py:613} INFO - Processing file /usr/local/airflow/dags/connect_to_gdrive.py for tasks to queue
[2021-09-03 08:45:46,885] {logging_mixin.py:109} INFO - [2021-09-03 08:45:46,885] {dagbag.py:496} INFO - Filling up the DagBag from /usr/local/airflow/dags/connect_to_gdrive.py
[2021-09-03 08:45:47,089] {processor.py:623} INFO - DAG(s) dict_keys(['hello_gdive']) retrieved from /usr/local/airflow/dags/connect_to_gdrive.py
[2021-09-03 08:45:47,101] {logging_mixin.py:109} INFO - [2021-09-03 08:45:47,101] {dag.py:1833} INFO - Sync 1 DAGs
[2021-09-03 08:45:47,109] {logging_mixin.py:109} INFO - [2021-09-03 08:45:47,109] {dag.py:2306} INFO - Setting next_dagrun for hello_gdive to None
[2021-09-03 08:45:47,119] {processor.py:170} INFO - Processing /usr/local/airflow/dags/connect_to_gdrive.py took 0.239 seconds
[2021-09-03 08:46:17,145] {processor.py:162} INFO - Started process (PID=21302) to work on /usr/local/airflow/dags/connect_to_gdrive.py
[2021-09-03 08:46:17,146] {processor.py:613} INFO - Processing file /usr/local/airflow/dags/connect_to_gdrive.py for tasks to queue
[2021-09-03 08:46:17,146] {logging_mixin.py:109} INFO - [2021-09-03 08:46:17,146] {dagbag.py:496} INFO - Filling up the DagBag from /usr/local/airflow/dags/connect_to_gdrive.py
[2021-09-03 08:46:17,391] {processor.py:623} INFO - DAG(s) dict_keys(['hello_gdive']) retrieved from /usr/local/airflow/dags/connect_to_gdrive.py
[2021-09-03 08:46:17,446] {logging_mixin.py:109} INFO - [2021-09-03 08:46:17,446] {dag.py:1833} INFO - Sync 1 DAGs
[2021-09-03 08:46:17,459] {logging_mixin.py:109} INFO - [2021-09-03 08:46:17,459] {dag.py:2306} INFO - Setting next_dagrun for hello_gdive to None
[2021-09-03 08:46:17,467] {processor.py:170} INFO - Processing /usr/local/airflow/dags/connect_to_gdrive.py took 0.326 seconds
[2021-09-03 08:46:48,325] {processor.py:162} INFO - Started process (PID=21654) to work on /usr/local/airflow/dags/connect_to_gdrive.py
[2021-09-03 08:46:48,326] {processor.py:613} INFO - Processing file /usr/local/airflow/dags/connect_to_gdrive.py for tasks to queue
[2021-09-03 08:46:48,327] {logging_mixin.py:109} INFO - [2021-09-03 08:46:48,327] {dagbag.py:496} INFO - Filling up the DagBag from /usr/local/airflow/dags/connect_to_gdrive.py
[2021-09-03 08:46:48,558] {processor.py:623} INFO - DAG(s) dict_keys(['hello_gdive']) retrieved from /usr/local/airflow/dags/connect_to_gdrive.py
[2021-09-03 08:46:48,569] {logging_mixin.py:109} INFO - [2021-09-03 08:46:48,569] {dag.py:1833} INFO - Sync 1 DAGs
[2021-09-03 08:46:48,577] {logging_mixin.py:109} INFO - [2021-09-03 08:46:48,576] {dag.py:2306} INFO - Setting next_dagrun for hello_gdive to None
[2021-09-03 08:46:48,583] {processor.py:170} INFO - Processing /usr/local/airflow/dags/connect_to_gdrive.py took 0.263 seconds
[2021-09-03 08:47:18,606] {processor.py:162} INFO - Started process (PID=21987) to work on /usr/local/airflow/dags/connect_to_gdrive.py
[2021-09-03 08:47:18,607] {processor.py:613} INFO - Processing file /usr/local/airflow/dags/connect_to_gdrive.py for tasks to queue
[2021-09-03 08:47:18,608] {logging_mixin.py:109} INFO - [2021-09-03 08:47:18,608] {dagbag.py:496} INFO - Filling up the DagBag from /usr/local/airflow/dags/connect_to_gdrive.py
[2021-09-03 08:47:18,909] {processor.py:623} INFO - DAG(s) dict_keys(['hello_gdive']) retrieved from /usr/local/airflow/dags/connect_to_gdrive.py
[2021-09-03 08:47:18,924] {logging_mixin.py:109} INFO - [2021-09-03 08:47:18,924] {dag.py:1833} INFO - Sync 1 DAGs
[2021-09-03 08:47:18,933] {logging_mixin.py:109} INFO - [2021-09-03 08:47:18,933] {dag.py:2306} INFO - Setting next_dagrun for hello_gdive to None
[2021-09-03 08:47:18,940] {processor.py:170} INFO - Processing /usr/local/airflow/dags/connect_to_gdrive.py took 0.338 seconds
[2021-09-03 08:47:49,804] {processor.py:162} INFO - Started process (PID=22337) to work on /usr/local/airflow/dags/connect_to_gdrive.py
[2021-09-03 08:47:49,805] {processor.py:613} INFO - Processing file /usr/local/airflow/dags/connect_to_gdrive.py for tasks to queue
[2021-09-03 08:47:49,806] {logging_mixin.py:109} INFO - [2021-09-03 08:47:49,806] {dagbag.py:496} INFO - Filling up the DagBag from /usr/local/airflow/dags/connect_to_gdrive.py
[2021-09-03 08:47:50,049] {processor.py:623} INFO - DAG(s) dict_keys(['hello_gdive']) retrieved from /usr/local/airflow/dags/connect_to_gdrive.py
[2021-09-03 08:47:50,060] {logging_mixin.py:109} INFO - [2021-09-03 08:47:50,060] {dag.py:1833} INFO - Sync 1 DAGs
[2021-09-03 08:47:50,067] {logging_mixin.py:109} INFO - [2021-09-03 08:47:50,067] {dag.py:2306} INFO - Setting next_dagrun for hello_gdive to None
[2021-09-03 08:47:50,072] {processor.py:170} INFO - Processing /usr/local/airflow/dags/connect_to_gdrive.py took 0.273 seconds
[2021-09-03 08:48:21,010] {processor.py:162} INFO - Started process (PID=22672) to work on /usr/local/airflow/dags/connect_to_gdrive.py
[2021-09-03 08:48:21,011] {processor.py:613} INFO - Processing file /usr/local/airflow/dags/connect_to_gdrive.py for tasks to queue
[2021-09-03 08:48:21,011] {logging_mixin.py:109} INFO - [2021-09-03 08:48:21,011] {dagbag.py:496} INFO - Filling up the DagBag from /usr/local/airflow/dags/connect_to_gdrive.py
[2021-09-03 08:48:21,204] {processor.py:623} INFO - DAG(s) dict_keys(['hello_gdive']) retrieved from /usr/local/airflow/dags/connect_to_gdrive.py
[2021-09-03 08:48:21,215] {logging_mixin.py:109} INFO - [2021-09-03 08:48:21,215] {dag.py:1833} INFO - Sync 1 DAGs
[2021-09-03 08:48:21,223] {logging_mixin.py:109} INFO - [2021-09-03 08:48:21,223] {dag.py:2306} INFO - Setting next_dagrun for hello_gdive to None
[2021-09-03 08:48:21,228] {processor.py:170} INFO - Processing /usr/local/airflow/dags/connect_to_gdrive.py took 0.221 seconds
[2021-09-03 08:48:51,278] {processor.py:162} INFO - Started process (PID=23010) to work on /usr/local/airflow/dags/connect_to_gdrive.py
[2021-09-03 08:48:51,279] {processor.py:613} INFO - Processing file /usr/local/airflow/dags/connect_to_gdrive.py for tasks to queue
[2021-09-03 08:48:51,279] {logging_mixin.py:109} INFO - [2021-09-03 08:48:51,279] {dagbag.py:496} INFO - Filling up the DagBag from /usr/local/airflow/dags/connect_to_gdrive.py
[2021-09-03 08:48:51,497] {processor.py:623} INFO - DAG(s) dict_keys(['hello_gdive']) retrieved from /usr/local/airflow/dags/connect_to_gdrive.py
[2021-09-03 08:48:51,510] {logging_mixin.py:109} INFO - [2021-09-03 08:48:51,510] {dag.py:1833} INFO - Sync 1 DAGs
[2021-09-03 08:48:51,519] {logging_mixin.py:109} INFO - [2021-09-03 08:48:51,519] {dag.py:2306} INFO - Setting next_dagrun for hello_gdive to None
[2021-09-03 08:48:51,527] {processor.py:170} INFO - Processing /usr/local/airflow/dags/connect_to_gdrive.py took 0.252 seconds
[2021-09-03 08:49:22,461] {processor.py:162} INFO - Started process (PID=23349) to work on /usr/local/airflow/dags/connect_to_gdrive.py
[2021-09-03 08:49:22,463] {processor.py:613} INFO - Processing file /usr/local/airflow/dags/connect_to_gdrive.py for tasks to queue
[2021-09-03 08:49:22,463] {logging_mixin.py:109} INFO - [2021-09-03 08:49:22,463] {dagbag.py:496} INFO - Filling up the DagBag from /usr/local/airflow/dags/connect_to_gdrive.py
[2021-09-03 08:49:22,686] {processor.py:623} INFO - DAG(s) dict_keys(['hello_gdive']) retrieved from /usr/local/airflow/dags/connect_to_gdrive.py
[2021-09-03 08:49:22,697] {logging_mixin.py:109} INFO - [2021-09-03 08:49:22,696] {dag.py:1833} INFO - Sync 1 DAGs
[2021-09-03 08:49:22,705] {logging_mixin.py:109} INFO - [2021-09-03 08:49:22,704] {dag.py:2306} INFO - Setting next_dagrun for hello_gdive to None
[2021-09-03 08:49:22,709] {processor.py:170} INFO - Processing /usr/local/airflow/dags/connect_to_gdrive.py took 0.252 seconds
[2021-09-03 08:49:53,670] {processor.py:162} INFO - Started process (PID=23743) to work on /usr/local/airflow/dags/connect_to_gdrive.py
[2021-09-03 08:49:53,672] {processor.py:613} INFO - Processing file /usr/local/airflow/dags/connect_to_gdrive.py for tasks to queue
[2021-09-03 08:49:53,672] {logging_mixin.py:109} INFO - [2021-09-03 08:49:53,672] {dagbag.py:496} INFO - Filling up the DagBag from /usr/local/airflow/dags/connect_to_gdrive.py
[2021-09-03 08:49:53,878] {processor.py:623} INFO - DAG(s) dict_keys(['hello_gdive']) retrieved from /usr/local/airflow/dags/connect_to_gdrive.py
[2021-09-03 08:49:53,889] {logging_mixin.py:109} INFO - [2021-09-03 08:49:53,889] {dag.py:1833} INFO - Sync 1 DAGs
[2021-09-03 08:49:53,899] {logging_mixin.py:109} INFO - [2021-09-03 08:49:53,899] {dag.py:2306} INFO - Setting next_dagrun for hello_gdive to None
[2021-09-03 08:49:53,905] {processor.py:170} INFO - Processing /usr/local/airflow/dags/connect_to_gdrive.py took 0.239 seconds
[2021-09-03 08:50:23,933] {processor.py:162} INFO - Started process (PID=24077) to work on /usr/local/airflow/dags/connect_to_gdrive.py
[2021-09-03 08:50:23,934] {processor.py:613} INFO - Processing file /usr/local/airflow/dags/connect_to_gdrive.py for tasks to queue
[2021-09-03 08:50:23,935] {logging_mixin.py:109} INFO - [2021-09-03 08:50:23,935] {dagbag.py:496} INFO - Filling up the DagBag from /usr/local/airflow/dags/connect_to_gdrive.py
[2021-09-03 08:50:24,137] {processor.py:623} INFO - DAG(s) dict_keys(['hello_gdive']) retrieved from /usr/local/airflow/dags/connect_to_gdrive.py
[2021-09-03 08:50:24,148] {logging_mixin.py:109} INFO - [2021-09-03 08:50:24,148] {dag.py:1833} INFO - Sync 1 DAGs
[2021-09-03 08:50:24,156] {logging_mixin.py:109} INFO - [2021-09-03 08:50:24,156] {dag.py:2306} INFO - Setting next_dagrun for hello_gdive to None
[2021-09-03 08:50:24,162] {processor.py:170} INFO - Processing /usr/local/airflow/dags/connect_to_gdrive.py took 0.233 seconds
[2021-09-03 08:50:55,124] {processor.py:162} INFO - Started process (PID=24264) to work on /usr/local/airflow/dags/connect_to_gdrive.py
[2021-09-03 08:50:55,125] {processor.py:613} INFO - Processing file /usr/local/airflow/dags/connect_to_gdrive.py for tasks to queue
[2021-09-03 08:50:55,126] {logging_mixin.py:109} INFO - [2021-09-03 08:50:55,126] {dagbag.py:496} INFO - Filling up the DagBag from /usr/local/airflow/dags/connect_to_gdrive.py
[2021-09-03 08:50:55,344] {processor.py:623} INFO - DAG(s) dict_keys(['hello_gdive']) retrieved from /usr/local/airflow/dags/connect_to_gdrive.py
[2021-09-03 08:50:55,355] {logging_mixin.py:109} INFO - [2021-09-03 08:50:55,355] {dag.py:1833} INFO - Sync 1 DAGs
[2021-09-03 08:50:55,364] {logging_mixin.py:109} INFO - [2021-09-03 08:50:55,364] {dag.py:2306} INFO - Setting next_dagrun for hello_gdive to None
[2021-09-03 08:50:55,372] {processor.py:170} INFO - Processing /usr/local/airflow/dags/connect_to_gdrive.py took 0.253 seconds
[2021-09-03 08:51:26,324] {processor.py:162} INFO - Started process (PID=24290) to work on /usr/local/airflow/dags/connect_to_gdrive.py
[2021-09-03 08:51:26,325] {processor.py:613} INFO - Processing file /usr/local/airflow/dags/connect_to_gdrive.py for tasks to queue
[2021-09-03 08:51:26,326] {logging_mixin.py:109} INFO - [2021-09-03 08:51:26,326] {dagbag.py:496} INFO - Filling up the DagBag from /usr/local/airflow/dags/connect_to_gdrive.py
[2021-09-03 08:51:26,589] {processor.py:623} INFO - DAG(s) dict_keys(['hello_gdive']) retrieved from /usr/local/airflow/dags/connect_to_gdrive.py
[2021-09-03 08:51:26,601] {logging_mixin.py:109} INFO - [2021-09-03 08:51:26,601] {dag.py:1833} INFO - Sync 1 DAGs
[2021-09-03 08:51:26,609] {logging_mixin.py:109} INFO - [2021-09-03 08:51:26,609] {dag.py:2306} INFO - Setting next_dagrun for hello_gdive to None
[2021-09-03 08:51:26,624] {processor.py:170} INFO - Processing /usr/local/airflow/dags/connect_to_gdrive.py took 0.304 seconds
[2021-09-03 08:51:57,561] {processor.py:162} INFO - Started process (PID=24316) to work on /usr/local/airflow/dags/connect_to_gdrive.py
[2021-09-03 08:51:57,562] {processor.py:613} INFO - Processing file /usr/local/airflow/dags/connect_to_gdrive.py for tasks to queue
[2021-09-03 08:51:57,563] {logging_mixin.py:109} INFO - [2021-09-03 08:51:57,563] {dagbag.py:496} INFO - Filling up the DagBag from /usr/local/airflow/dags/connect_to_gdrive.py
[2021-09-03 08:51:57,827] {processor.py:623} INFO - DAG(s) dict_keys(['hello_gdive']) retrieved from /usr/local/airflow/dags/connect_to_gdrive.py
[2021-09-03 08:51:57,841] {logging_mixin.py:109} INFO - [2021-09-03 08:51:57,841] {dag.py:1833} INFO - Sync 1 DAGs
[2021-09-03 08:51:57,850] {logging_mixin.py:109} INFO - [2021-09-03 08:51:57,850] {dag.py:2306} INFO - Setting next_dagrun for hello_gdive to None
[2021-09-03 08:51:57,856] {processor.py:170} INFO - Processing /usr/local/airflow/dags/connect_to_gdrive.py took 0.299 seconds
[2021-09-03 08:52:28,816] {processor.py:162} INFO - Started process (PID=24343) to work on /usr/local/airflow/dags/connect_to_gdrive.py
[2021-09-03 08:52:28,818] {processor.py:613} INFO - Processing file /usr/local/airflow/dags/connect_to_gdrive.py for tasks to queue
[2021-09-03 08:52:28,818] {logging_mixin.py:109} INFO - [2021-09-03 08:52:28,818] {dagbag.py:496} INFO - Filling up the DagBag from /usr/local/airflow/dags/connect_to_gdrive.py
[2021-09-03 08:52:29,021] {processor.py:623} INFO - DAG(s) dict_keys(['hello_gdive']) retrieved from /usr/local/airflow/dags/connect_to_gdrive.py
[2021-09-03 08:52:29,032] {logging_mixin.py:109} INFO - [2021-09-03 08:52:29,032] {dag.py:1833} INFO - Sync 1 DAGs
[2021-09-03 08:52:29,040] {logging_mixin.py:109} INFO - [2021-09-03 08:52:29,040] {dag.py:2306} INFO - Setting next_dagrun for hello_gdive to None
[2021-09-03 08:52:29,044] {processor.py:170} INFO - Processing /usr/local/airflow/dags/connect_to_gdrive.py took 0.232 seconds
[2021-09-03 08:52:59,079] {processor.py:162} INFO - Started process (PID=24369) to work on /usr/local/airflow/dags/connect_to_gdrive.py
[2021-09-03 08:52:59,080] {processor.py:613} INFO - Processing file /usr/local/airflow/dags/connect_to_gdrive.py for tasks to queue
[2021-09-03 08:52:59,080] {logging_mixin.py:109} INFO - [2021-09-03 08:52:59,080] {dagbag.py:496} INFO - Filling up the DagBag from /usr/local/airflow/dags/connect_to_gdrive.py
[2021-09-03 08:52:59,314] {processor.py:623} INFO - DAG(s) dict_keys(['hello_gdive']) retrieved from /usr/local/airflow/dags/connect_to_gdrive.py
[2021-09-03 08:52:59,327] {logging_mixin.py:109} INFO - [2021-09-03 08:52:59,327] {dag.py:1833} INFO - Sync 1 DAGs
[2021-09-03 08:52:59,335] {logging_mixin.py:109} INFO - [2021-09-03 08:52:59,335] {dag.py:2306} INFO - Setting next_dagrun for hello_gdive to None
[2021-09-03 08:52:59,341] {processor.py:170} INFO - Processing /usr/local/airflow/dags/connect_to_gdrive.py took 0.264 seconds
[2021-09-03 08:53:30,326] {processor.py:162} INFO - Started process (PID=24395) to work on /usr/local/airflow/dags/connect_to_gdrive.py
[2021-09-03 08:53:30,327] {processor.py:613} INFO - Processing file /usr/local/airflow/dags/connect_to_gdrive.py for tasks to queue
[2021-09-03 08:53:30,328] {logging_mixin.py:109} INFO - [2021-09-03 08:53:30,328] {dagbag.py:496} INFO - Filling up the DagBag from /usr/local/airflow/dags/connect_to_gdrive.py
[2021-09-03 08:53:30,534] {processor.py:623} INFO - DAG(s) dict_keys(['hello_gdive']) retrieved from /usr/local/airflow/dags/connect_to_gdrive.py
[2021-09-03 08:53:30,546] {logging_mixin.py:109} INFO - [2021-09-03 08:53:30,546] {dag.py:1833} INFO - Sync 1 DAGs
[2021-09-03 08:53:30,553] {logging_mixin.py:109} INFO - [2021-09-03 08:53:30,553] {dag.py:2306} INFO - Setting next_dagrun for hello_gdive to None
[2021-09-03 08:53:30,557] {processor.py:170} INFO - Processing /usr/local/airflow/dags/connect_to_gdrive.py took 0.236 seconds
[2021-09-03 08:54:01,547] {processor.py:162} INFO - Started process (PID=24421) to work on /usr/local/airflow/dags/connect_to_gdrive.py
[2021-09-03 08:54:01,548] {processor.py:613} INFO - Processing file /usr/local/airflow/dags/connect_to_gdrive.py for tasks to queue
[2021-09-03 08:54:01,548] {logging_mixin.py:109} INFO - [2021-09-03 08:54:01,548] {dagbag.py:496} INFO - Filling up the DagBag from /usr/local/airflow/dags/connect_to_gdrive.py
[2021-09-03 08:54:01,754] {processor.py:623} INFO - DAG(s) dict_keys(['hello_gdive']) retrieved from /usr/local/airflow/dags/connect_to_gdrive.py
[2021-09-03 08:54:01,766] {logging_mixin.py:109} INFO - [2021-09-03 08:54:01,765] {dag.py:1833} INFO - Sync 1 DAGs
[2021-09-03 08:54:01,773] {logging_mixin.py:109} INFO - [2021-09-03 08:54:01,773] {dag.py:2306} INFO - Setting next_dagrun for hello_gdive to None
[2021-09-03 08:54:01,778] {processor.py:170} INFO - Processing /usr/local/airflow/dags/connect_to_gdrive.py took 0.234 seconds
[2021-09-03 08:54:32,798] {processor.py:162} INFO - Started process (PID=24447) to work on /usr/local/airflow/dags/connect_to_gdrive.py
[2021-09-03 08:54:32,799] {processor.py:613} INFO - Processing file /usr/local/airflow/dags/connect_to_gdrive.py for tasks to queue
[2021-09-03 08:54:32,800] {logging_mixin.py:109} INFO - [2021-09-03 08:54:32,800] {dagbag.py:496} INFO - Filling up the DagBag from /usr/local/airflow/dags/connect_to_gdrive.py
[2021-09-03 08:54:33,040] {processor.py:623} INFO - DAG(s) dict_keys(['hello_gdive']) retrieved from /usr/local/airflow/dags/connect_to_gdrive.py
[2021-09-03 08:54:33,054] {logging_mixin.py:109} INFO - [2021-09-03 08:54:33,054] {dag.py:1833} INFO - Sync 1 DAGs
[2021-09-03 08:54:33,063] {logging_mixin.py:109} INFO - [2021-09-03 08:54:33,063] {dag.py:2306} INFO - Setting next_dagrun for hello_gdive to None
[2021-09-03 08:54:33,070] {processor.py:170} INFO - Processing /usr/local/airflow/dags/connect_to_gdrive.py took 0.276 seconds
[2021-09-03 08:55:03,172] {processor.py:162} INFO - Started process (PID=24486) to work on /usr/local/airflow/dags/connect_to_gdrive.py
[2021-09-03 08:55:03,173] {processor.py:613} INFO - Processing file /usr/local/airflow/dags/connect_to_gdrive.py for tasks to queue
[2021-09-03 08:55:03,173] {logging_mixin.py:109} INFO - [2021-09-03 08:55:03,173] {dagbag.py:496} INFO - Filling up the DagBag from /usr/local/airflow/dags/connect_to_gdrive.py
[2021-09-03 08:55:03,358] {processor.py:623} INFO - DAG(s) dict_keys(['hello_gdive']) retrieved from /usr/local/airflow/dags/connect_to_gdrive.py
[2021-09-03 08:55:03,369] {logging_mixin.py:109} INFO - [2021-09-03 08:55:03,369] {dag.py:1833} INFO - Sync 1 DAGs
[2021-09-03 08:55:03,376] {logging_mixin.py:109} INFO - [2021-09-03 08:55:03,376] {dag.py:2306} INFO - Setting next_dagrun for hello_gdive to None
[2021-09-03 08:55:03,381] {processor.py:170} INFO - Processing /usr/local/airflow/dags/connect_to_gdrive.py took 0.212 seconds
[2021-09-03 08:55:33,476] {processor.py:162} INFO - Started process (PID=24515) to work on /usr/local/airflow/dags/connect_to_gdrive.py
[2021-09-03 08:55:33,477] {processor.py:613} INFO - Processing file /usr/local/airflow/dags/connect_to_gdrive.py for tasks to queue
[2021-09-03 08:55:33,477] {logging_mixin.py:109} INFO - [2021-09-03 08:55:33,477] {dagbag.py:496} INFO - Filling up the DagBag from /usr/local/airflow/dags/connect_to_gdrive.py
[2021-09-03 08:55:33,681] {processor.py:623} INFO - DAG(s) dict_keys(['hello_gdive']) retrieved from /usr/local/airflow/dags/connect_to_gdrive.py
[2021-09-03 08:55:33,693] {logging_mixin.py:109} INFO - [2021-09-03 08:55:33,692] {dag.py:1833} INFO - Sync 1 DAGs
[2021-09-03 08:55:33,700] {logging_mixin.py:109} INFO - [2021-09-03 08:55:33,700] {dag.py:2306} INFO - Setting next_dagrun for hello_gdive to None
[2021-09-03 08:55:33,706] {processor.py:170} INFO - Processing /usr/local/airflow/dags/connect_to_gdrive.py took 0.233 seconds
[2021-09-03 08:56:03,733] {processor.py:162} INFO - Started process (PID=24541) to work on /usr/local/airflow/dags/connect_to_gdrive.py
[2021-09-03 08:56:03,734] {processor.py:613} INFO - Processing file /usr/local/airflow/dags/connect_to_gdrive.py for tasks to queue
[2021-09-03 08:56:03,735] {logging_mixin.py:109} INFO - [2021-09-03 08:56:03,735] {dagbag.py:496} INFO - Filling up the DagBag from /usr/local/airflow/dags/connect_to_gdrive.py
[2021-09-03 08:56:03,942] {processor.py:623} INFO - DAG(s) dict_keys(['hello_gdive']) retrieved from /usr/local/airflow/dags/connect_to_gdrive.py
[2021-09-03 08:56:03,956] {logging_mixin.py:109} INFO - [2021-09-03 08:56:03,955] {dag.py:1833} INFO - Sync 1 DAGs
[2021-09-03 08:56:03,965] {logging_mixin.py:109} INFO - [2021-09-03 08:56:03,965] {dag.py:2306} INFO - Setting next_dagrun for hello_gdive to None
[2021-09-03 08:56:03,970] {processor.py:170} INFO - Processing /usr/local/airflow/dags/connect_to_gdrive.py took 0.240 seconds
[2021-09-03 08:56:34,044] {processor.py:162} INFO - Started process (PID=24567) to work on /usr/local/airflow/dags/connect_to_gdrive.py
[2021-09-03 08:56:34,045] {processor.py:613} INFO - Processing file /usr/local/airflow/dags/connect_to_gdrive.py for tasks to queue
[2021-09-03 08:56:34,046] {logging_mixin.py:109} INFO - [2021-09-03 08:56:34,045] {dagbag.py:496} INFO - Filling up the DagBag from /usr/local/airflow/dags/connect_to_gdrive.py
[2021-09-03 08:56:34,288] {processor.py:623} INFO - DAG(s) dict_keys(['hello_gdive']) retrieved from /usr/local/airflow/dags/connect_to_gdrive.py
[2021-09-03 08:56:34,308] {logging_mixin.py:109} INFO - [2021-09-03 08:56:34,308] {dag.py:1833} INFO - Sync 1 DAGs
[2021-09-03 08:56:34,320] {logging_mixin.py:109} INFO - [2021-09-03 08:56:34,320] {dag.py:2306} INFO - Setting next_dagrun for hello_gdive to None
[2021-09-03 08:56:34,330] {processor.py:170} INFO - Processing /usr/local/airflow/dags/connect_to_gdrive.py took 0.290 seconds
[2021-09-03 08:57:05,233] {processor.py:162} INFO - Started process (PID=24594) to work on /usr/local/airflow/dags/connect_to_gdrive.py
[2021-09-03 08:57:05,234] {processor.py:613} INFO - Processing file /usr/local/airflow/dags/connect_to_gdrive.py for tasks to queue
[2021-09-03 08:57:05,235] {logging_mixin.py:109} INFO - [2021-09-03 08:57:05,235] {dagbag.py:496} INFO - Filling up the DagBag from /usr/local/airflow/dags/connect_to_gdrive.py
[2021-09-03 08:57:05,441] {processor.py:623} INFO - DAG(s) dict_keys(['hello_gdive']) retrieved from /usr/local/airflow/dags/connect_to_gdrive.py
[2021-09-03 08:57:05,452] {logging_mixin.py:109} INFO - [2021-09-03 08:57:05,452] {dag.py:1833} INFO - Sync 1 DAGs
[2021-09-03 08:57:05,460] {logging_mixin.py:109} INFO - [2021-09-03 08:57:05,460] {dag.py:2306} INFO - Setting next_dagrun for hello_gdive to None
[2021-09-03 08:57:05,464] {processor.py:170} INFO - Processing /usr/local/airflow/dags/connect_to_gdrive.py took 0.235 seconds
[2021-09-03 08:57:35,501] {processor.py:162} INFO - Started process (PID=24620) to work on /usr/local/airflow/dags/connect_to_gdrive.py
[2021-09-03 08:57:35,503] {processor.py:613} INFO - Processing file /usr/local/airflow/dags/connect_to_gdrive.py for tasks to queue
[2021-09-03 08:57:35,503] {logging_mixin.py:109} INFO - [2021-09-03 08:57:35,503] {dagbag.py:496} INFO - Filling up the DagBag from /usr/local/airflow/dags/connect_to_gdrive.py
[2021-09-03 08:57:35,706] {processor.py:623} INFO - DAG(s) dict_keys(['hello_gdive']) retrieved from /usr/local/airflow/dags/connect_to_gdrive.py
[2021-09-03 08:57:35,718] {logging_mixin.py:109} INFO - [2021-09-03 08:57:35,717] {dag.py:1833} INFO - Sync 1 DAGs
[2021-09-03 08:57:35,725] {logging_mixin.py:109} INFO - [2021-09-03 08:57:35,725] {dag.py:2306} INFO - Setting next_dagrun for hello_gdive to None
[2021-09-03 08:57:35,731] {processor.py:170} INFO - Processing /usr/local/airflow/dags/connect_to_gdrive.py took 0.234 seconds
[2021-09-03 08:58:05,803] {processor.py:162} INFO - Started process (PID=24646) to work on /usr/local/airflow/dags/connect_to_gdrive.py
[2021-09-03 08:58:05,804] {processor.py:613} INFO - Processing file /usr/local/airflow/dags/connect_to_gdrive.py for tasks to queue
[2021-09-03 08:58:05,805] {logging_mixin.py:109} INFO - [2021-09-03 08:58:05,805] {dagbag.py:496} INFO - Filling up the DagBag from /usr/local/airflow/dags/connect_to_gdrive.py
[2021-09-03 08:58:06,006] {processor.py:623} INFO - DAG(s) dict_keys(['hello_gdive']) retrieved from /usr/local/airflow/dags/connect_to_gdrive.py
[2021-09-03 08:58:06,018] {logging_mixin.py:109} INFO - [2021-09-03 08:58:06,017] {dag.py:1833} INFO - Sync 1 DAGs
[2021-09-03 08:58:06,025] {logging_mixin.py:109} INFO - [2021-09-03 08:58:06,025] {dag.py:2306} INFO - Setting next_dagrun for hello_gdive to None
[2021-09-03 08:58:06,031] {processor.py:170} INFO - Processing /usr/local/airflow/dags/connect_to_gdrive.py took 0.232 seconds
[2021-09-03 08:58:36,980] {processor.py:162} INFO - Started process (PID=24672) to work on /usr/local/airflow/dags/connect_to_gdrive.py
[2021-09-03 08:58:36,981] {processor.py:613} INFO - Processing file /usr/local/airflow/dags/connect_to_gdrive.py for tasks to queue
[2021-09-03 08:58:36,984] {logging_mixin.py:109} INFO - [2021-09-03 08:58:36,984] {dagbag.py:496} INFO - Filling up the DagBag from /usr/local/airflow/dags/connect_to_gdrive.py
[2021-09-03 08:58:37,182] {processor.py:623} INFO - DAG(s) dict_keys(['hello_gdive']) retrieved from /usr/local/airflow/dags/connect_to_gdrive.py
[2021-09-03 08:58:37,193] {logging_mixin.py:109} INFO - [2021-09-03 08:58:37,193] {dag.py:1833} INFO - Sync 1 DAGs
[2021-09-03 08:58:37,200] {logging_mixin.py:109} INFO - [2021-09-03 08:58:37,200] {dag.py:2306} INFO - Setting next_dagrun for hello_gdive to None
[2021-09-03 08:58:37,205] {processor.py:170} INFO - Processing /usr/local/airflow/dags/connect_to_gdrive.py took 0.229 seconds
[2021-09-03 08:59:07,287] {processor.py:162} INFO - Started process (PID=24698) to work on /usr/local/airflow/dags/connect_to_gdrive.py
[2021-09-03 08:59:07,288] {processor.py:613} INFO - Processing file /usr/local/airflow/dags/connect_to_gdrive.py for tasks to queue
[2021-09-03 08:59:07,288] {logging_mixin.py:109} INFO - [2021-09-03 08:59:07,288] {dagbag.py:496} INFO - Filling up the DagBag from /usr/local/airflow/dags/connect_to_gdrive.py
[2021-09-03 08:59:07,491] {processor.py:623} INFO - DAG(s) dict_keys(['hello_gdive']) retrieved from /usr/local/airflow/dags/connect_to_gdrive.py
[2021-09-03 08:59:07,503] {logging_mixin.py:109} INFO - [2021-09-03 08:59:07,502] {dag.py:1833} INFO - Sync 1 DAGs
[2021-09-03 08:59:07,510] {logging_mixin.py:109} INFO - [2021-09-03 08:59:07,510] {dag.py:2306} INFO - Setting next_dagrun for hello_gdive to None
[2021-09-03 08:59:07,516] {processor.py:170} INFO - Processing /usr/local/airflow/dags/connect_to_gdrive.py took 0.233 seconds
[2021-09-03 08:59:37,542] {processor.py:162} INFO - Started process (PID=24724) to work on /usr/local/airflow/dags/connect_to_gdrive.py
[2021-09-03 08:59:37,543] {processor.py:613} INFO - Processing file /usr/local/airflow/dags/connect_to_gdrive.py for tasks to queue
[2021-09-03 08:59:37,544] {logging_mixin.py:109} INFO - [2021-09-03 08:59:37,544] {dagbag.py:496} INFO - Filling up the DagBag from /usr/local/airflow/dags/connect_to_gdrive.py
[2021-09-03 08:59:37,751] {processor.py:623} INFO - DAG(s) dict_keys(['hello_gdive']) retrieved from /usr/local/airflow/dags/connect_to_gdrive.py
[2021-09-03 08:59:37,762] {logging_mixin.py:109} INFO - [2021-09-03 08:59:37,762] {dag.py:1833} INFO - Sync 1 DAGs
[2021-09-03 08:59:37,769] {logging_mixin.py:109} INFO - [2021-09-03 08:59:37,769] {dag.py:2306} INFO - Setting next_dagrun for hello_gdive to None
[2021-09-03 08:59:37,776] {processor.py:170} INFO - Processing /usr/local/airflow/dags/connect_to_gdrive.py took 0.237 seconds
[2021-09-03 09:00:08,724] {processor.py:162} INFO - Started process (PID=24750) to work on /usr/local/airflow/dags/connect_to_gdrive.py
[2021-09-03 09:00:08,726] {processor.py:613} INFO - Processing file /usr/local/airflow/dags/connect_to_gdrive.py for tasks to queue
[2021-09-03 09:00:08,726] {logging_mixin.py:109} INFO - [2021-09-03 09:00:08,726] {dagbag.py:496} INFO - Filling up the DagBag from /usr/local/airflow/dags/connect_to_gdrive.py
[2021-09-03 09:00:08,928] {processor.py:623} INFO - DAG(s) dict_keys(['hello_gdive']) retrieved from /usr/local/airflow/dags/connect_to_gdrive.py
[2021-09-03 09:00:08,940] {logging_mixin.py:109} INFO - [2021-09-03 09:00:08,939] {dag.py:1833} INFO - Sync 1 DAGs
[2021-09-03 09:00:08,947] {logging_mixin.py:109} INFO - [2021-09-03 09:00:08,947] {dag.py:2306} INFO - Setting next_dagrun for hello_gdive to None
[2021-09-03 09:00:08,952] {processor.py:170} INFO - Processing /usr/local/airflow/dags/connect_to_gdrive.py took 0.231 seconds
[2021-09-03 09:00:38,981] {processor.py:162} INFO - Started process (PID=24776) to work on /usr/local/airflow/dags/connect_to_gdrive.py
[2021-09-03 09:00:38,982] {processor.py:613} INFO - Processing file /usr/local/airflow/dags/connect_to_gdrive.py for tasks to queue
[2021-09-03 09:00:38,982] {logging_mixin.py:109} INFO - [2021-09-03 09:00:38,982] {dagbag.py:496} INFO - Filling up the DagBag from /usr/local/airflow/dags/connect_to_gdrive.py
[2021-09-03 09:00:39,183] {processor.py:623} INFO - DAG(s) dict_keys(['hello_gdive']) retrieved from /usr/local/airflow/dags/connect_to_gdrive.py
[2021-09-03 09:00:39,195] {logging_mixin.py:109} INFO - [2021-09-03 09:00:39,195] {dag.py:1833} INFO - Sync 1 DAGs
[2021-09-03 09:00:39,203] {logging_mixin.py:109} INFO - [2021-09-03 09:00:39,203] {dag.py:2306} INFO - Setting next_dagrun for hello_gdive to None
[2021-09-03 09:00:39,207] {processor.py:170} INFO - Processing /usr/local/airflow/dags/connect_to_gdrive.py took 0.230 seconds
[2021-09-03 09:01:09,285] {processor.py:162} INFO - Started process (PID=24803) to work on /usr/local/airflow/dags/connect_to_gdrive.py
[2021-09-03 09:01:09,287] {processor.py:613} INFO - Processing file /usr/local/airflow/dags/connect_to_gdrive.py for tasks to queue
[2021-09-03 09:01:09,287] {logging_mixin.py:109} INFO - [2021-09-03 09:01:09,287] {dagbag.py:496} INFO - Filling up the DagBag from /usr/local/airflow/dags/connect_to_gdrive.py
[2021-09-03 09:01:09,498] {processor.py:623} INFO - DAG(s) dict_keys(['hello_gdive']) retrieved from /usr/local/airflow/dags/connect_to_gdrive.py
[2021-09-03 09:01:09,510] {logging_mixin.py:109} INFO - [2021-09-03 09:01:09,510] {dag.py:1833} INFO - Sync 1 DAGs
[2021-09-03 09:01:09,517] {logging_mixin.py:109} INFO - [2021-09-03 09:01:09,517] {dag.py:2306} INFO - Setting next_dagrun for hello_gdive to None
[2021-09-03 09:01:09,523] {processor.py:170} INFO - Processing /usr/local/airflow/dags/connect_to_gdrive.py took 0.242 seconds
[2021-09-03 09:01:40,476] {processor.py:162} INFO - Started process (PID=24830) to work on /usr/local/airflow/dags/connect_to_gdrive.py
[2021-09-03 09:01:40,477] {processor.py:613} INFO - Processing file /usr/local/airflow/dags/connect_to_gdrive.py for tasks to queue
[2021-09-03 09:01:40,477] {logging_mixin.py:109} INFO - [2021-09-03 09:01:40,477] {dagbag.py:496} INFO - Filling up the DagBag from /usr/local/airflow/dags/connect_to_gdrive.py
[2021-09-03 09:01:40,672] {processor.py:623} INFO - DAG(s) dict_keys(['hello_gdive']) retrieved from /usr/local/airflow/dags/connect_to_gdrive.py
[2021-09-03 09:01:40,684] {logging_mixin.py:109} INFO - [2021-09-03 09:01:40,684] {dag.py:1833} INFO - Sync 1 DAGs
[2021-09-03 09:01:40,691] {logging_mixin.py:109} INFO - [2021-09-03 09:01:40,691] {dag.py:2306} INFO - Setting next_dagrun for hello_gdive to None
[2021-09-03 09:01:40,696] {processor.py:170} INFO - Processing /usr/local/airflow/dags/connect_to_gdrive.py took 0.224 seconds
[2021-09-03 09:02:10,718] {processor.py:162} INFO - Started process (PID=24856) to work on /usr/local/airflow/dags/connect_to_gdrive.py
[2021-09-03 09:02:10,719] {processor.py:613} INFO - Processing file /usr/local/airflow/dags/connect_to_gdrive.py for tasks to queue
[2021-09-03 09:02:10,719] {logging_mixin.py:109} INFO - [2021-09-03 09:02:10,719] {dagbag.py:496} INFO - Filling up the DagBag from /usr/local/airflow/dags/connect_to_gdrive.py
[2021-09-03 09:02:10,919] {processor.py:623} INFO - DAG(s) dict_keys(['hello_gdive']) retrieved from /usr/local/airflow/dags/connect_to_gdrive.py
[2021-09-03 09:02:10,930] {logging_mixin.py:109} INFO - [2021-09-03 09:02:10,930] {dag.py:1833} INFO - Sync 1 DAGs
[2021-09-03 09:02:10,937] {logging_mixin.py:109} INFO - [2021-09-03 09:02:10,937] {dag.py:2306} INFO - Setting next_dagrun for hello_gdive to None
[2021-09-03 09:02:10,942] {processor.py:170} INFO - Processing /usr/local/airflow/dags/connect_to_gdrive.py took 0.228 seconds
[2021-09-03 09:02:40,995] {processor.py:162} INFO - Started process (PID=24882) to work on /usr/local/airflow/dags/connect_to_gdrive.py
[2021-09-03 09:02:40,997] {processor.py:613} INFO - Processing file /usr/local/airflow/dags/connect_to_gdrive.py for tasks to queue
[2021-09-03 09:02:40,998] {logging_mixin.py:109} INFO - [2021-09-03 09:02:40,997] {dagbag.py:496} INFO - Filling up the DagBag from /usr/local/airflow/dags/connect_to_gdrive.py
[2021-09-03 09:02:41,218] {processor.py:623} INFO - DAG(s) dict_keys(['hello_gdive']) retrieved from /usr/local/airflow/dags/connect_to_gdrive.py
[2021-09-03 09:02:41,230] {logging_mixin.py:109} INFO - [2021-09-03 09:02:41,230] {dag.py:1833} INFO - Sync 1 DAGs
[2021-09-03 09:02:41,239] {logging_mixin.py:109} INFO - [2021-09-03 09:02:41,239] {dag.py:2306} INFO - Setting next_dagrun for hello_gdive to None
[2021-09-03 09:02:41,246] {processor.py:170} INFO - Processing /usr/local/airflow/dags/connect_to_gdrive.py took 0.254 seconds
[2021-09-03 09:03:11,312] {processor.py:162} INFO - Started process (PID=24908) to work on /usr/local/airflow/dags/connect_to_gdrive.py
[2021-09-03 09:03:11,313] {processor.py:613} INFO - Processing file /usr/local/airflow/dags/connect_to_gdrive.py for tasks to queue
[2021-09-03 09:03:11,314] {logging_mixin.py:109} INFO - [2021-09-03 09:03:11,313] {dagbag.py:496} INFO - Filling up the DagBag from /usr/local/airflow/dags/connect_to_gdrive.py
[2021-09-03 09:03:11,552] {processor.py:623} INFO - DAG(s) dict_keys(['hello_gdive']) retrieved from /usr/local/airflow/dags/connect_to_gdrive.py
[2021-09-03 09:03:11,566] {logging_mixin.py:109} INFO - [2021-09-03 09:03:11,566] {dag.py:1833} INFO - Sync 1 DAGs
[2021-09-03 09:03:11,575] {logging_mixin.py:109} INFO - [2021-09-03 09:03:11,574] {dag.py:2306} INFO - Setting next_dagrun for hello_gdive to None
[2021-09-03 09:03:11,589] {processor.py:170} INFO - Processing /usr/local/airflow/dags/connect_to_gdrive.py took 0.282 seconds
[2021-09-03 09:03:42,559] {processor.py:162} INFO - Started process (PID=24934) to work on /usr/local/airflow/dags/connect_to_gdrive.py
[2021-09-03 09:03:42,560] {processor.py:613} INFO - Processing file /usr/local/airflow/dags/connect_to_gdrive.py for tasks to queue
[2021-09-03 09:03:42,560] {logging_mixin.py:109} INFO - [2021-09-03 09:03:42,560] {dagbag.py:496} INFO - Filling up the DagBag from /usr/local/airflow/dags/connect_to_gdrive.py
[2021-09-03 09:03:42,778] {processor.py:623} INFO - DAG(s) dict_keys(['hello_gdive']) retrieved from /usr/local/airflow/dags/connect_to_gdrive.py
[2021-09-03 09:03:42,790] {logging_mixin.py:109} INFO - [2021-09-03 09:03:42,790] {dag.py:1833} INFO - Sync 1 DAGs
[2021-09-03 09:03:42,798] {logging_mixin.py:109} INFO - [2021-09-03 09:03:42,798] {dag.py:2306} INFO - Setting next_dagrun for hello_gdive to None
[2021-09-03 09:03:42,812] {processor.py:170} INFO - Processing /usr/local/airflow/dags/connect_to_gdrive.py took 0.257 seconds
[2021-09-03 09:04:12,832] {processor.py:162} INFO - Started process (PID=25661) to work on /usr/local/airflow/dags/connect_to_gdrive.py
[2021-09-03 09:04:12,833] {processor.py:613} INFO - Processing file /usr/local/airflow/dags/connect_to_gdrive.py for tasks to queue
[2021-09-03 09:04:12,834] {logging_mixin.py:109} INFO - [2021-09-03 09:04:12,833] {dagbag.py:496} INFO - Filling up the DagBag from /usr/local/airflow/dags/connect_to_gdrive.py
[2021-09-03 09:04:13,047] {processor.py:623} INFO - DAG(s) dict_keys(['hello_gdive']) retrieved from /usr/local/airflow/dags/connect_to_gdrive.py
[2021-09-03 09:04:13,062] {logging_mixin.py:109} INFO - [2021-09-03 09:04:13,062] {dag.py:1833} INFO - Sync 1 DAGs
[2021-09-03 09:04:13,073] {logging_mixin.py:109} INFO - [2021-09-03 09:04:13,073] {dag.py:2306} INFO - Setting next_dagrun for hello_gdive to None
[2021-09-03 09:04:13,080] {processor.py:170} INFO - Processing /usr/local/airflow/dags/connect_to_gdrive.py took 0.250 seconds
[2021-09-03 09:04:43,113] {processor.py:162} INFO - Started process (PID=25975) to work on /usr/local/airflow/dags/connect_to_gdrive.py
[2021-09-03 09:04:43,115] {processor.py:613} INFO - Processing file /usr/local/airflow/dags/connect_to_gdrive.py for tasks to queue
[2021-09-03 09:04:43,115] {logging_mixin.py:109} INFO - [2021-09-03 09:04:43,115] {dagbag.py:496} INFO - Filling up the DagBag from /usr/local/airflow/dags/connect_to_gdrive.py
[2021-09-03 09:04:43,319] {processor.py:623} INFO - DAG(s) dict_keys(['hello_gdive']) retrieved from /usr/local/airflow/dags/connect_to_gdrive.py
[2021-09-03 09:04:43,331] {logging_mixin.py:109} INFO - [2021-09-03 09:04:43,331] {dag.py:1833} INFO - Sync 1 DAGs
[2021-09-03 09:04:43,340] {logging_mixin.py:109} INFO - [2021-09-03 09:04:43,340] {dag.py:2306} INFO - Setting next_dagrun for hello_gdive to None
[2021-09-03 09:04:43,353] {processor.py:170} INFO - Processing /usr/local/airflow/dags/connect_to_gdrive.py took 0.244 seconds
[2021-09-03 09:05:13,701] {processor.py:162} INFO - Started process (PID=26312) to work on /usr/local/airflow/dags/connect_to_gdrive.py
[2021-09-03 09:05:13,703] {processor.py:613} INFO - Processing file /usr/local/airflow/dags/connect_to_gdrive.py for tasks to queue
[2021-09-03 09:05:13,703] {logging_mixin.py:109} INFO - [2021-09-03 09:05:13,703] {dagbag.py:496} INFO - Filling up the DagBag from /usr/local/airflow/dags/connect_to_gdrive.py
[2021-09-03 09:05:13,904] {processor.py:623} INFO - DAG(s) dict_keys(['hello_gdive']) retrieved from /usr/local/airflow/dags/connect_to_gdrive.py
[2021-09-03 09:05:14,686] {processor.py:173} ERROR - Got an exception! Propagating...
Traceback (most recent call last):
  File "/usr/local/lib/python3.8/dist-packages/sqlalchemy/engine/base.py", line 2336, in _wrap_pool_connect
    return fn()
  File "/usr/local/lib/python3.8/dist-packages/sqlalchemy/pool/base.py", line 364, in connect
    return _ConnectionFairy._checkout(self)
  File "/usr/local/lib/python3.8/dist-packages/sqlalchemy/pool/base.py", line 778, in _checkout
    fairy = _ConnectionRecord.checkout(pool)
  File "/usr/local/lib/python3.8/dist-packages/sqlalchemy/pool/base.py", line 495, in checkout
    rec = pool._do_get()
  File "/usr/local/lib/python3.8/dist-packages/sqlalchemy/pool/impl.py", line 140, in _do_get
    self._dec_overflow()
  File "/usr/local/lib/python3.8/dist-packages/sqlalchemy/util/langhelpers.py", line 68, in __exit__
    compat.raise_(
  File "/usr/local/lib/python3.8/dist-packages/sqlalchemy/util/compat.py", line 182, in raise_
    raise exception
  File "/usr/local/lib/python3.8/dist-packages/sqlalchemy/pool/impl.py", line 137, in _do_get
    return self._create_connection()
  File "/usr/local/lib/python3.8/dist-packages/sqlalchemy/pool/base.py", line 309, in _create_connection
    return _ConnectionRecord(self)
  File "/usr/local/lib/python3.8/dist-packages/sqlalchemy/pool/base.py", line 440, in __init__
    self.__connect(first_connect_check=True)
  File "/usr/local/lib/python3.8/dist-packages/sqlalchemy/pool/base.py", line 661, in __connect
    pool.logger.debug("Error on connect(): %s", e)
  File "/usr/local/lib/python3.8/dist-packages/sqlalchemy/util/langhelpers.py", line 68, in __exit__
    compat.raise_(
  File "/usr/local/lib/python3.8/dist-packages/sqlalchemy/util/compat.py", line 182, in raise_
    raise exception
  File "/usr/local/lib/python3.8/dist-packages/sqlalchemy/pool/base.py", line 656, in __connect
    connection = pool._invoke_creator(self)
  File "/usr/local/lib/python3.8/dist-packages/sqlalchemy/engine/strategies.py", line 114, in connect
    return dialect.connect(*cargs, **cparams)
  File "/usr/local/lib/python3.8/dist-packages/sqlalchemy/engine/default.py", line 508, in connect
    return self.dbapi.connect(*cargs, **cparams)
  File "/usr/local/lib/python3.8/dist-packages/psycopg2/__init__.py", line 122, in connect
    conn = _connect(dsn, connection_factory=connection_factory, **kwasync)
psycopg2.OperationalError: FATAL:  could not open file "global/pg_filenode.map": Permission denied


The above exception was the direct cause of the following exception:

Traceback (most recent call last):
  File "/usr/local/lib/python3.8/dist-packages/airflow/dag_processing/processor.py", line 164, in _run_file_processor
    result: Tuple[int, int] = dag_file_processor.process_file(
  File "/usr/local/lib/python3.8/dist-packages/airflow/utils/session.py", line 70, in wrapper
    return func(*args, session=session, **kwargs)
  File "/usr/local/lib/python3.8/dist-packages/airflow/dag_processing/processor.py", line 632, in process_file
    dagbag.sync_to_db()
  File "/usr/local/lib/python3.8/dist-packages/airflow/utils/session.py", line 70, in wrapper
    return func(*args, session=session, **kwargs)
  File "/usr/local/lib/python3.8/dist-packages/airflow/models/dagbag.py", line 604, in sync_to_db
    for attempt in run_with_db_retries(logger=self.log):
  File "/usr/local/lib/python3.8/dist-packages/tenacity/__init__.py", line 390, in __iter__
    do = self.iter(retry_state=retry_state)
  File "/usr/local/lib/python3.8/dist-packages/tenacity/__init__.py", line 368, in iter
    raise retry_exc.reraise()
  File "/usr/local/lib/python3.8/dist-packages/tenacity/__init__.py", line 186, in reraise
    raise self.last_attempt.result()
  File "/usr/lib/python3.8/concurrent/futures/_base.py", line 437, in result
    return self.__get_result()
  File "/usr/lib/python3.8/concurrent/futures/_base.py", line 389, in __get_result
    raise self._exception
  File "/usr/local/lib/python3.8/dist-packages/airflow/models/dagbag.py", line 616, in sync_to_db
    serialize_errors.extend(_serialize_dag_capturing_errors(dag, session))
  File "/usr/local/lib/python3.8/dist-packages/airflow/models/dagbag.py", line 587, in _serialize_dag_capturing_errors
    dag_was_updated = SerializedDagModel.write_dag(
  File "/usr/local/lib/python3.8/dist-packages/airflow/utils/session.py", line 67, in wrapper
    return func(*args, **kwargs)
  File "/usr/local/lib/python3.8/dist-packages/airflow/models/serialized_dag.py", line 120, in write_dag
    if session.query(
  File "/usr/local/lib/python3.8/dist-packages/sqlalchemy/orm/query.py", line 3523, in scalar
    ret = self.one()
  File "/usr/local/lib/python3.8/dist-packages/sqlalchemy/orm/query.py", line 3490, in one
    ret = self.one_or_none()
  File "/usr/local/lib/python3.8/dist-packages/sqlalchemy/orm/query.py", line 3459, in one_or_none
    ret = list(self)
  File "/usr/local/lib/python3.8/dist-packages/sqlalchemy/orm/query.py", line 3535, in __iter__
    return self._execute_and_instances(context)
  File "/usr/local/lib/python3.8/dist-packages/sqlalchemy/orm/query.py", line 3556, in _execute_and_instances
    conn = self._get_bind_args(
  File "/usr/local/lib/python3.8/dist-packages/sqlalchemy/orm/query.py", line 3571, in _get_bind_args
    return fn(
  File "/usr/local/lib/python3.8/dist-packages/sqlalchemy/orm/query.py", line 3550, in _connection_from_session
    conn = self.session.connection(**kw)
  File "/usr/local/lib/python3.8/dist-packages/sqlalchemy/orm/session.py", line 1142, in connection
    return self._connection_for_bind(
  File "/usr/local/lib/python3.8/dist-packages/sqlalchemy/orm/session.py", line 1150, in _connection_for_bind
    return self.transaction._connection_for_bind(
  File "/usr/local/lib/python3.8/dist-packages/sqlalchemy/orm/session.py", line 433, in _connection_for_bind
    conn = bind._contextual_connect()
  File "/usr/local/lib/python3.8/dist-packages/sqlalchemy/engine/base.py", line 2302, in _contextual_connect
    self._wrap_pool_connect(self.pool.connect, None),
  File "/usr/local/lib/python3.8/dist-packages/sqlalchemy/engine/base.py", line 2339, in _wrap_pool_connect
    Connection._handle_dbapi_exception_noconnection(
  File "/usr/local/lib/python3.8/dist-packages/sqlalchemy/engine/base.py", line 1583, in _handle_dbapi_exception_noconnection
    util.raise_(
  File "/usr/local/lib/python3.8/dist-packages/sqlalchemy/util/compat.py", line 182, in raise_
    raise exception
  File "/usr/local/lib/python3.8/dist-packages/sqlalchemy/engine/base.py", line 2336, in _wrap_pool_connect
    return fn()
  File "/usr/local/lib/python3.8/dist-packages/sqlalchemy/pool/base.py", line 364, in connect
    return _ConnectionFairy._checkout(self)
  File "/usr/local/lib/python3.8/dist-packages/sqlalchemy/pool/base.py", line 778, in _checkout
    fairy = _ConnectionRecord.checkout(pool)
  File "/usr/local/lib/python3.8/dist-packages/sqlalchemy/pool/base.py", line 495, in checkout
    rec = pool._do_get()
  File "/usr/local/lib/python3.8/dist-packages/sqlalchemy/pool/impl.py", line 140, in _do_get
    self._dec_overflow()
  File "/usr/local/lib/python3.8/dist-packages/sqlalchemy/util/langhelpers.py", line 68, in __exit__
    compat.raise_(
  File "/usr/local/lib/python3.8/dist-packages/sqlalchemy/util/compat.py", line 182, in raise_
    raise exception
  File "/usr/local/lib/python3.8/dist-packages/sqlalchemy/pool/impl.py", line 137, in _do_get
    return self._create_connection()
  File "/usr/local/lib/python3.8/dist-packages/sqlalchemy/pool/base.py", line 309, in _create_connection
    return _ConnectionRecord(self)
  File "/usr/local/lib/python3.8/dist-packages/sqlalchemy/pool/base.py", line 440, in __init__
    self.__connect(first_connect_check=True)
  File "/usr/local/lib/python3.8/dist-packages/sqlalchemy/pool/base.py", line 661, in __connect
    pool.logger.debug("Error on connect(): %s", e)
  File "/usr/local/lib/python3.8/dist-packages/sqlalchemy/util/langhelpers.py", line 68, in __exit__
    compat.raise_(
  File "/usr/local/lib/python3.8/dist-packages/sqlalchemy/util/compat.py", line 182, in raise_
    raise exception
  File "/usr/local/lib/python3.8/dist-packages/sqlalchemy/pool/base.py", line 656, in __connect
    connection = pool._invoke_creator(self)
  File "/usr/local/lib/python3.8/dist-packages/sqlalchemy/engine/strategies.py", line 114, in connect
    return dialect.connect(*cargs, **cparams)
  File "/usr/local/lib/python3.8/dist-packages/sqlalchemy/engine/default.py", line 508, in connect
    return self.dbapi.connect(*cargs, **cparams)
  File "/usr/local/lib/python3.8/dist-packages/psycopg2/__init__.py", line 122, in connect
    conn = _connect(dsn, connection_factory=connection_factory, **kwasync)
sqlalchemy.exc.OperationalError: (psycopg2.OperationalError) FATAL:  could not open file "global/pg_filenode.map": Permission denied

(Background on this error at: http://sqlalche.me/e/13/e3q8)
[2021-09-03 09:05:44,934] {processor.py:162} INFO - Started process (PID=26647) to work on /usr/local/airflow/dags/connect_to_gdrive.py
[2021-09-03 09:05:44,935] {processor.py:613} INFO - Processing file /usr/local/airflow/dags/connect_to_gdrive.py for tasks to queue
[2021-09-03 09:05:44,935] {logging_mixin.py:109} INFO - [2021-09-03 09:05:44,935] {dagbag.py:496} INFO - Filling up the DagBag from /usr/local/airflow/dags/connect_to_gdrive.py
[2021-09-03 09:05:45,170] {processor.py:623} INFO - DAG(s) dict_keys(['hello_gdive']) retrieved from /usr/local/airflow/dags/connect_to_gdrive.py
[2021-09-03 09:05:45,796] {processor.py:173} ERROR - Got an exception! Propagating...
Traceback (most recent call last):
  File "/usr/local/lib/python3.8/dist-packages/sqlalchemy/engine/base.py", line 2336, in _wrap_pool_connect
    return fn()
  File "/usr/local/lib/python3.8/dist-packages/sqlalchemy/pool/base.py", line 364, in connect
    return _ConnectionFairy._checkout(self)
  File "/usr/local/lib/python3.8/dist-packages/sqlalchemy/pool/base.py", line 778, in _checkout
    fairy = _ConnectionRecord.checkout(pool)
  File "/usr/local/lib/python3.8/dist-packages/sqlalchemy/pool/base.py", line 495, in checkout
    rec = pool._do_get()
  File "/usr/local/lib/python3.8/dist-packages/sqlalchemy/pool/impl.py", line 140, in _do_get
    self._dec_overflow()
  File "/usr/local/lib/python3.8/dist-packages/sqlalchemy/util/langhelpers.py", line 68, in __exit__
    compat.raise_(
  File "/usr/local/lib/python3.8/dist-packages/sqlalchemy/util/compat.py", line 182, in raise_
    raise exception
  File "/usr/local/lib/python3.8/dist-packages/sqlalchemy/pool/impl.py", line 137, in _do_get
    return self._create_connection()
  File "/usr/local/lib/python3.8/dist-packages/sqlalchemy/pool/base.py", line 309, in _create_connection
    return _ConnectionRecord(self)
  File "/usr/local/lib/python3.8/dist-packages/sqlalchemy/pool/base.py", line 440, in __init__
    self.__connect(first_connect_check=True)
  File "/usr/local/lib/python3.8/dist-packages/sqlalchemy/pool/base.py", line 661, in __connect
    pool.logger.debug("Error on connect(): %s", e)
  File "/usr/local/lib/python3.8/dist-packages/sqlalchemy/util/langhelpers.py", line 68, in __exit__
    compat.raise_(
  File "/usr/local/lib/python3.8/dist-packages/sqlalchemy/util/compat.py", line 182, in raise_
    raise exception
  File "/usr/local/lib/python3.8/dist-packages/sqlalchemy/pool/base.py", line 656, in __connect
    connection = pool._invoke_creator(self)
  File "/usr/local/lib/python3.8/dist-packages/sqlalchemy/engine/strategies.py", line 114, in connect
    return dialect.connect(*cargs, **cparams)
  File "/usr/local/lib/python3.8/dist-packages/sqlalchemy/engine/default.py", line 508, in connect
    return self.dbapi.connect(*cargs, **cparams)
  File "/usr/local/lib/python3.8/dist-packages/psycopg2/__init__.py", line 122, in connect
    conn = _connect(dsn, connection_factory=connection_factory, **kwasync)
psycopg2.OperationalError: FATAL:  could not open file "global/pg_filenode.map": Permission denied


The above exception was the direct cause of the following exception:

Traceback (most recent call last):
  File "/usr/local/lib/python3.8/dist-packages/airflow/dag_processing/processor.py", line 164, in _run_file_processor
    result: Tuple[int, int] = dag_file_processor.process_file(
  File "/usr/local/lib/python3.8/dist-packages/airflow/utils/session.py", line 70, in wrapper
    return func(*args, session=session, **kwargs)
  File "/usr/local/lib/python3.8/dist-packages/airflow/dag_processing/processor.py", line 632, in process_file
    dagbag.sync_to_db()
  File "/usr/local/lib/python3.8/dist-packages/airflow/utils/session.py", line 70, in wrapper
    return func(*args, session=session, **kwargs)
  File "/usr/local/lib/python3.8/dist-packages/airflow/models/dagbag.py", line 604, in sync_to_db
    for attempt in run_with_db_retries(logger=self.log):
  File "/usr/local/lib/python3.8/dist-packages/tenacity/__init__.py", line 390, in __iter__
    do = self.iter(retry_state=retry_state)
  File "/usr/local/lib/python3.8/dist-packages/tenacity/__init__.py", line 368, in iter
    raise retry_exc.reraise()
  File "/usr/local/lib/python3.8/dist-packages/tenacity/__init__.py", line 186, in reraise
    raise self.last_attempt.result()
  File "/usr/lib/python3.8/concurrent/futures/_base.py", line 437, in result
    return self.__get_result()
  File "/usr/lib/python3.8/concurrent/futures/_base.py", line 389, in __get_result
    raise self._exception
  File "/usr/local/lib/python3.8/dist-packages/airflow/models/dagbag.py", line 616, in sync_to_db
    serialize_errors.extend(_serialize_dag_capturing_errors(dag, session))
  File "/usr/local/lib/python3.8/dist-packages/airflow/models/dagbag.py", line 587, in _serialize_dag_capturing_errors
    dag_was_updated = SerializedDagModel.write_dag(
  File "/usr/local/lib/python3.8/dist-packages/airflow/utils/session.py", line 67, in wrapper
    return func(*args, **kwargs)
  File "/usr/local/lib/python3.8/dist-packages/airflow/models/serialized_dag.py", line 120, in write_dag
    if session.query(
  File "/usr/local/lib/python3.8/dist-packages/sqlalchemy/orm/query.py", line 3523, in scalar
    ret = self.one()
  File "/usr/local/lib/python3.8/dist-packages/sqlalchemy/orm/query.py", line 3490, in one
    ret = self.one_or_none()
  File "/usr/local/lib/python3.8/dist-packages/sqlalchemy/orm/query.py", line 3459, in one_or_none
    ret = list(self)
  File "/usr/local/lib/python3.8/dist-packages/sqlalchemy/orm/query.py", line 3535, in __iter__
    return self._execute_and_instances(context)
  File "/usr/local/lib/python3.8/dist-packages/sqlalchemy/orm/query.py", line 3556, in _execute_and_instances
    conn = self._get_bind_args(
  File "/usr/local/lib/python3.8/dist-packages/sqlalchemy/orm/query.py", line 3571, in _get_bind_args
    return fn(
  File "/usr/local/lib/python3.8/dist-packages/sqlalchemy/orm/query.py", line 3550, in _connection_from_session
    conn = self.session.connection(**kw)
  File "/usr/local/lib/python3.8/dist-packages/sqlalchemy/orm/session.py", line 1142, in connection
    return self._connection_for_bind(
  File "/usr/local/lib/python3.8/dist-packages/sqlalchemy/orm/session.py", line 1150, in _connection_for_bind
    return self.transaction._connection_for_bind(
  File "/usr/local/lib/python3.8/dist-packages/sqlalchemy/orm/session.py", line 433, in _connection_for_bind
    conn = bind._contextual_connect()
  File "/usr/local/lib/python3.8/dist-packages/sqlalchemy/engine/base.py", line 2302, in _contextual_connect
    self._wrap_pool_connect(self.pool.connect, None),
  File "/usr/local/lib/python3.8/dist-packages/sqlalchemy/engine/base.py", line 2339, in _wrap_pool_connect
    Connection._handle_dbapi_exception_noconnection(
  File "/usr/local/lib/python3.8/dist-packages/sqlalchemy/engine/base.py", line 1583, in _handle_dbapi_exception_noconnection
    util.raise_(
  File "/usr/local/lib/python3.8/dist-packages/sqlalchemy/util/compat.py", line 182, in raise_
    raise exception
  File "/usr/local/lib/python3.8/dist-packages/sqlalchemy/engine/base.py", line 2336, in _wrap_pool_connect
    return fn()
  File "/usr/local/lib/python3.8/dist-packages/sqlalchemy/pool/base.py", line 364, in connect
    return _ConnectionFairy._checkout(self)
  File "/usr/local/lib/python3.8/dist-packages/sqlalchemy/pool/base.py", line 778, in _checkout
    fairy = _ConnectionRecord.checkout(pool)
  File "/usr/local/lib/python3.8/dist-packages/sqlalchemy/pool/base.py", line 495, in checkout
    rec = pool._do_get()
  File "/usr/local/lib/python3.8/dist-packages/sqlalchemy/pool/impl.py", line 140, in _do_get
    self._dec_overflow()
  File "/usr/local/lib/python3.8/dist-packages/sqlalchemy/util/langhelpers.py", line 68, in __exit__
    compat.raise_(
  File "/usr/local/lib/python3.8/dist-packages/sqlalchemy/util/compat.py", line 182, in raise_
    raise exception
  File "/usr/local/lib/python3.8/dist-packages/sqlalchemy/pool/impl.py", line 137, in _do_get
    return self._create_connection()
  File "/usr/local/lib/python3.8/dist-packages/sqlalchemy/pool/base.py", line 309, in _create_connection
    return _ConnectionRecord(self)
  File "/usr/local/lib/python3.8/dist-packages/sqlalchemy/pool/base.py", line 440, in __init__
    self.__connect(first_connect_check=True)
  File "/usr/local/lib/python3.8/dist-packages/sqlalchemy/pool/base.py", line 661, in __connect
    pool.logger.debug("Error on connect(): %s", e)
  File "/usr/local/lib/python3.8/dist-packages/sqlalchemy/util/langhelpers.py", line 68, in __exit__
    compat.raise_(
  File "/usr/local/lib/python3.8/dist-packages/sqlalchemy/util/compat.py", line 182, in raise_
    raise exception
  File "/usr/local/lib/python3.8/dist-packages/sqlalchemy/pool/base.py", line 656, in __connect
    connection = pool._invoke_creator(self)
  File "/usr/local/lib/python3.8/dist-packages/sqlalchemy/engine/strategies.py", line 114, in connect
    return dialect.connect(*cargs, **cparams)
  File "/usr/local/lib/python3.8/dist-packages/sqlalchemy/engine/default.py", line 508, in connect
    return self.dbapi.connect(*cargs, **cparams)
  File "/usr/local/lib/python3.8/dist-packages/psycopg2/__init__.py", line 122, in connect
    conn = _connect(dsn, connection_factory=connection_factory, **kwasync)
sqlalchemy.exc.OperationalError: (psycopg2.OperationalError) FATAL:  could not open file "global/pg_filenode.map": Permission denied

(Background on this error at: http://sqlalche.me/e/13/e3q8)
[2021-09-03 09:06:16,316] {processor.py:162} INFO - Started process (PID=26838) to work on /usr/local/airflow/dags/connect_to_gdrive.py
[2021-09-03 09:06:16,317] {processor.py:613} INFO - Processing file /usr/local/airflow/dags/connect_to_gdrive.py for tasks to queue
[2021-09-03 09:06:16,318] {logging_mixin.py:109} INFO - [2021-09-03 09:06:16,318] {dagbag.py:496} INFO - Filling up the DagBag from /usr/local/airflow/dags/connect_to_gdrive.py
[2021-09-03 09:06:16,519] {processor.py:623} INFO - DAG(s) dict_keys(['hello_gdive']) retrieved from /usr/local/airflow/dags/connect_to_gdrive.py
[2021-09-03 09:06:17,340] {processor.py:173} ERROR - Got an exception! Propagating...
Traceback (most recent call last):
  File "/usr/local/lib/python3.8/dist-packages/sqlalchemy/engine/base.py", line 2336, in _wrap_pool_connect
    return fn()
  File "/usr/local/lib/python3.8/dist-packages/sqlalchemy/pool/base.py", line 364, in connect
    return _ConnectionFairy._checkout(self)
  File "/usr/local/lib/python3.8/dist-packages/sqlalchemy/pool/base.py", line 778, in _checkout
    fairy = _ConnectionRecord.checkout(pool)
  File "/usr/local/lib/python3.8/dist-packages/sqlalchemy/pool/base.py", line 495, in checkout
    rec = pool._do_get()
  File "/usr/local/lib/python3.8/dist-packages/sqlalchemy/pool/impl.py", line 140, in _do_get
    self._dec_overflow()
  File "/usr/local/lib/python3.8/dist-packages/sqlalchemy/util/langhelpers.py", line 68, in __exit__
    compat.raise_(
  File "/usr/local/lib/python3.8/dist-packages/sqlalchemy/util/compat.py", line 182, in raise_
    raise exception
  File "/usr/local/lib/python3.8/dist-packages/sqlalchemy/pool/impl.py", line 137, in _do_get
    return self._create_connection()
  File "/usr/local/lib/python3.8/dist-packages/sqlalchemy/pool/base.py", line 309, in _create_connection
    return _ConnectionRecord(self)
  File "/usr/local/lib/python3.8/dist-packages/sqlalchemy/pool/base.py", line 440, in __init__
    self.__connect(first_connect_check=True)
  File "/usr/local/lib/python3.8/dist-packages/sqlalchemy/pool/base.py", line 661, in __connect
    pool.logger.debug("Error on connect(): %s", e)
  File "/usr/local/lib/python3.8/dist-packages/sqlalchemy/util/langhelpers.py", line 68, in __exit__
    compat.raise_(
  File "/usr/local/lib/python3.8/dist-packages/sqlalchemy/util/compat.py", line 182, in raise_
    raise exception
  File "/usr/local/lib/python3.8/dist-packages/sqlalchemy/pool/base.py", line 656, in __connect
    connection = pool._invoke_creator(self)
  File "/usr/local/lib/python3.8/dist-packages/sqlalchemy/engine/strategies.py", line 114, in connect
    return dialect.connect(*cargs, **cparams)
  File "/usr/local/lib/python3.8/dist-packages/sqlalchemy/engine/default.py", line 508, in connect
    return self.dbapi.connect(*cargs, **cparams)
  File "/usr/local/lib/python3.8/dist-packages/psycopg2/__init__.py", line 122, in connect
    conn = _connect(dsn, connection_factory=connection_factory, **kwasync)
psycopg2.OperationalError: FATAL:  could not open file "global/pg_filenode.map": Permission denied


The above exception was the direct cause of the following exception:

Traceback (most recent call last):
  File "/usr/local/lib/python3.8/dist-packages/airflow/dag_processing/processor.py", line 164, in _run_file_processor
    result: Tuple[int, int] = dag_file_processor.process_file(
  File "/usr/local/lib/python3.8/dist-packages/airflow/utils/session.py", line 70, in wrapper
    return func(*args, session=session, **kwargs)
  File "/usr/local/lib/python3.8/dist-packages/airflow/dag_processing/processor.py", line 632, in process_file
    dagbag.sync_to_db()
  File "/usr/local/lib/python3.8/dist-packages/airflow/utils/session.py", line 70, in wrapper
    return func(*args, session=session, **kwargs)
  File "/usr/local/lib/python3.8/dist-packages/airflow/models/dagbag.py", line 604, in sync_to_db
    for attempt in run_with_db_retries(logger=self.log):
  File "/usr/local/lib/python3.8/dist-packages/tenacity/__init__.py", line 390, in __iter__
    do = self.iter(retry_state=retry_state)
  File "/usr/local/lib/python3.8/dist-packages/tenacity/__init__.py", line 368, in iter
    raise retry_exc.reraise()
  File "/usr/local/lib/python3.8/dist-packages/tenacity/__init__.py", line 186, in reraise
    raise self.last_attempt.result()
  File "/usr/lib/python3.8/concurrent/futures/_base.py", line 437, in result
    return self.__get_result()
  File "/usr/lib/python3.8/concurrent/futures/_base.py", line 389, in __get_result
    raise self._exception
  File "/usr/local/lib/python3.8/dist-packages/airflow/models/dagbag.py", line 616, in sync_to_db
    serialize_errors.extend(_serialize_dag_capturing_errors(dag, session))
  File "/usr/local/lib/python3.8/dist-packages/airflow/models/dagbag.py", line 587, in _serialize_dag_capturing_errors
    dag_was_updated = SerializedDagModel.write_dag(
  File "/usr/local/lib/python3.8/dist-packages/airflow/utils/session.py", line 67, in wrapper
    return func(*args, **kwargs)
  File "/usr/local/lib/python3.8/dist-packages/airflow/models/serialized_dag.py", line 120, in write_dag
    if session.query(
  File "/usr/local/lib/python3.8/dist-packages/sqlalchemy/orm/query.py", line 3523, in scalar
    ret = self.one()
  File "/usr/local/lib/python3.8/dist-packages/sqlalchemy/orm/query.py", line 3490, in one
    ret = self.one_or_none()
  File "/usr/local/lib/python3.8/dist-packages/sqlalchemy/orm/query.py", line 3459, in one_or_none
    ret = list(self)
  File "/usr/local/lib/python3.8/dist-packages/sqlalchemy/orm/query.py", line 3535, in __iter__
    return self._execute_and_instances(context)
  File "/usr/local/lib/python3.8/dist-packages/sqlalchemy/orm/query.py", line 3556, in _execute_and_instances
    conn = self._get_bind_args(
  File "/usr/local/lib/python3.8/dist-packages/sqlalchemy/orm/query.py", line 3571, in _get_bind_args
    return fn(
  File "/usr/local/lib/python3.8/dist-packages/sqlalchemy/orm/query.py", line 3550, in _connection_from_session
    conn = self.session.connection(**kw)
  File "/usr/local/lib/python3.8/dist-packages/sqlalchemy/orm/session.py", line 1142, in connection
    return self._connection_for_bind(
  File "/usr/local/lib/python3.8/dist-packages/sqlalchemy/orm/session.py", line 1150, in _connection_for_bind
    return self.transaction._connection_for_bind(
  File "/usr/local/lib/python3.8/dist-packages/sqlalchemy/orm/session.py", line 433, in _connection_for_bind
    conn = bind._contextual_connect()
  File "/usr/local/lib/python3.8/dist-packages/sqlalchemy/engine/base.py", line 2302, in _contextual_connect
    self._wrap_pool_connect(self.pool.connect, None),
  File "/usr/local/lib/python3.8/dist-packages/sqlalchemy/engine/base.py", line 2339, in _wrap_pool_connect
    Connection._handle_dbapi_exception_noconnection(
  File "/usr/local/lib/python3.8/dist-packages/sqlalchemy/engine/base.py", line 1583, in _handle_dbapi_exception_noconnection
    util.raise_(
  File "/usr/local/lib/python3.8/dist-packages/sqlalchemy/util/compat.py", line 182, in raise_
    raise exception
  File "/usr/local/lib/python3.8/dist-packages/sqlalchemy/engine/base.py", line 2336, in _wrap_pool_connect
    return fn()
  File "/usr/local/lib/python3.8/dist-packages/sqlalchemy/pool/base.py", line 364, in connect
    return _ConnectionFairy._checkout(self)
  File "/usr/local/lib/python3.8/dist-packages/sqlalchemy/pool/base.py", line 778, in _checkout
    fairy = _ConnectionRecord.checkout(pool)
  File "/usr/local/lib/python3.8/dist-packages/sqlalchemy/pool/base.py", line 495, in checkout
    rec = pool._do_get()
  File "/usr/local/lib/python3.8/dist-packages/sqlalchemy/pool/impl.py", line 140, in _do_get
    self._dec_overflow()
  File "/usr/local/lib/python3.8/dist-packages/sqlalchemy/util/langhelpers.py", line 68, in __exit__
    compat.raise_(
  File "/usr/local/lib/python3.8/dist-packages/sqlalchemy/util/compat.py", line 182, in raise_
    raise exception
  File "/usr/local/lib/python3.8/dist-packages/sqlalchemy/pool/impl.py", line 137, in _do_get
    return self._create_connection()
  File "/usr/local/lib/python3.8/dist-packages/sqlalchemy/pool/base.py", line 309, in _create_connection
    return _ConnectionRecord(self)
  File "/usr/local/lib/python3.8/dist-packages/sqlalchemy/pool/base.py", line 440, in __init__
    self.__connect(first_connect_check=True)
  File "/usr/local/lib/python3.8/dist-packages/sqlalchemy/pool/base.py", line 661, in __connect
    pool.logger.debug("Error on connect(): %s", e)
  File "/usr/local/lib/python3.8/dist-packages/sqlalchemy/util/langhelpers.py", line 68, in __exit__
    compat.raise_(
  File "/usr/local/lib/python3.8/dist-packages/sqlalchemy/util/compat.py", line 182, in raise_
    raise exception
  File "/usr/local/lib/python3.8/dist-packages/sqlalchemy/pool/base.py", line 656, in __connect
    connection = pool._invoke_creator(self)
  File "/usr/local/lib/python3.8/dist-packages/sqlalchemy/engine/strategies.py", line 114, in connect
    return dialect.connect(*cargs, **cparams)
  File "/usr/local/lib/python3.8/dist-packages/sqlalchemy/engine/default.py", line 508, in connect
    return self.dbapi.connect(*cargs, **cparams)
  File "/usr/local/lib/python3.8/dist-packages/psycopg2/__init__.py", line 122, in connect
    conn = _connect(dsn, connection_factory=connection_factory, **kwasync)
sqlalchemy.exc.OperationalError: (psycopg2.OperationalError) FATAL:  could not open file "global/pg_filenode.map": Permission denied

(Background on this error at: http://sqlalche.me/e/13/e3q8)
[2021-09-03 09:06:47,729] {processor.py:162} INFO - Started process (PID=26864) to work on /usr/local/airflow/dags/connect_to_gdrive.py
[2021-09-03 09:06:47,730] {processor.py:613} INFO - Processing file /usr/local/airflow/dags/connect_to_gdrive.py for tasks to queue
[2021-09-03 09:06:47,730] {logging_mixin.py:109} INFO - [2021-09-03 09:06:47,730] {dagbag.py:496} INFO - Filling up the DagBag from /usr/local/airflow/dags/connect_to_gdrive.py
[2021-09-03 09:06:47,918] {processor.py:623} INFO - DAG(s) dict_keys(['hello_gdive']) retrieved from /usr/local/airflow/dags/connect_to_gdrive.py
[2021-09-03 09:06:48,490] {processor.py:173} ERROR - Got an exception! Propagating...
Traceback (most recent call last):
  File "/usr/local/lib/python3.8/dist-packages/sqlalchemy/engine/base.py", line 2336, in _wrap_pool_connect
    return fn()
  File "/usr/local/lib/python3.8/dist-packages/sqlalchemy/pool/base.py", line 364, in connect
    return _ConnectionFairy._checkout(self)
  File "/usr/local/lib/python3.8/dist-packages/sqlalchemy/pool/base.py", line 778, in _checkout
    fairy = _ConnectionRecord.checkout(pool)
  File "/usr/local/lib/python3.8/dist-packages/sqlalchemy/pool/base.py", line 495, in checkout
    rec = pool._do_get()
  File "/usr/local/lib/python3.8/dist-packages/sqlalchemy/pool/impl.py", line 140, in _do_get
    self._dec_overflow()
  File "/usr/local/lib/python3.8/dist-packages/sqlalchemy/util/langhelpers.py", line 68, in __exit__
    compat.raise_(
  File "/usr/local/lib/python3.8/dist-packages/sqlalchemy/util/compat.py", line 182, in raise_
    raise exception
  File "/usr/local/lib/python3.8/dist-packages/sqlalchemy/pool/impl.py", line 137, in _do_get
    return self._create_connection()
  File "/usr/local/lib/python3.8/dist-packages/sqlalchemy/pool/base.py", line 309, in _create_connection
    return _ConnectionRecord(self)
  File "/usr/local/lib/python3.8/dist-packages/sqlalchemy/pool/base.py", line 440, in __init__
    self.__connect(first_connect_check=True)
  File "/usr/local/lib/python3.8/dist-packages/sqlalchemy/pool/base.py", line 661, in __connect
    pool.logger.debug("Error on connect(): %s", e)
  File "/usr/local/lib/python3.8/dist-packages/sqlalchemy/util/langhelpers.py", line 68, in __exit__
    compat.raise_(
  File "/usr/local/lib/python3.8/dist-packages/sqlalchemy/util/compat.py", line 182, in raise_
    raise exception
  File "/usr/local/lib/python3.8/dist-packages/sqlalchemy/pool/base.py", line 656, in __connect
    connection = pool._invoke_creator(self)
  File "/usr/local/lib/python3.8/dist-packages/sqlalchemy/engine/strategies.py", line 114, in connect
    return dialect.connect(*cargs, **cparams)
  File "/usr/local/lib/python3.8/dist-packages/sqlalchemy/engine/default.py", line 508, in connect
    return self.dbapi.connect(*cargs, **cparams)
  File "/usr/local/lib/python3.8/dist-packages/psycopg2/__init__.py", line 122, in connect
    conn = _connect(dsn, connection_factory=connection_factory, **kwasync)
psycopg2.OperationalError: FATAL:  could not open file "global/pg_filenode.map": Permission denied


The above exception was the direct cause of the following exception:

Traceback (most recent call last):
  File "/usr/local/lib/python3.8/dist-packages/airflow/dag_processing/processor.py", line 164, in _run_file_processor
    result: Tuple[int, int] = dag_file_processor.process_file(
  File "/usr/local/lib/python3.8/dist-packages/airflow/utils/session.py", line 70, in wrapper
    return func(*args, session=session, **kwargs)
  File "/usr/local/lib/python3.8/dist-packages/airflow/dag_processing/processor.py", line 632, in process_file
    dagbag.sync_to_db()
  File "/usr/local/lib/python3.8/dist-packages/airflow/utils/session.py", line 70, in wrapper
    return func(*args, session=session, **kwargs)
  File "/usr/local/lib/python3.8/dist-packages/airflow/models/dagbag.py", line 604, in sync_to_db
    for attempt in run_with_db_retries(logger=self.log):
  File "/usr/local/lib/python3.8/dist-packages/tenacity/__init__.py", line 390, in __iter__
    do = self.iter(retry_state=retry_state)
  File "/usr/local/lib/python3.8/dist-packages/tenacity/__init__.py", line 368, in iter
    raise retry_exc.reraise()
  File "/usr/local/lib/python3.8/dist-packages/tenacity/__init__.py", line 186, in reraise
    raise self.last_attempt.result()
  File "/usr/lib/python3.8/concurrent/futures/_base.py", line 437, in result
    return self.__get_result()
  File "/usr/lib/python3.8/concurrent/futures/_base.py", line 389, in __get_result
    raise self._exception
  File "/usr/local/lib/python3.8/dist-packages/airflow/models/dagbag.py", line 616, in sync_to_db
    serialize_errors.extend(_serialize_dag_capturing_errors(dag, session))
  File "/usr/local/lib/python3.8/dist-packages/airflow/models/dagbag.py", line 587, in _serialize_dag_capturing_errors
    dag_was_updated = SerializedDagModel.write_dag(
  File "/usr/local/lib/python3.8/dist-packages/airflow/utils/session.py", line 67, in wrapper
    return func(*args, **kwargs)
  File "/usr/local/lib/python3.8/dist-packages/airflow/models/serialized_dag.py", line 120, in write_dag
    if session.query(
  File "/usr/local/lib/python3.8/dist-packages/sqlalchemy/orm/query.py", line 3523, in scalar
    ret = self.one()
  File "/usr/local/lib/python3.8/dist-packages/sqlalchemy/orm/query.py", line 3490, in one
    ret = self.one_or_none()
  File "/usr/local/lib/python3.8/dist-packages/sqlalchemy/orm/query.py", line 3459, in one_or_none
    ret = list(self)
  File "/usr/local/lib/python3.8/dist-packages/sqlalchemy/orm/query.py", line 3535, in __iter__
    return self._execute_and_instances(context)
  File "/usr/local/lib/python3.8/dist-packages/sqlalchemy/orm/query.py", line 3556, in _execute_and_instances
    conn = self._get_bind_args(
  File "/usr/local/lib/python3.8/dist-packages/sqlalchemy/orm/query.py", line 3571, in _get_bind_args
    return fn(
  File "/usr/local/lib/python3.8/dist-packages/sqlalchemy/orm/query.py", line 3550, in _connection_from_session
    conn = self.session.connection(**kw)
  File "/usr/local/lib/python3.8/dist-packages/sqlalchemy/orm/session.py", line 1142, in connection
    return self._connection_for_bind(
  File "/usr/local/lib/python3.8/dist-packages/sqlalchemy/orm/session.py", line 1150, in _connection_for_bind
    return self.transaction._connection_for_bind(
  File "/usr/local/lib/python3.8/dist-packages/sqlalchemy/orm/session.py", line 433, in _connection_for_bind
    conn = bind._contextual_connect()
  File "/usr/local/lib/python3.8/dist-packages/sqlalchemy/engine/base.py", line 2302, in _contextual_connect
    self._wrap_pool_connect(self.pool.connect, None),
  File "/usr/local/lib/python3.8/dist-packages/sqlalchemy/engine/base.py", line 2339, in _wrap_pool_connect
    Connection._handle_dbapi_exception_noconnection(
  File "/usr/local/lib/python3.8/dist-packages/sqlalchemy/engine/base.py", line 1583, in _handle_dbapi_exception_noconnection
    util.raise_(
  File "/usr/local/lib/python3.8/dist-packages/sqlalchemy/util/compat.py", line 182, in raise_
    raise exception
  File "/usr/local/lib/python3.8/dist-packages/sqlalchemy/engine/base.py", line 2336, in _wrap_pool_connect
    return fn()
  File "/usr/local/lib/python3.8/dist-packages/sqlalchemy/pool/base.py", line 364, in connect
    return _ConnectionFairy._checkout(self)
  File "/usr/local/lib/python3.8/dist-packages/sqlalchemy/pool/base.py", line 778, in _checkout
    fairy = _ConnectionRecord.checkout(pool)
  File "/usr/local/lib/python3.8/dist-packages/sqlalchemy/pool/base.py", line 495, in checkout
    rec = pool._do_get()
  File "/usr/local/lib/python3.8/dist-packages/sqlalchemy/pool/impl.py", line 140, in _do_get
    self._dec_overflow()
  File "/usr/local/lib/python3.8/dist-packages/sqlalchemy/util/langhelpers.py", line 68, in __exit__
    compat.raise_(
  File "/usr/local/lib/python3.8/dist-packages/sqlalchemy/util/compat.py", line 182, in raise_
    raise exception
  File "/usr/local/lib/python3.8/dist-packages/sqlalchemy/pool/impl.py", line 137, in _do_get
    return self._create_connection()
  File "/usr/local/lib/python3.8/dist-packages/sqlalchemy/pool/base.py", line 309, in _create_connection
    return _ConnectionRecord(self)
  File "/usr/local/lib/python3.8/dist-packages/sqlalchemy/pool/base.py", line 440, in __init__
    self.__connect(first_connect_check=True)
  File "/usr/local/lib/python3.8/dist-packages/sqlalchemy/pool/base.py", line 661, in __connect
    pool.logger.debug("Error on connect(): %s", e)
  File "/usr/local/lib/python3.8/dist-packages/sqlalchemy/util/langhelpers.py", line 68, in __exit__
    compat.raise_(
  File "/usr/local/lib/python3.8/dist-packages/sqlalchemy/util/compat.py", line 182, in raise_
    raise exception
  File "/usr/local/lib/python3.8/dist-packages/sqlalchemy/pool/base.py", line 656, in __connect
    connection = pool._invoke_creator(self)
  File "/usr/local/lib/python3.8/dist-packages/sqlalchemy/engine/strategies.py", line 114, in connect
    return dialect.connect(*cargs, **cparams)
  File "/usr/local/lib/python3.8/dist-packages/sqlalchemy/engine/default.py", line 508, in connect
    return self.dbapi.connect(*cargs, **cparams)
  File "/usr/local/lib/python3.8/dist-packages/psycopg2/__init__.py", line 122, in connect
    conn = _connect(dsn, connection_factory=connection_factory, **kwasync)
sqlalchemy.exc.OperationalError: (psycopg2.OperationalError) FATAL:  could not open file "global/pg_filenode.map": Permission denied

(Background on this error at: http://sqlalche.me/e/13/e3q8)
[2021-09-03 16:19:22,680] {processor.py:162} INFO - Started process (PID=173) to work on /usr/local/airflow/dags/connect_to_gdrive.py
[2021-09-03 16:19:22,681] {processor.py:613} INFO - Processing file /usr/local/airflow/dags/connect_to_gdrive.py for tasks to queue
[2021-09-03 16:19:22,681] {logging_mixin.py:109} INFO - [2021-09-03 16:19:22,681] {dagbag.py:496} INFO - Filling up the DagBag from /usr/local/airflow/dags/connect_to_gdrive.py
[2021-09-03 16:19:22,874] {processor.py:623} INFO - DAG(s) dict_keys(['hello_gdive']) retrieved from /usr/local/airflow/dags/connect_to_gdrive.py
[2021-09-03 16:19:22,885] {logging_mixin.py:109} INFO - [2021-09-03 16:19:22,884] {dag.py:1833} INFO - Sync 1 DAGs
[2021-09-03 16:19:22,891] {logging_mixin.py:109} INFO - [2021-09-03 16:19:22,891] {dag.py:2306} INFO - Setting next_dagrun for hello_gdive to None
[2021-09-03 16:19:22,896] {processor.py:170} INFO - Processing /usr/local/airflow/dags/connect_to_gdrive.py took 0.219 seconds
[2021-09-03 16:19:52,925] {processor.py:162} INFO - Started process (PID=919) to work on /usr/local/airflow/dags/connect_to_gdrive.py
[2021-09-03 16:19:52,926] {processor.py:613} INFO - Processing file /usr/local/airflow/dags/connect_to_gdrive.py for tasks to queue
[2021-09-03 16:19:52,926] {logging_mixin.py:109} INFO - [2021-09-03 16:19:52,926] {dagbag.py:496} INFO - Filling up the DagBag from /usr/local/airflow/dags/connect_to_gdrive.py
[2021-09-03 16:19:53,161] {processor.py:623} INFO - DAG(s) dict_keys(['hello_gdive']) retrieved from /usr/local/airflow/dags/connect_to_gdrive.py
[2021-09-03 16:19:53,174] {logging_mixin.py:109} INFO - [2021-09-03 16:19:53,174] {dag.py:1833} INFO - Sync 1 DAGs
[2021-09-03 16:19:53,181] {logging_mixin.py:109} INFO - [2021-09-03 16:19:53,181] {dag.py:2306} INFO - Setting next_dagrun for hello_gdive to None
[2021-09-03 16:19:53,187] {processor.py:170} INFO - Processing /usr/local/airflow/dags/connect_to_gdrive.py took 0.265 seconds
[2021-09-03 16:20:23,282] {processor.py:162} INFO - Started process (PID=1135) to work on /usr/local/airflow/dags/connect_to_gdrive.py
[2021-09-03 16:20:23,283] {processor.py:613} INFO - Processing file /usr/local/airflow/dags/connect_to_gdrive.py for tasks to queue
[2021-09-03 16:20:23,284] {logging_mixin.py:109} INFO - [2021-09-03 16:20:23,283] {dagbag.py:496} INFO - Filling up the DagBag from /usr/local/airflow/dags/connect_to_gdrive.py
[2021-09-03 16:20:23,478] {processor.py:623} INFO - DAG(s) dict_keys(['hello_gdive']) retrieved from /usr/local/airflow/dags/connect_to_gdrive.py
[2021-09-03 16:20:23,489] {logging_mixin.py:109} INFO - [2021-09-03 16:20:23,489] {dag.py:1833} INFO - Sync 1 DAGs
[2021-09-03 16:20:23,496] {logging_mixin.py:109} INFO - [2021-09-03 16:20:23,496] {dag.py:2306} INFO - Setting next_dagrun for hello_gdive to None
[2021-09-03 16:20:23,501] {processor.py:170} INFO - Processing /usr/local/airflow/dags/connect_to_gdrive.py took 0.222 seconds
[2021-09-03 16:20:53,572] {processor.py:162} INFO - Started process (PID=1258) to work on /usr/local/airflow/dags/connect_to_gdrive.py
[2021-09-03 16:20:53,573] {processor.py:613} INFO - Processing file /usr/local/airflow/dags/connect_to_gdrive.py for tasks to queue
[2021-09-03 16:20:53,574] {logging_mixin.py:109} INFO - [2021-09-03 16:20:53,574] {dagbag.py:496} INFO - Filling up the DagBag from /usr/local/airflow/dags/connect_to_gdrive.py
[2021-09-03 16:20:53,771] {processor.py:623} INFO - DAG(s) dict_keys(['hello_gdive']) retrieved from /usr/local/airflow/dags/connect_to_gdrive.py
[2021-09-03 16:20:53,783] {logging_mixin.py:109} INFO - [2021-09-03 16:20:53,783] {dag.py:1833} INFO - Sync 1 DAGs
[2021-09-03 16:20:53,790] {logging_mixin.py:109} INFO - [2021-09-03 16:20:53,790] {dag.py:2306} INFO - Setting next_dagrun for hello_gdive to None
[2021-09-03 16:20:53,796] {processor.py:170} INFO - Processing /usr/local/airflow/dags/connect_to_gdrive.py took 0.226 seconds
[2021-09-03 16:21:24,748] {processor.py:162} INFO - Started process (PID=1284) to work on /usr/local/airflow/dags/connect_to_gdrive.py
[2021-09-03 16:21:24,750] {processor.py:613} INFO - Processing file /usr/local/airflow/dags/connect_to_gdrive.py for tasks to queue
[2021-09-03 16:21:24,750] {logging_mixin.py:109} INFO - [2021-09-03 16:21:24,750] {dagbag.py:496} INFO - Filling up the DagBag from /usr/local/airflow/dags/connect_to_gdrive.py
[2021-09-03 16:21:24,959] {processor.py:623} INFO - DAG(s) dict_keys(['hello_gdive']) retrieved from /usr/local/airflow/dags/connect_to_gdrive.py
[2021-09-03 16:21:24,971] {logging_mixin.py:109} INFO - [2021-09-03 16:21:24,971] {dag.py:1833} INFO - Sync 1 DAGs
[2021-09-03 16:21:24,978] {logging_mixin.py:109} INFO - [2021-09-03 16:21:24,978] {dag.py:2306} INFO - Setting next_dagrun for hello_gdive to None
[2021-09-03 16:21:24,983] {processor.py:170} INFO - Processing /usr/local/airflow/dags/connect_to_gdrive.py took 0.238 seconds
[2021-09-03 16:21:55,006] {processor.py:162} INFO - Started process (PID=1310) to work on /usr/local/airflow/dags/connect_to_gdrive.py
[2021-09-03 16:21:55,007] {processor.py:613} INFO - Processing file /usr/local/airflow/dags/connect_to_gdrive.py for tasks to queue
[2021-09-03 16:21:55,008] {logging_mixin.py:109} INFO - [2021-09-03 16:21:55,008] {dagbag.py:496} INFO - Filling up the DagBag from /usr/local/airflow/dags/connect_to_gdrive.py
[2021-09-03 16:21:55,212] {processor.py:623} INFO - DAG(s) dict_keys(['hello_gdive']) retrieved from /usr/local/airflow/dags/connect_to_gdrive.py
[2021-09-03 16:21:55,224] {logging_mixin.py:109} INFO - [2021-09-03 16:21:55,223] {dag.py:1833} INFO - Sync 1 DAGs
[2021-09-03 16:21:55,231] {logging_mixin.py:109} INFO - [2021-09-03 16:21:55,231] {dag.py:2306} INFO - Setting next_dagrun for hello_gdive to None
[2021-09-03 16:21:55,235] {processor.py:170} INFO - Processing /usr/local/airflow/dags/connect_to_gdrive.py took 0.232 seconds
[2021-09-03 16:22:25,317] {processor.py:162} INFO - Started process (PID=1336) to work on /usr/local/airflow/dags/connect_to_gdrive.py
[2021-09-03 16:22:25,318] {processor.py:613} INFO - Processing file /usr/local/airflow/dags/connect_to_gdrive.py for tasks to queue
[2021-09-03 16:22:25,319] {logging_mixin.py:109} INFO - [2021-09-03 16:22:25,319] {dagbag.py:496} INFO - Filling up the DagBag from /usr/local/airflow/dags/connect_to_gdrive.py
[2021-09-03 16:22:25,524] {processor.py:623} INFO - DAG(s) dict_keys(['hello_gdive']) retrieved from /usr/local/airflow/dags/connect_to_gdrive.py
[2021-09-03 16:22:25,536] {logging_mixin.py:109} INFO - [2021-09-03 16:22:25,536] {dag.py:1833} INFO - Sync 1 DAGs
[2021-09-03 16:22:25,543] {logging_mixin.py:109} INFO - [2021-09-03 16:22:25,543] {dag.py:2306} INFO - Setting next_dagrun for hello_gdive to None
[2021-09-03 16:22:25,547] {processor.py:170} INFO - Processing /usr/local/airflow/dags/connect_to_gdrive.py took 0.234 seconds
[2021-09-03 16:22:55,601] {processor.py:162} INFO - Started process (PID=1362) to work on /usr/local/airflow/dags/connect_to_gdrive.py
[2021-09-03 16:22:55,602] {processor.py:613} INFO - Processing file /usr/local/airflow/dags/connect_to_gdrive.py for tasks to queue
[2021-09-03 16:22:55,603] {logging_mixin.py:109} INFO - [2021-09-03 16:22:55,603] {dagbag.py:496} INFO - Filling up the DagBag from /usr/local/airflow/dags/connect_to_gdrive.py
[2021-09-03 16:22:55,811] {processor.py:623} INFO - DAG(s) dict_keys(['hello_gdive']) retrieved from /usr/local/airflow/dags/connect_to_gdrive.py
[2021-09-03 16:22:56,860] {processor.py:173} ERROR - Got an exception! Propagating...
Traceback (most recent call last):
  File "/usr/local/lib/python3.8/dist-packages/sqlalchemy/engine/base.py", line 2336, in _wrap_pool_connect
    return fn()
  File "/usr/local/lib/python3.8/dist-packages/sqlalchemy/pool/base.py", line 364, in connect
    return _ConnectionFairy._checkout(self)
  File "/usr/local/lib/python3.8/dist-packages/sqlalchemy/pool/base.py", line 778, in _checkout
    fairy = _ConnectionRecord.checkout(pool)
  File "/usr/local/lib/python3.8/dist-packages/sqlalchemy/pool/base.py", line 495, in checkout
    rec = pool._do_get()
  File "/usr/local/lib/python3.8/dist-packages/sqlalchemy/pool/impl.py", line 140, in _do_get
    self._dec_overflow()
  File "/usr/local/lib/python3.8/dist-packages/sqlalchemy/util/langhelpers.py", line 68, in __exit__
    compat.raise_(
  File "/usr/local/lib/python3.8/dist-packages/sqlalchemy/util/compat.py", line 182, in raise_
    raise exception
  File "/usr/local/lib/python3.8/dist-packages/sqlalchemy/pool/impl.py", line 137, in _do_get
    return self._create_connection()
  File "/usr/local/lib/python3.8/dist-packages/sqlalchemy/pool/base.py", line 309, in _create_connection
    return _ConnectionRecord(self)
  File "/usr/local/lib/python3.8/dist-packages/sqlalchemy/pool/base.py", line 440, in __init__
    self.__connect(first_connect_check=True)
  File "/usr/local/lib/python3.8/dist-packages/sqlalchemy/pool/base.py", line 661, in __connect
    pool.logger.debug("Error on connect(): %s", e)
  File "/usr/local/lib/python3.8/dist-packages/sqlalchemy/util/langhelpers.py", line 68, in __exit__
    compat.raise_(
  File "/usr/local/lib/python3.8/dist-packages/sqlalchemy/util/compat.py", line 182, in raise_
    raise exception
  File "/usr/local/lib/python3.8/dist-packages/sqlalchemy/pool/base.py", line 656, in __connect
    connection = pool._invoke_creator(self)
  File "/usr/local/lib/python3.8/dist-packages/sqlalchemy/engine/strategies.py", line 114, in connect
    return dialect.connect(*cargs, **cparams)
  File "/usr/local/lib/python3.8/dist-packages/sqlalchemy/engine/default.py", line 508, in connect
    return self.dbapi.connect(*cargs, **cparams)
  File "/usr/local/lib/python3.8/dist-packages/psycopg2/__init__.py", line 122, in connect
    conn = _connect(dsn, connection_factory=connection_factory, **kwasync)
psycopg2.OperationalError: FATAL:  could not open file "global/pg_filenode.map": Permission denied


The above exception was the direct cause of the following exception:

Traceback (most recent call last):
  File "/usr/local/lib/python3.8/dist-packages/airflow/dag_processing/processor.py", line 164, in _run_file_processor
    result: Tuple[int, int] = dag_file_processor.process_file(
  File "/usr/local/lib/python3.8/dist-packages/airflow/utils/session.py", line 70, in wrapper
    return func(*args, session=session, **kwargs)
  File "/usr/local/lib/python3.8/dist-packages/airflow/dag_processing/processor.py", line 632, in process_file
    dagbag.sync_to_db()
  File "/usr/local/lib/python3.8/dist-packages/airflow/utils/session.py", line 70, in wrapper
    return func(*args, session=session, **kwargs)
  File "/usr/local/lib/python3.8/dist-packages/airflow/models/dagbag.py", line 604, in sync_to_db
    for attempt in run_with_db_retries(logger=self.log):
  File "/usr/local/lib/python3.8/dist-packages/tenacity/__init__.py", line 390, in __iter__
    do = self.iter(retry_state=retry_state)
  File "/usr/local/lib/python3.8/dist-packages/tenacity/__init__.py", line 368, in iter
    raise retry_exc.reraise()
  File "/usr/local/lib/python3.8/dist-packages/tenacity/__init__.py", line 186, in reraise
    raise self.last_attempt.result()
  File "/usr/lib/python3.8/concurrent/futures/_base.py", line 437, in result
    return self.__get_result()
  File "/usr/lib/python3.8/concurrent/futures/_base.py", line 389, in __get_result
    raise self._exception
  File "/usr/local/lib/python3.8/dist-packages/airflow/models/dagbag.py", line 616, in sync_to_db
    serialize_errors.extend(_serialize_dag_capturing_errors(dag, session))
  File "/usr/local/lib/python3.8/dist-packages/airflow/models/dagbag.py", line 587, in _serialize_dag_capturing_errors
    dag_was_updated = SerializedDagModel.write_dag(
  File "/usr/local/lib/python3.8/dist-packages/airflow/utils/session.py", line 67, in wrapper
    return func(*args, **kwargs)
  File "/usr/local/lib/python3.8/dist-packages/airflow/models/serialized_dag.py", line 120, in write_dag
    if session.query(
  File "/usr/local/lib/python3.8/dist-packages/sqlalchemy/orm/query.py", line 3523, in scalar
    ret = self.one()
  File "/usr/local/lib/python3.8/dist-packages/sqlalchemy/orm/query.py", line 3490, in one
    ret = self.one_or_none()
  File "/usr/local/lib/python3.8/dist-packages/sqlalchemy/orm/query.py", line 3459, in one_or_none
    ret = list(self)
  File "/usr/local/lib/python3.8/dist-packages/sqlalchemy/orm/query.py", line 3535, in __iter__
    return self._execute_and_instances(context)
  File "/usr/local/lib/python3.8/dist-packages/sqlalchemy/orm/query.py", line 3556, in _execute_and_instances
    conn = self._get_bind_args(
  File "/usr/local/lib/python3.8/dist-packages/sqlalchemy/orm/query.py", line 3571, in _get_bind_args
    return fn(
  File "/usr/local/lib/python3.8/dist-packages/sqlalchemy/orm/query.py", line 3550, in _connection_from_session
    conn = self.session.connection(**kw)
  File "/usr/local/lib/python3.8/dist-packages/sqlalchemy/orm/session.py", line 1142, in connection
    return self._connection_for_bind(
  File "/usr/local/lib/python3.8/dist-packages/sqlalchemy/orm/session.py", line 1150, in _connection_for_bind
    return self.transaction._connection_for_bind(
  File "/usr/local/lib/python3.8/dist-packages/sqlalchemy/orm/session.py", line 433, in _connection_for_bind
    conn = bind._contextual_connect()
  File "/usr/local/lib/python3.8/dist-packages/sqlalchemy/engine/base.py", line 2302, in _contextual_connect
    self._wrap_pool_connect(self.pool.connect, None),
  File "/usr/local/lib/python3.8/dist-packages/sqlalchemy/engine/base.py", line 2339, in _wrap_pool_connect
    Connection._handle_dbapi_exception_noconnection(
  File "/usr/local/lib/python3.8/dist-packages/sqlalchemy/engine/base.py", line 1583, in _handle_dbapi_exception_noconnection
    util.raise_(
  File "/usr/local/lib/python3.8/dist-packages/sqlalchemy/util/compat.py", line 182, in raise_
    raise exception
  File "/usr/local/lib/python3.8/dist-packages/sqlalchemy/engine/base.py", line 2336, in _wrap_pool_connect
    return fn()
  File "/usr/local/lib/python3.8/dist-packages/sqlalchemy/pool/base.py", line 364, in connect
    return _ConnectionFairy._checkout(self)
  File "/usr/local/lib/python3.8/dist-packages/sqlalchemy/pool/base.py", line 778, in _checkout
    fairy = _ConnectionRecord.checkout(pool)
  File "/usr/local/lib/python3.8/dist-packages/sqlalchemy/pool/base.py", line 495, in checkout
    rec = pool._do_get()
  File "/usr/local/lib/python3.8/dist-packages/sqlalchemy/pool/impl.py", line 140, in _do_get
    self._dec_overflow()
  File "/usr/local/lib/python3.8/dist-packages/sqlalchemy/util/langhelpers.py", line 68, in __exit__
    compat.raise_(
  File "/usr/local/lib/python3.8/dist-packages/sqlalchemy/util/compat.py", line 182, in raise_
    raise exception
  File "/usr/local/lib/python3.8/dist-packages/sqlalchemy/pool/impl.py", line 137, in _do_get
    return self._create_connection()
  File "/usr/local/lib/python3.8/dist-packages/sqlalchemy/pool/base.py", line 309, in _create_connection
    return _ConnectionRecord(self)
  File "/usr/local/lib/python3.8/dist-packages/sqlalchemy/pool/base.py", line 440, in __init__
    self.__connect(first_connect_check=True)
  File "/usr/local/lib/python3.8/dist-packages/sqlalchemy/pool/base.py", line 661, in __connect
    pool.logger.debug("Error on connect(): %s", e)
  File "/usr/local/lib/python3.8/dist-packages/sqlalchemy/util/langhelpers.py", line 68, in __exit__
    compat.raise_(
  File "/usr/local/lib/python3.8/dist-packages/sqlalchemy/util/compat.py", line 182, in raise_
    raise exception
  File "/usr/local/lib/python3.8/dist-packages/sqlalchemy/pool/base.py", line 656, in __connect
    connection = pool._invoke_creator(self)
  File "/usr/local/lib/python3.8/dist-packages/sqlalchemy/engine/strategies.py", line 114, in connect
    return dialect.connect(*cargs, **cparams)
  File "/usr/local/lib/python3.8/dist-packages/sqlalchemy/engine/default.py", line 508, in connect
    return self.dbapi.connect(*cargs, **cparams)
  File "/usr/local/lib/python3.8/dist-packages/psycopg2/__init__.py", line 122, in connect
    conn = _connect(dsn, connection_factory=connection_factory, **kwasync)
sqlalchemy.exc.OperationalError: (psycopg2.OperationalError) FATAL:  could not open file "global/pg_filenode.map": Permission denied

(Background on this error at: http://sqlalche.me/e/13/e3q8)
[2021-09-03 16:23:26,902] {processor.py:162} INFO - Started process (PID=1388) to work on /usr/local/airflow/dags/connect_to_gdrive.py
[2021-09-03 16:23:26,903] {processor.py:613} INFO - Processing file /usr/local/airflow/dags/connect_to_gdrive.py for tasks to queue
[2021-09-03 16:23:26,903] {logging_mixin.py:109} INFO - [2021-09-03 16:23:26,903] {dagbag.py:496} INFO - Filling up the DagBag from /usr/local/airflow/dags/connect_to_gdrive.py
[2021-09-03 16:23:27,120] {processor.py:623} INFO - DAG(s) dict_keys(['hello_gdive']) retrieved from /usr/local/airflow/dags/connect_to_gdrive.py
[2021-09-03 16:23:28,151] {processor.py:173} ERROR - Got an exception! Propagating...
Traceback (most recent call last):
  File "/usr/local/lib/python3.8/dist-packages/sqlalchemy/engine/base.py", line 2336, in _wrap_pool_connect
    return fn()
  File "/usr/local/lib/python3.8/dist-packages/sqlalchemy/pool/base.py", line 364, in connect
    return _ConnectionFairy._checkout(self)
  File "/usr/local/lib/python3.8/dist-packages/sqlalchemy/pool/base.py", line 778, in _checkout
    fairy = _ConnectionRecord.checkout(pool)
  File "/usr/local/lib/python3.8/dist-packages/sqlalchemy/pool/base.py", line 495, in checkout
    rec = pool._do_get()
  File "/usr/local/lib/python3.8/dist-packages/sqlalchemy/pool/impl.py", line 140, in _do_get
    self._dec_overflow()
  File "/usr/local/lib/python3.8/dist-packages/sqlalchemy/util/langhelpers.py", line 68, in __exit__
    compat.raise_(
  File "/usr/local/lib/python3.8/dist-packages/sqlalchemy/util/compat.py", line 182, in raise_
    raise exception
  File "/usr/local/lib/python3.8/dist-packages/sqlalchemy/pool/impl.py", line 137, in _do_get
    return self._create_connection()
  File "/usr/local/lib/python3.8/dist-packages/sqlalchemy/pool/base.py", line 309, in _create_connection
    return _ConnectionRecord(self)
  File "/usr/local/lib/python3.8/dist-packages/sqlalchemy/pool/base.py", line 440, in __init__
    self.__connect(first_connect_check=True)
  File "/usr/local/lib/python3.8/dist-packages/sqlalchemy/pool/base.py", line 661, in __connect
    pool.logger.debug("Error on connect(): %s", e)
  File "/usr/local/lib/python3.8/dist-packages/sqlalchemy/util/langhelpers.py", line 68, in __exit__
    compat.raise_(
  File "/usr/local/lib/python3.8/dist-packages/sqlalchemy/util/compat.py", line 182, in raise_
    raise exception
  File "/usr/local/lib/python3.8/dist-packages/sqlalchemy/pool/base.py", line 656, in __connect
    connection = pool._invoke_creator(self)
  File "/usr/local/lib/python3.8/dist-packages/sqlalchemy/engine/strategies.py", line 114, in connect
    return dialect.connect(*cargs, **cparams)
  File "/usr/local/lib/python3.8/dist-packages/sqlalchemy/engine/default.py", line 508, in connect
    return self.dbapi.connect(*cargs, **cparams)
  File "/usr/local/lib/python3.8/dist-packages/psycopg2/__init__.py", line 122, in connect
    conn = _connect(dsn, connection_factory=connection_factory, **kwasync)
psycopg2.OperationalError: FATAL:  could not open file "global/pg_filenode.map": Permission denied


The above exception was the direct cause of the following exception:

Traceback (most recent call last):
  File "/usr/local/lib/python3.8/dist-packages/airflow/dag_processing/processor.py", line 164, in _run_file_processor
    result: Tuple[int, int] = dag_file_processor.process_file(
  File "/usr/local/lib/python3.8/dist-packages/airflow/utils/session.py", line 70, in wrapper
    return func(*args, session=session, **kwargs)
  File "/usr/local/lib/python3.8/dist-packages/airflow/dag_processing/processor.py", line 632, in process_file
    dagbag.sync_to_db()
  File "/usr/local/lib/python3.8/dist-packages/airflow/utils/session.py", line 70, in wrapper
    return func(*args, session=session, **kwargs)
  File "/usr/local/lib/python3.8/dist-packages/airflow/models/dagbag.py", line 604, in sync_to_db
    for attempt in run_with_db_retries(logger=self.log):
  File "/usr/local/lib/python3.8/dist-packages/tenacity/__init__.py", line 390, in __iter__
    do = self.iter(retry_state=retry_state)
  File "/usr/local/lib/python3.8/dist-packages/tenacity/__init__.py", line 368, in iter
    raise retry_exc.reraise()
  File "/usr/local/lib/python3.8/dist-packages/tenacity/__init__.py", line 186, in reraise
    raise self.last_attempt.result()
  File "/usr/lib/python3.8/concurrent/futures/_base.py", line 437, in result
    return self.__get_result()
  File "/usr/lib/python3.8/concurrent/futures/_base.py", line 389, in __get_result
    raise self._exception
  File "/usr/local/lib/python3.8/dist-packages/airflow/models/dagbag.py", line 616, in sync_to_db
    serialize_errors.extend(_serialize_dag_capturing_errors(dag, session))
  File "/usr/local/lib/python3.8/dist-packages/airflow/models/dagbag.py", line 587, in _serialize_dag_capturing_errors
    dag_was_updated = SerializedDagModel.write_dag(
  File "/usr/local/lib/python3.8/dist-packages/airflow/utils/session.py", line 67, in wrapper
    return func(*args, **kwargs)
  File "/usr/local/lib/python3.8/dist-packages/airflow/models/serialized_dag.py", line 120, in write_dag
    if session.query(
  File "/usr/local/lib/python3.8/dist-packages/sqlalchemy/orm/query.py", line 3523, in scalar
    ret = self.one()
  File "/usr/local/lib/python3.8/dist-packages/sqlalchemy/orm/query.py", line 3490, in one
    ret = self.one_or_none()
  File "/usr/local/lib/python3.8/dist-packages/sqlalchemy/orm/query.py", line 3459, in one_or_none
    ret = list(self)
  File "/usr/local/lib/python3.8/dist-packages/sqlalchemy/orm/query.py", line 3535, in __iter__
    return self._execute_and_instances(context)
  File "/usr/local/lib/python3.8/dist-packages/sqlalchemy/orm/query.py", line 3556, in _execute_and_instances
    conn = self._get_bind_args(
  File "/usr/local/lib/python3.8/dist-packages/sqlalchemy/orm/query.py", line 3571, in _get_bind_args
    return fn(
  File "/usr/local/lib/python3.8/dist-packages/sqlalchemy/orm/query.py", line 3550, in _connection_from_session
    conn = self.session.connection(**kw)
  File "/usr/local/lib/python3.8/dist-packages/sqlalchemy/orm/session.py", line 1142, in connection
    return self._connection_for_bind(
  File "/usr/local/lib/python3.8/dist-packages/sqlalchemy/orm/session.py", line 1150, in _connection_for_bind
    return self.transaction._connection_for_bind(
  File "/usr/local/lib/python3.8/dist-packages/sqlalchemy/orm/session.py", line 433, in _connection_for_bind
    conn = bind._contextual_connect()
  File "/usr/local/lib/python3.8/dist-packages/sqlalchemy/engine/base.py", line 2302, in _contextual_connect
    self._wrap_pool_connect(self.pool.connect, None),
  File "/usr/local/lib/python3.8/dist-packages/sqlalchemy/engine/base.py", line 2339, in _wrap_pool_connect
    Connection._handle_dbapi_exception_noconnection(
  File "/usr/local/lib/python3.8/dist-packages/sqlalchemy/engine/base.py", line 1583, in _handle_dbapi_exception_noconnection
    util.raise_(
  File "/usr/local/lib/python3.8/dist-packages/sqlalchemy/util/compat.py", line 182, in raise_
    raise exception
  File "/usr/local/lib/python3.8/dist-packages/sqlalchemy/engine/base.py", line 2336, in _wrap_pool_connect
    return fn()
  File "/usr/local/lib/python3.8/dist-packages/sqlalchemy/pool/base.py", line 364, in connect
    return _ConnectionFairy._checkout(self)
  File "/usr/local/lib/python3.8/dist-packages/sqlalchemy/pool/base.py", line 778, in _checkout
    fairy = _ConnectionRecord.checkout(pool)
  File "/usr/local/lib/python3.8/dist-packages/sqlalchemy/pool/base.py", line 495, in checkout
    rec = pool._do_get()
  File "/usr/local/lib/python3.8/dist-packages/sqlalchemy/pool/impl.py", line 140, in _do_get
    self._dec_overflow()
  File "/usr/local/lib/python3.8/dist-packages/sqlalchemy/util/langhelpers.py", line 68, in __exit__
    compat.raise_(
  File "/usr/local/lib/python3.8/dist-packages/sqlalchemy/util/compat.py", line 182, in raise_
    raise exception
  File "/usr/local/lib/python3.8/dist-packages/sqlalchemy/pool/impl.py", line 137, in _do_get
    return self._create_connection()
  File "/usr/local/lib/python3.8/dist-packages/sqlalchemy/pool/base.py", line 309, in _create_connection
    return _ConnectionRecord(self)
  File "/usr/local/lib/python3.8/dist-packages/sqlalchemy/pool/base.py", line 440, in __init__
    self.__connect(first_connect_check=True)
  File "/usr/local/lib/python3.8/dist-packages/sqlalchemy/pool/base.py", line 661, in __connect
    pool.logger.debug("Error on connect(): %s", e)
  File "/usr/local/lib/python3.8/dist-packages/sqlalchemy/util/langhelpers.py", line 68, in __exit__
    compat.raise_(
  File "/usr/local/lib/python3.8/dist-packages/sqlalchemy/util/compat.py", line 182, in raise_
    raise exception
  File "/usr/local/lib/python3.8/dist-packages/sqlalchemy/pool/base.py", line 656, in __connect
    connection = pool._invoke_creator(self)
  File "/usr/local/lib/python3.8/dist-packages/sqlalchemy/engine/strategies.py", line 114, in connect
    return dialect.connect(*cargs, **cparams)
  File "/usr/local/lib/python3.8/dist-packages/sqlalchemy/engine/default.py", line 508, in connect
    return self.dbapi.connect(*cargs, **cparams)
  File "/usr/local/lib/python3.8/dist-packages/psycopg2/__init__.py", line 122, in connect
    conn = _connect(dsn, connection_factory=connection_factory, **kwasync)
sqlalchemy.exc.OperationalError: (psycopg2.OperationalError) FATAL:  could not open file "global/pg_filenode.map": Permission denied

(Background on this error at: http://sqlalche.me/e/13/e3q8)
[2021-09-03 16:23:58,544] {processor.py:162} INFO - Started process (PID=1415) to work on /usr/local/airflow/dags/connect_to_gdrive.py
[2021-09-03 16:23:58,545] {processor.py:613} INFO - Processing file /usr/local/airflow/dags/connect_to_gdrive.py for tasks to queue
[2021-09-03 16:23:58,546] {logging_mixin.py:109} INFO - [2021-09-03 16:23:58,546] {dagbag.py:496} INFO - Filling up the DagBag from /usr/local/airflow/dags/connect_to_gdrive.py
[2021-09-03 16:23:58,757] {processor.py:623} INFO - DAG(s) dict_keys(['hello_gdive']) retrieved from /usr/local/airflow/dags/connect_to_gdrive.py
[2021-09-03 16:23:59,243] {processor.py:173} ERROR - Got an exception! Propagating...
Traceback (most recent call last):
  File "/usr/local/lib/python3.8/dist-packages/sqlalchemy/engine/base.py", line 2336, in _wrap_pool_connect
    return fn()
  File "/usr/local/lib/python3.8/dist-packages/sqlalchemy/pool/base.py", line 364, in connect
    return _ConnectionFairy._checkout(self)
  File "/usr/local/lib/python3.8/dist-packages/sqlalchemy/pool/base.py", line 778, in _checkout
    fairy = _ConnectionRecord.checkout(pool)
  File "/usr/local/lib/python3.8/dist-packages/sqlalchemy/pool/base.py", line 495, in checkout
    rec = pool._do_get()
  File "/usr/local/lib/python3.8/dist-packages/sqlalchemy/pool/impl.py", line 140, in _do_get
    self._dec_overflow()
  File "/usr/local/lib/python3.8/dist-packages/sqlalchemy/util/langhelpers.py", line 68, in __exit__
    compat.raise_(
  File "/usr/local/lib/python3.8/dist-packages/sqlalchemy/util/compat.py", line 182, in raise_
    raise exception
  File "/usr/local/lib/python3.8/dist-packages/sqlalchemy/pool/impl.py", line 137, in _do_get
    return self._create_connection()
  File "/usr/local/lib/python3.8/dist-packages/sqlalchemy/pool/base.py", line 309, in _create_connection
    return _ConnectionRecord(self)
  File "/usr/local/lib/python3.8/dist-packages/sqlalchemy/pool/base.py", line 440, in __init__
    self.__connect(first_connect_check=True)
  File "/usr/local/lib/python3.8/dist-packages/sqlalchemy/pool/base.py", line 661, in __connect
    pool.logger.debug("Error on connect(): %s", e)
  File "/usr/local/lib/python3.8/dist-packages/sqlalchemy/util/langhelpers.py", line 68, in __exit__
    compat.raise_(
  File "/usr/local/lib/python3.8/dist-packages/sqlalchemy/util/compat.py", line 182, in raise_
    raise exception
  File "/usr/local/lib/python3.8/dist-packages/sqlalchemy/pool/base.py", line 656, in __connect
    connection = pool._invoke_creator(self)
  File "/usr/local/lib/python3.8/dist-packages/sqlalchemy/engine/strategies.py", line 114, in connect
    return dialect.connect(*cargs, **cparams)
  File "/usr/local/lib/python3.8/dist-packages/sqlalchemy/engine/default.py", line 508, in connect
    return self.dbapi.connect(*cargs, **cparams)
  File "/usr/local/lib/python3.8/dist-packages/psycopg2/__init__.py", line 122, in connect
    conn = _connect(dsn, connection_factory=connection_factory, **kwasync)
psycopg2.OperationalError: FATAL:  could not open file "global/pg_filenode.map": Permission denied


The above exception was the direct cause of the following exception:

Traceback (most recent call last):
  File "/usr/local/lib/python3.8/dist-packages/airflow/dag_processing/processor.py", line 164, in _run_file_processor
    result: Tuple[int, int] = dag_file_processor.process_file(
  File "/usr/local/lib/python3.8/dist-packages/airflow/utils/session.py", line 70, in wrapper
    return func(*args, session=session, **kwargs)
  File "/usr/local/lib/python3.8/dist-packages/airflow/dag_processing/processor.py", line 632, in process_file
    dagbag.sync_to_db()
  File "/usr/local/lib/python3.8/dist-packages/airflow/utils/session.py", line 70, in wrapper
    return func(*args, session=session, **kwargs)
  File "/usr/local/lib/python3.8/dist-packages/airflow/models/dagbag.py", line 604, in sync_to_db
    for attempt in run_with_db_retries(logger=self.log):
  File "/usr/local/lib/python3.8/dist-packages/tenacity/__init__.py", line 390, in __iter__
    do = self.iter(retry_state=retry_state)
  File "/usr/local/lib/python3.8/dist-packages/tenacity/__init__.py", line 368, in iter
    raise retry_exc.reraise()
  File "/usr/local/lib/python3.8/dist-packages/tenacity/__init__.py", line 186, in reraise
    raise self.last_attempt.result()
  File "/usr/lib/python3.8/concurrent/futures/_base.py", line 437, in result
    return self.__get_result()
  File "/usr/lib/python3.8/concurrent/futures/_base.py", line 389, in __get_result
    raise self._exception
  File "/usr/local/lib/python3.8/dist-packages/airflow/models/dagbag.py", line 616, in sync_to_db
    serialize_errors.extend(_serialize_dag_capturing_errors(dag, session))
  File "/usr/local/lib/python3.8/dist-packages/airflow/models/dagbag.py", line 587, in _serialize_dag_capturing_errors
    dag_was_updated = SerializedDagModel.write_dag(
  File "/usr/local/lib/python3.8/dist-packages/airflow/utils/session.py", line 67, in wrapper
    return func(*args, **kwargs)
  File "/usr/local/lib/python3.8/dist-packages/airflow/models/serialized_dag.py", line 120, in write_dag
    if session.query(
  File "/usr/local/lib/python3.8/dist-packages/sqlalchemy/orm/query.py", line 3523, in scalar
    ret = self.one()
  File "/usr/local/lib/python3.8/dist-packages/sqlalchemy/orm/query.py", line 3490, in one
    ret = self.one_or_none()
  File "/usr/local/lib/python3.8/dist-packages/sqlalchemy/orm/query.py", line 3459, in one_or_none
    ret = list(self)
  File "/usr/local/lib/python3.8/dist-packages/sqlalchemy/orm/query.py", line 3535, in __iter__
    return self._execute_and_instances(context)
  File "/usr/local/lib/python3.8/dist-packages/sqlalchemy/orm/query.py", line 3556, in _execute_and_instances
    conn = self._get_bind_args(
  File "/usr/local/lib/python3.8/dist-packages/sqlalchemy/orm/query.py", line 3571, in _get_bind_args
    return fn(
  File "/usr/local/lib/python3.8/dist-packages/sqlalchemy/orm/query.py", line 3550, in _connection_from_session
    conn = self.session.connection(**kw)
  File "/usr/local/lib/python3.8/dist-packages/sqlalchemy/orm/session.py", line 1142, in connection
    return self._connection_for_bind(
  File "/usr/local/lib/python3.8/dist-packages/sqlalchemy/orm/session.py", line 1150, in _connection_for_bind
    return self.transaction._connection_for_bind(
  File "/usr/local/lib/python3.8/dist-packages/sqlalchemy/orm/session.py", line 433, in _connection_for_bind
    conn = bind._contextual_connect()
  File "/usr/local/lib/python3.8/dist-packages/sqlalchemy/engine/base.py", line 2302, in _contextual_connect
    self._wrap_pool_connect(self.pool.connect, None),
  File "/usr/local/lib/python3.8/dist-packages/sqlalchemy/engine/base.py", line 2339, in _wrap_pool_connect
    Connection._handle_dbapi_exception_noconnection(
  File "/usr/local/lib/python3.8/dist-packages/sqlalchemy/engine/base.py", line 1583, in _handle_dbapi_exception_noconnection
    util.raise_(
  File "/usr/local/lib/python3.8/dist-packages/sqlalchemy/util/compat.py", line 182, in raise_
    raise exception
  File "/usr/local/lib/python3.8/dist-packages/sqlalchemy/engine/base.py", line 2336, in _wrap_pool_connect
    return fn()
  File "/usr/local/lib/python3.8/dist-packages/sqlalchemy/pool/base.py", line 364, in connect
    return _ConnectionFairy._checkout(self)
  File "/usr/local/lib/python3.8/dist-packages/sqlalchemy/pool/base.py", line 778, in _checkout
    fairy = _ConnectionRecord.checkout(pool)
  File "/usr/local/lib/python3.8/dist-packages/sqlalchemy/pool/base.py", line 495, in checkout
    rec = pool._do_get()
  File "/usr/local/lib/python3.8/dist-packages/sqlalchemy/pool/impl.py", line 140, in _do_get
    self._dec_overflow()
  File "/usr/local/lib/python3.8/dist-packages/sqlalchemy/util/langhelpers.py", line 68, in __exit__
    compat.raise_(
  File "/usr/local/lib/python3.8/dist-packages/sqlalchemy/util/compat.py", line 182, in raise_
    raise exception
  File "/usr/local/lib/python3.8/dist-packages/sqlalchemy/pool/impl.py", line 137, in _do_get
    return self._create_connection()
  File "/usr/local/lib/python3.8/dist-packages/sqlalchemy/pool/base.py", line 309, in _create_connection
    return _ConnectionRecord(self)
  File "/usr/local/lib/python3.8/dist-packages/sqlalchemy/pool/base.py", line 440, in __init__
    self.__connect(first_connect_check=True)
  File "/usr/local/lib/python3.8/dist-packages/sqlalchemy/pool/base.py", line 661, in __connect
    pool.logger.debug("Error on connect(): %s", e)
  File "/usr/local/lib/python3.8/dist-packages/sqlalchemy/util/langhelpers.py", line 68, in __exit__
    compat.raise_(
  File "/usr/local/lib/python3.8/dist-packages/sqlalchemy/util/compat.py", line 182, in raise_
    raise exception
  File "/usr/local/lib/python3.8/dist-packages/sqlalchemy/pool/base.py", line 656, in __connect
    connection = pool._invoke_creator(self)
  File "/usr/local/lib/python3.8/dist-packages/sqlalchemy/engine/strategies.py", line 114, in connect
    return dialect.connect(*cargs, **cparams)
  File "/usr/local/lib/python3.8/dist-packages/sqlalchemy/engine/default.py", line 508, in connect
    return self.dbapi.connect(*cargs, **cparams)
  File "/usr/local/lib/python3.8/dist-packages/psycopg2/__init__.py", line 122, in connect
    conn = _connect(dsn, connection_factory=connection_factory, **kwasync)
sqlalchemy.exc.OperationalError: (psycopg2.OperationalError) FATAL:  could not open file "global/pg_filenode.map": Permission denied

(Background on this error at: http://sqlalche.me/e/13/e3q8)
