[2021-09-03 08:47:06,618] {taskinstance.py:903} INFO - Dependencies all met for <TaskInstance: hello_gdive.py_op_1 2021-09-03T08:47:05.140956+00:00 [queued]>
[2021-09-03 08:47:06,625] {taskinstance.py:903} INFO - Dependencies all met for <TaskInstance: hello_gdive.py_op_1 2021-09-03T08:47:05.140956+00:00 [queued]>
[2021-09-03 08:47:06,625] {taskinstance.py:1094} INFO - 
--------------------------------------------------------------------------------
[2021-09-03 08:47:06,625] {taskinstance.py:1095} INFO - Starting attempt 1 of 1
[2021-09-03 08:47:06,625] {taskinstance.py:1096} INFO - 
--------------------------------------------------------------------------------
[2021-09-03 08:47:06,639] {taskinstance.py:1114} INFO - Executing <Task(PythonOperator): py_op_1> on 2021-09-03T08:47:05.140956+00:00
[2021-09-03 08:47:06,643] {standard_task_runner.py:52} INFO - Started process 21861 to run task
[2021-09-03 08:47:06,647] {standard_task_runner.py:76} INFO - Running: ['airflow', 'tasks', 'run', 'hello_gdive', 'py_op_1', '2021-09-03T08:47:05.140956+00:00', '--job-id', '117', '--pool', 'default_pool', '--raw', '--subdir', 'DAGS_FOLDER/connect_to_gdrive.py', '--cfg-path', '/tmp/tmpvgq40516', '--error-file', '/tmp/tmph_l25_ud']
[2021-09-03 08:47:06,647] {standard_task_runner.py:77} INFO - Job 117: Subtask py_op_1
[2021-09-03 08:47:06,690] {logging_mixin.py:109} INFO - Running <TaskInstance: hello_gdive.py_op_1 2021-09-03T08:47:05.140956+00:00 [running]> on host 961ab95df326
[2021-09-03 08:47:06,744] {taskinstance.py:1251} INFO - Exporting the following env vars:
AIRFLOW_CTX_DAG_OWNER=airflow
AIRFLOW_CTX_DAG_ID=hello_gdive
AIRFLOW_CTX_TASK_ID=py_op_1
AIRFLOW_CTX_EXECUTION_DATE=2021-09-03T08:47:05.140956+00:00
AIRFLOW_CTX_DAG_RUN_ID=manual__2021-09-03T08:47:05.140956+00:00
[2021-09-03 08:47:06,755] {__init__.py:48} WARNING - file_cache is unavailable when using oauth2client >= 4.0.0 or google-auth
Traceback (most recent call last):
  File "/usr/local/lib/python3.8/dist-packages/googleapiclient/discovery_cache/file_cache.py", line 33, in <module>
    from oauth2client.contrib.locked_file import LockedFile
ModuleNotFoundError: No module named 'oauth2client'

During handling of the above exception, another exception occurred:

Traceback (most recent call last):
  File "/usr/local/lib/python3.8/dist-packages/googleapiclient/discovery_cache/file_cache.py", line 37, in <module>
    from oauth2client.locked_file import LockedFile
ModuleNotFoundError: No module named 'oauth2client'

During handling of the above exception, another exception occurred:

Traceback (most recent call last):
  File "/usr/local/lib/python3.8/dist-packages/googleapiclient/discovery_cache/__init__.py", line 44, in autodetect
    from . import file_cache
  File "/usr/local/lib/python3.8/dist-packages/googleapiclient/discovery_cache/file_cache.py", line 40, in <module>
    raise ImportError(
ImportError: file_cache is unavailable when using oauth2client >= 4.0.0 or google-auth
[2021-09-03 08:47:08,262] {logging_mixin.py:109} INFO - I LOVE PYTHON: 1mwy3WmRATps0t36_kesuEY8Thbi4XgzW
[2021-09-03 08:47:08,262] {python.py:151} INFO - Done. Returned value was: None
[2021-09-03 08:47:08,276] {taskinstance.py:1211} INFO - Marking task as SUCCESS. dag_id=hello_gdive, task_id=py_op_1, execution_date=20210903T084705, start_date=20210903T084706, end_date=20210903T084708
[2021-09-03 08:47:08,302] {local_task_job.py:151} INFO - Task exited with return code 0
[2021-09-03 08:47:08,325] {local_task_job.py:261} INFO - 0 downstream tasks scheduled from follow-on schedule check
