[2021-09-03 08:27:12,674] {taskinstance.py:903} INFO - Dependencies all met for <TaskInstance: hello_gdive.py_op_1 2021-09-03T08:27:10.595071+00:00 [queued]>
[2021-09-03 08:27:12,681] {taskinstance.py:903} INFO - Dependencies all met for <TaskInstance: hello_gdive.py_op_1 2021-09-03T08:27:10.595071+00:00 [queued]>
[2021-09-03 08:27:12,681] {taskinstance.py:1094} INFO - 
--------------------------------------------------------------------------------
[2021-09-03 08:27:12,681] {taskinstance.py:1095} INFO - Starting attempt 1 of 1
[2021-09-03 08:27:12,681] {taskinstance.py:1096} INFO - 
--------------------------------------------------------------------------------
[2021-09-03 08:27:12,691] {taskinstance.py:1114} INFO - Executing <Task(PythonOperator): py_op_1> on 2021-09-03T08:27:10.595071+00:00
[2021-09-03 08:27:12,694] {standard_task_runner.py:52} INFO - Started process 8520 to run task
[2021-09-03 08:27:12,699] {standard_task_runner.py:76} INFO - Running: ['airflow', 'tasks', 'run', 'hello_gdive', 'py_op_1', '2021-09-03T08:27:10.595071+00:00', '--job-id', '110', '--pool', 'default_pool', '--raw', '--subdir', 'DAGS_FOLDER/connect_to_gdrive.py', '--cfg-path', '/tmp/tmpitlbqolk', '--error-file', '/tmp/tmpnhitz5fc']
[2021-09-03 08:27:12,699] {standard_task_runner.py:77} INFO - Job 110: Subtask py_op_1
[2021-09-03 08:27:12,753] {logging_mixin.py:109} INFO - Running <TaskInstance: hello_gdive.py_op_1 2021-09-03T08:27:10.595071+00:00 [running]> on host 961ab95df326
[2021-09-03 08:27:12,803] {taskinstance.py:1251} INFO - Exporting the following env vars:
AIRFLOW_CTX_DAG_OWNER=airflow
AIRFLOW_CTX_DAG_ID=hello_gdive
AIRFLOW_CTX_TASK_ID=py_op_1
AIRFLOW_CTX_EXECUTION_DATE=2021-09-03T08:27:10.595071+00:00
AIRFLOW_CTX_DAG_RUN_ID=manual__2021-09-03T08:27:10.595071+00:00
[2021-09-03 08:27:12,805] {taskinstance.py:1462} ERROR - Task failed with exception
Traceback (most recent call last):
  File "/usr/local/lib/python3.8/dist-packages/airflow/models/taskinstance.py", line 1164, in _run_raw_task
    self._prepare_and_execute_task_with_callbacks(context, task)
  File "/usr/local/lib/python3.8/dist-packages/airflow/models/taskinstance.py", line 1282, in _prepare_and_execute_task_with_callbacks
    result = self._execute_task(context, task_copy)
  File "/usr/local/lib/python3.8/dist-packages/airflow/models/taskinstance.py", line 1312, in _execute_task
    result = task_copy.execute(context=context)
  File "/usr/local/lib/python3.8/dist-packages/airflow/operators/python.py", line 150, in execute
    return_value = self.execute_callable()
  File "/usr/local/lib/python3.8/dist-packages/airflow/operators/python.py", line 161, in execute_callable
    return self.python_callable(*self.op_args, **self.op_kwargs)
  File "/usr/local/airflow/dags/connect_to_gdrive.py", line 35, in print_file_id
    credentials = service_account.Credentials.from_service_account_file(jsonfile, scopes=scopes)
  File "/usr/local/lib/python3.8/dist-packages/google/oauth2/service_account.py", line 238, in from_service_account_file
    info, signer = _service_account_info.from_filename(
  File "/usr/local/lib/python3.8/dist-packages/google/auth/_service_account_info.py", line 72, in from_filename
    with io.open(filename, "r", encoding="utf-8") as json_file:
FileNotFoundError: [Errno 2] No such file or directory: '/usr/local/airflow/files/datateam1599968716114-6f9f144b4262.json'
[2021-09-03 08:27:12,807] {taskinstance.py:1505} INFO - Marking task as FAILED. dag_id=hello_gdive, task_id=py_op_1, execution_date=20210903T082710, start_date=20210903T082712, end_date=20210903T082712
[2021-09-03 08:27:12,870] {local_task_job.py:151} INFO - Task exited with return code 1
[2021-09-03 08:27:12,900] {local_task_job.py:261} INFO - 0 downstream tasks scheduled from follow-on schedule check
